Workbook

Sheet 종합표
A2: 강원본부 직할 OPGW 광코어 점검 종합표
A3: 2025.12
A4: T/L 명 | B4: 구 간 | D4: 총코어수 | E4: 사용코어 | F4: 미사용코어 | G4: 점검결과 (적합/부적합/측정불가) | I4: 기준손실 (dB) | J4: 평균접속손실 (dB) | K4: 기준손실 (dB) | L4: 평균접속손실 (dB) | M4: 점 검 일
G5: 1.3㎛ | H5: 1.5㎛ | I5: 1.3㎛ | K5: 1.5㎛
A6: 154kV 남춘천-소양T/L | B6: 남춘천S/S ∼ 홍천S/S | D6: 24 | E6: 14 | F6: =D6-E6 -> 10 | G6: 10 / 0 / 0 | H6: 2 / 8 / 0 | I6: =전송손실!M5 -> -13.00172 | J6: =남춘천!P28 -> -10.2816 | K6: =전송손실!M31 -> -8.47994 | L6: =남춘천!Q28 -> -10.8023 | M6: =남춘천!E2 -> 2025.12.30
A7: 154kV 상제T/L | B7: 상남S/S ~ 인제S/S | D7: 24 | E7: 12 | F7: =D7-E7 -> 12 | G7: 10 / 0 / 2 | H7: 10 / 0 / 2 | I7: =전송손실!M6 -> -18.969608 | J7: =인제!P80 -> -15.4341 | K7: =전송손실!M32 -> -12.495316 | L7: =인제!Q80 -> -10.0317 | M7: =인제!E54 -> 2025.12.30
A8: 154kV 서홍천분기T/L | B8: 서홍천S/S ~ 열병합S/S | D8: 12 | E8: 12 | F8: =D8-E8 -> 0 | G8: 0 / 0 / 0 | H8: 0 / 0 / 0 | I8: =전송손실!M7 -> 미측정 | J8: 미측정 | K8: =전송손실!M33 -> 미측정 | L8: 미측정 | M8: =서홍천!E2 -> 2025.12.30
A9: 154kV 서홍천분기T/L | B9: 서홍천S/S ~ 청평P/P | D9: 12 | E9: 6 | F9: =D9-E9 -> 6 | G9: 6 / 0 / 0 | H9: 6 / 0 / 0 | I9: =전송손실!M8 -> -2.15 | J9: =서홍천!O32 -> -3.5373333 | K9: =전송손실!M34 -> -1.82 | L9: =서홍천!P32 -> -2.41 | M9: =서홍천!E2 -> 2025.12.30
A10: 154kV 청평양수#3,4T/L | B10: 춘천열병합 ~ 청평P/P | D10: 12 | E10: 4 | F10: =D10-E10 -> 8 | G10: 8 / 0 / 0 | H10: 7 / 1/ 0 | I10: =전송손실!M9 -> -14.197988 | J10: =열병합!O44 -> -12.428125 | K10: =전송손실!M35 -> -9.324326 | L10: =열병합!P44 -> -8.72475 | M10: =열병합!E30 -> 2025.12.30
A11: 154kV 소양T/L | B11: 춘천S/S ~ 홍천S/S | D11: 20 | E11: 11 | F11: =D11-E11 -> 9 | G11: 9 / 0 / 0 | H11: 9 / 0 / 0 | I11: =전송손실!M10 -> -15.9554 | J11: ='(구)춘천'!O28 -> -12.059667 | K11: =전송손실!M36 -> -10.4833 | L11: ='(구)춘천'!P28 -> -8.2244444 | M11: ='(구)춘천'!E2 -> 2025.12.30
A12: 154KV 신양양-인제T/L | B12: 신양양S/S ∼ 인제S/S | D12: 24 | E12: 9 | F12: =D12-E12 -> 15 | G12: 15 / 0 / 0 | H12: 15 / 0 / 0 | I12: =전송손실!M11 -> -22.76 | J12: =인제!P136 -> -17.5764 | K12: =전송손실!M37 -> -14.84 | L12: =인제!Q136 -> -12.1336 | M12: =인제!E110 -> 2025.12.30
A13: 154KV 양구T/L | B13: 양구S/S ~ 인제S/S | D13: 24 | E13: 12 | F13: =D13-E13 -> 12 | G13: 12 / 0 / 0 | H13: 12 / 0 / 0 | I13: =전송손실!M12 -> -9.498272 | J13: =양구!O28 -> -7.97525 | K13: =전송손실!M38 -> -6.338944 | L13: =양구!P28 -> -5.0884167 | M13: =양구!E2 -> 2025.12.30
A14: 154KV 양구T/L | B14: 양구S/S ~ 상남S/S | D14: 24 | E14: 10 | F14: =D14-E14 -> 14 | G14: 14 / 0 / 0 | H14: 14 / 0 / 0 | I14: =전송손실!M13 -> -24.36248 | J14: =양구!O56 -> -19.825571 | K14: =전송손실!M39 -> -15.96096 | L14: =양구!P56 -> -13.073 | M14: =양구!E30 -> 2025.12.30
A15: 154KV 인성T/L | B15: 인제S/S ∼ 간성S/S | D15: 48 | E15: 18 | F15: =D15-E15 -> 30 | G15: 25 / 0 / 5 | H15: 25 / 0 / 5 | I15: =전송손실!M14 -> -23.899976 | J15: =인제!P52 -> -20.62424 | K15: =전송손실!M40 -> -15.621652 | L15: =인제!Q52 -> -12.33552 | M15: =인제!E2 -> 2025.12.30
A16: 154KV 철원-화천T/L | B16: 철원S/S ∼ 화천S/S | D16: 24 | E16: 17 | F16: =D16-E16 -> 7 | G16: 7 / 0 / 0 | H16: 7 / 0 / 0 | I16: =전송손실!M15 -> -3.2 | J16: =철원!O28 -> -6.2132857 | K16: =전송손실!M41 -> -2.66 | L16: =철원!P28 -> -3.6714286 | M16: =철원!E2 -> 2025.12.30
A17: 154KV 운천-철원T/L | B17: 운천S/S ∼ 철원S/S | D17: 24 | E17: 15 | F17: =D17-E17 -> 9 | G17: 5 / 0 / 4 | H17: 4 / 1 / 4 | I17: =전송손실!M16 -> -8.646464 | J17: =철원!O56 -> -7.6308 | K17: =전송손실!M42 -> -5.761728 | L17: =철원!P56 -> -5.4684 | M17: =철원!E30 -> 2025.12.30
A18: 154KV 춘천-북춘천T/L | B18: 춘천S/S ∼ 북춘천S/S | D18: 24 | E18: 15 | F18: =D18-E18 -> 9 | G18: 5 / 0 / 4 | H18: 5 / 0 / 4 | I18: =전송손실!M17 -> -9.04964 | J18: ='(구)춘천'!O56 -> -6.5156 | K18: =전송손실!M43 -> -6.06478 | L18: ='(구)춘천'!P56 -> -4.2722 | M18: ='(구)춘천'!E2 -> 2025.12.30
A19: 154KV 춘천분기T/L | B19: 춘천S/S ~ 소양H/P | D19: 4 | E19: 4 | F19: =D19-E19 -> 0 | G19: 0 / 0 / 0 | H19: 0 / 0 / 0 | I19: =전송손실!M18 -> 미측정 | J19: 미측정 | K19: =전송손실!M44 -> 미측정 | L19: 미측정 | M19: =M11 -> 2025.12.30
A20: 154KV 춘천수력T/L | B20: 북춘천S/S ∼ 춘천H/P | D20: 48 | E20: 27 | F20: =D20-E20 -> 21 | G20: 17 / 0 / 4 | H20: 17 / 0 / 4 | I20: =전송손실!M19 -> -4.49096 | J20: =춘천HP!O84 -> -2.7572941 | K20: =전송손실!M45 -> -3.10892 | L20: =춘천HP!P84 -> -2.1418235 | M20: =춘천HP!E86 -> 2025.12.30
A21: 154KV 한강분기T/L | B21: 춘천H/P ∼ 가평S/S | D21: 24 | E21: 18 | F21: =D21-E21 -> 6 | G21: 6 / 0 / 0 | H21: 6 / 0 / 0 | I21: =전송손실!M20 -> -14.64836 | J21: =춘천HP!O28 -> -11.372833 | K21: =전송손실!M46 -> -9.65622 | L21: =춘천HP!P28 -> -7.9445 | M21: =춘천HP!E2 -> 2025.12.30
A22: 154KV 화천T/L | B22: 화천H/P ∼ 춘천H/P | D22: 24 | E22: 21 | F22: =D22-E22 -> 3 | G22: 3 / 0 / 0 | H22: 3 / 0 / 0 | I22: =전송손실!M21 -> -11.017604 | J22: =화천HP!O28 -> -11.702818 | K22: =전송손실!M47 -> -7.295758 | L22: =화천HP!P28 -> -7.7458182 | M22: =화천!E2 -> 2025.12.30
A23: 154kV 화천수력T/L | B23: 화천S/S ∼ 화천H/P | D23: 24 | E23: 16 | F23: =D23-E23 -> 8 | G23: 7 / 0 / 1 | H23: 3 / 4 / 1 | I23: =전송손실!M22 -> -8.76314 | J23: =화천!O28 -> -13.8775 | K23: =전송손실!M48 -> -5.83303 | L23: =화천!P28 -> -12.403167 | M23: =화천!E2 -> 2025.12.30
A24: 154kV 남춘천-열병합T/L | B24: 남춘천S/S ~ 열병합S/S | D24: 24 | E24: 13 | F24: =D24-E24 -> 11 | G24: 11 / 0 / 0 | H24: 11 / 0 / 0 | I24: =전송손실!M23 -> -7.20428 | J24: =열병합!O28 -> -5.9097273 | K24: =전송손실!M49 -> -4.85206 | L24: =열병합!P28 -> -4.6131818 | M24: =열병합!E2 -> 2025.12.30
A25: 154kV 양구-화천HP T/L | B25: 양구S/S ~ 화천H/P | D25: 24 | E25: 9 | F25: =D25-E25 -> 15 | G25: 15 / 0 / 0 | H25: 15 / 0 / 0 | I25: =전송손실!M24 -> -15.49208 | J25: =화천HP!O84 -> -12.811737 | K25: =전송손실!M50 -> -10.03016 | L25: =화천HP!P84 -> -7.2759474 | M25: =화천HP!E58 -> 2025.12.30
A26: 합 계 | D26: =SUM(D6:D25) -> 468 | E26: =SUM(E6:E25) -> 263 | F26: =SUM(F6:F25) -> 205 | G26: 185 / 0 / 20 | H26: 171 / 14 / 20

Sheet 전송손실
A2: OPGW 선로손실표 (기준파장: 1.31㎛)
A3: 2025.12 | K3: 강원본부 직할 관내
A4: T/L 명 | B4: 구 간 | D4: 기준 (㏈/㎞) | E4: 접속손실 (dB/개소) | F4: 콘넥타손실 (dB/개) | G4: 거리(km) | H4: 접속개소수 | I4: 콘넥타수 | J4: 선로손실 (dB) | K4: 접속손실 (dB) | L4: 콘넥타손실 (dB) | M4: 총손실(dB) | N4: 경 로
A5: 154kV 남춘천분기T/L | B5: 남춘천S/S ∼ 홍천S/S | D5: 0.36 | E5: 0.15 | F5: 0.5 | G5: 29.727 | H5: 12 | I5: 1 | J5: =D5*G5 -> 10.70172 | K5: =H5*E5 -> 1.8 | L5: =F5*I5 -> 0.5 | M5: =(L5+K5+J5)*-1 -> -13.00172 | N5: 남춘천S/S~남춘천열병합#14~남춘천분기T/L~홍천소양강#74~홍천S/S
A6: 154kV 상제T/L | B6: 상남S/S ~ 인제S/S | D6: 0.36 | E6: 0.15 | F6: 0.5 | G6: =인제!G73 -> 40.8878 | H6: 25 | I6: 1 | J6: =D6*G6 -> 14.719608 | K6: =H6*E6 -> 3.75 | L6: =F6*I6 -> 0.5 | M6: =(L6+K6+J6)*-1 -> -18.969608 | N6: 상남S/S~인제S/S
A7: 154kV 서홍천분기T/L | B7: 서홍천S/S ~ 열병합S/S | D7: 0.36 | E7: 0.15 | F7: 0.5 | G7: 0 | H7: 18 | I7: 1 | J7: =D7*G7 -> 0 | K7: =H7*E7 -> 2.7 | L7: =F7*I7 -> 0.5 | M7: 미측정 | N7: 서홍천S/S~서홍천분기T/L~신가평포천LNGCC#26~청평PP열병합#19~춘천열병합
A8: 154kV 서홍천분기T/L | B8: 서홍천S/S ~ 청평P/P | D8: 0.36 | E8: 0.15 | F8: 0.5 | G8: =서홍천!G28 -> 0 | H8: 11 | I8: 1 | J8: =D8*G8 -> 0 | K8: =H8*E8 -> 1.65 | L8: =F8*I8 -> 0.5 | M8: =(L8+K8+J8)*-1 -> -2.15 | N8: 서홍천S/S~서홍천분기T/L~신가평포천LNGCC#26~청평PP열병합#19~청평P/P
A9: 154kV 청평양수#3,4T/L | B9: 춘천열병합 ~ 청평P/P | D9: 0.36 | E9: 0.15 | F9: 0.5 | G9: =열병합!I42 -> 31.3833 | H9: 16 | I9: 1 | J9: =D9*G9 -> 11.297988 | K9: =H9*E9 -> 2.4 | L9: =F9*I9 -> 0.5 | M9: =(L9+K9+J9)*-1 -> -14.197988 | N9: 춘천열병합~청평P/P
A10: 154kV 소양T/L | B10: 소양강H/P ~ 홍천S/S | D10: 0.36 | E10: 0.15 | F10: 0.5 | G10: ='(구)춘천'!I17 -> 35.015 | H10: 19 | I10: 1 | J10: =D10*G10 -> 12.6054 | K10: =H10*E10 -> 2.85 | L10: =F10*I10 -> 0.5 | M10: =(L10+K10+J10)*-1 -> -15.9554 | N10: 소양강H/P~홍천S/S
A11: 154KV 신양양-인제T/L | B11: 신양양S/S ∼ 인제S/S | D11: 0.36 | E11: 0.15 | F11: 0.5 | G11: =인제!I126 -> 51 | H11: 26 | I11: 1 | J11: =D11*G11 -> 18.36 | K11: =H11*E11 -> 3.9 | L11: =F11*I11 -> 0.5 | M11: =(L11+K11+J11)*-1 -> -22.76 | N11: 신양양S/S~신양양분기T/L~양양양수#5~신양양인제T/L~인제S/S
A12: 154KV 양구T/L | B12: 양구S/S ~ 인제S/S | D12: 0.36 | E12: 0.15 | F12: 0.5 | G12: =인제!I97 -> 19.9952 | H12: 12 | I12: 1 | J12: =D12*G12 -> 7.198272 | K12: =H12*E12 -> 1.8 | L12: =F12*I12 -> 0.5 | M12: =(L12+K12+J12)*-1 -> -9.498272 | N12: 양구S/S~양구T/L~상제#125~인제S/S
A13: 154KV 양구T/L | B13: 양구S/S ~ 상남S/S | D13: 0.36 | E13: 0.15 | F13: 0.5 | G13: =양구!G51 -> 53.368 | H13: 31 | I13: 1 | J13: =D13*G13 -> 19.21248 | K13: =H13*E13 -> 4.65 | L13: =F13*I13 -> 0.5 | M13: =(L13+K13+J13)*-1 -> -24.36248 | N13: 양구S/S~양구T/L~상제#125~상남S/S
A14: 154KV 인성T/L | B14: 인제S/S ∼ 간성S/S | D14: 0.36 | E14: 0.15 | F14: 0.5 | G14: =인제!I10 -> 52.9166 | H14: 29 | I14: 1 | J14: =D14*G14 -> 19.049976 | K14: =H14*E14 -> 4.35 | L14: =F14*I14 -> 0.5 | M14: =(L14+K14+J14)*-1 -> -23.899976 | N14: 인제S/S~간성S/S
A15: 154KV 철원-화천T/L | B15: 철원S/S ∼ 화천S/S | D15: 0.36 | E15: 0.15 | F15: 0.5 | G15: =철원!G10 -> 0 | H15: 18 | I15: 1 | J15: =D15*G15 -> 0 | K15: =H15*E15 -> 2.7 | L15: =F15*I15 -> 0.5 | M15: =(L15+K15+J15)*-1 -> -3.2 | N15: 철원S/S~철원화천#100~화천수력#45~화천S/S
A16: 154KV 운천-철원T/L | B16: 운천S/S ∼ 철원S/S | D16: 0.36 | E16: 0.15 | F16: 0.5 | G16: =철원!I51 -> 18.4624 | H16: 10 | I16: 1 | J16: =D16*G16 -> 6.646464 | K16: =H16*E16 -> 1.5 | L16: =F16*I16 -> 0.5 | M16: =(L16+K16+J16)*-1 -> -8.646464 | N16: 운천S/S~철원S/S
A17: 154KV 춘천-북춘천T/L | B17: 춘천S/S ∼ 북춘천S/S | D17: 0.36 | E17: 0.15 | F17: 0.5 | G17: ='(구)춘천'!I37 -> 18.749 | H17: 12 | I17: 1 | J17: =D17*G17 -> 6.74964 | K17: =H17*E17 -> 1.8 | L17: =F17*I17 -> 0.5 | M17: =(L17+K17+J17)*-1 -> -9.04964 | N17: 춘천S/S~춘천분기#11~춘천북춘천T/L~북춘천S/S
A18: 154KV 춘천분기T/L | B18: 춘천S/S ~ 소양H/P | D18: 0.36 | E18: 0.15 | F18: 0.5 | G18: 0 | H18: 10 | I18: 1 | J18: =D18*G18 -> 0 | K18: =H18*E18 -> 1.5 | L18: =F18*I18 -> 0.5 | M18: 미측정 | N18: 춘천S/S~춘천분기#15~소양#23~소양강H/P
A19: 154KV 춘천수력T/L | B19: 북춘천S/S ∼ 춘천H/P | D19: 0.36 | E19: 0.15 | F19: 0.5 | G19: =북춘천!G51 -> 8.586 | H19: 6 | I19: 1 | J19: =D19*G19 -> 3.09096 | K19: =H19*E19 -> 0.9 | L19: =F19*I19 -> 0.5 | M19: =(L19+K19+J19)*-1 -> -4.49096 | N19: 북춘천S/S~춘천수력T/L~춘천H/P
A20: 154KV 한강분기T/L | B20: 춘천H/P ∼ 가평S/S | D20: 0.36 | E20: 0.15 | F20: 0.5 | G20: =춘천HP!I17 -> 31.801 | H20: 18 | I20: 1 | J20: =D20*G20 -> 11.44836 | K20: =H20*E20 -> 2.7 | L20: =F20*I20 -> 0.5 | M20: =(L20+K20+J20)*-1 -> -14.64836 | N20: 춘천H/P~한강분기T/L~가평화천HP#53~가평S/S
A21: 154KV 화천T/L | B21: 화천H/P ∼ 춘천H/P | D21: 0.36 | E21: 0.15 | F21: 0.5 | G21: =화천HP!I23 -> 23.7989 | H21: 13 | I21: 1 | J21: =D21*G21 -> 8.567604 | K21: =H21*E21 -> 1.95 | L21: =F21*I21 -> 0.5 | M21: =(L21+K21+J21)*-1 -> -11.017604 | N21: 화천H/P~가평화천HP#53~한강분기T/L~춘천H/P
A22: 154kV 화천수력T/L | B22: 화천S/S ∼ 화천H/P | D22: 0.36 | E22: 0.15 | F22: 0.5 | G22: =화천!I21 -> 18.7865 | H22: 10 | I22: 1 | J22: =D22*G22 -> 6.76314 | K22: =H22*E22 -> 1.5 | L22: =F22*I22 -> 0.5 | M22: =(L22+K22+J22)*-1 -> -8.76314 | N22: 화천S/S~화천H/P
A23: 154kV 남춘천-열병합T/L | B23: 남춘천S/S ~ 열병합S/S | D23: 0.36 | E23: 0.15 | F23: 0.5 | G23: =남춘천!I41 -> 14.873 | H23: 9 | I23: 1 | J23: =D23*G23 -> 5.35428 | K23: =H23*E23 -> 1.35 | L23: =F23*I23 -> 0.5 | M23: =(L23+K23+J23)*-1 -> -7.20428 | N23: 남춘천S/S~남춘천열병합T/L~청평PP열병합#71~열병합S/S
A24: 154kV 양구-화천HP T/L | B24: 양구S/S ~ 화천H/P | D24: 0.36 | E24: 0.15 | F24: 0.5 | G24: =화천HP!I77 -> 36.228 | H24: 13 | I24: 1 | J24: =D24*G24 -> 13.04208 | K24: =H24*E24 -> 1.95 | L24: =F24*I24 -> 0.5 | M24: =(L24+K24+J24)*-1 -> -15.49208 | N24: 양구S/S~화천H/P
A28: OPGW 선로손실표 (기준파장: 1.55㎛)
A29: =A3 -> 2025.12 | K29: =K3 -> 강원본부 직할 관내
A30: T/L 명 | B30: 구 간 | D30: 기준 (㏈/㎞) | E30: 접속손실 (dB/개소) | F30: 콘넥타손실 (dB/개) | G30: 거리(km) | H30: 접속개소수 | I30: 콘넥타수 | J30: 선로손실 (dB) | K30: 접속손실 (dB) | L30: 콘넥타손실 (dB) | M30: 총손실(dB) | N30: 경 로
A31: 154kV 남춘천분기T/L | B31: 남춘천S/S ∼ 홍천S/S | D31: 0.22 | E31: 0.12 | F31: 0.5 | G31: =G5 -> 29.727 | H31: =H5 -> 12 | I31: 1 | J31: =D31*G31 -> 6.53994 | K31: =H31*E31 -> 1.44 | L31: =F31*I31 -> 0.5 | M31: =(L31+K31+J31)*-1 -> -8.47994 | N31: 남춘천S/S~남춘천열병합#14~남춘천분기T/L~홍천소양강#74~홍천S/S
A32: 154kV 상제T/L | B32: 상남S/S ~ 인제S/S | D32: 0.22 | E32: 0.12 | F32: 0.5 | G32: =G6 -> 40.8878 | H32: =H6 -> 25 | I32: 1 | J32: =D32*G32 -> 8.995316 | K32: =H32*E32 -> 3 | L32: =F32*I32 -> 0.5 | M32: =(L32+K32+J32)*-1 -> -12.495316 | N32: 상남S/S~인제S/S
A33: 154kV 서홍천분기T/L | B33: 서홍천S/S ~ 열병합S/S | D33: 0.22 | E33: 0.12 | F33: 0.5 | G33: =G7 -> 0 | H33: =H7 -> 18 | I33: 1 | J33: =D33*G33 -> 0 | K33: =H33*E33 -> 2.16 | L33: =F33*I33 -> 0.5 | M33: 미측정 | N33: 서홍천S/S~서홍천분기T/L~신가평포천LNGCC#26~청평PP열병합#19~춘천열병합
A34: 154kV 서홍천분기T/L | B34: 서홍천S/S ~ 청평P/P | D34: 0.22 | E34: 0.12 | F34: 0.5 | G34: =G8 -> 0 | H34: =H8 -> 11 | I34: 1 | J34: =D34*G34 -> 0 | K34: =H34*E34 -> 1.32 | L34: =F34*I34 -> 0.5 | M34: =(L34+K34+J34)*-1 -> -1.82 | N34: 서홍천S/S~서홍천분기T/L~신가평포천LNGCC#26~청평PP열병합#19~청평P/P
A35: 154kV 청평양수#3,4T/L | B35: 춘천열병합 ~ 청평P/P | D35: 0.22 | E35: 0.12 | F35: 0.5 | G35: =G9 -> 31.3833 | H35: =H9 -> 16 | I35: 1 | J35: =D35*G35 -> 6.904326 | K35: =H35*E35 -> 1.92 | L35: =F35*I35 -> 0.5 | M35: =(L35+K35+J35)*-1 -> -9.324326 | N35: 춘천열병합~청평P/P
A36: 154kV 소양T/L | B36: 춘천S/S ~ 홍천S/S | D36: 0.22 | E36: 0.12 | F36: 0.5 | G36: =G10 -> 35.015 | H36: =H10 -> 19 | I36: 1 | J36: =D36*G36 -> 7.7033 | K36: =H36*E36 -> 2.28 | L36: =F36*I36 -> 0.5 | M36: =(L36+K36+J36)*-1 -> -10.4833 | N36: 춘천S/S~춘천분기#15~소양#23~홍천S/S
A37: 154KV 신양양-인제T/L | B37: 신양양S/S ∼ 인제S/S | D37: 0.22 | E37: 0.12 | F37: 0.5 | G37: =G11 -> 51 | H37: =H11 -> 26 | I37: 1 | J37: =D37*G37 -> 11.22 | K37: =H37*E37 -> 3.12 | L37: =F37*I37 -> 0.5 | M37: =(L37+K37+J37)*-1 -> -14.84 | N37: 신양양S/S~신양양분기T/L~양양양수#5~신양양인제T/L~인제S/S
A38: 154KV 양구T/L | B38: 양구S/S ~ 인제S/S | D38: 0.22 | E38: 0.12 | F38: 0.5 | G38: =G12 -> 19.9952 | H38: =H12 -> 12 | I38: 1 | J38: =D38*G38 -> 4.398944 | K38: =H38*E38 -> 1.44 | L38: =F38*I38 -> 0.5 | M38: =(L38+K38+J38)*-1 -> -6.338944 | N38: 양구S/S~양구T/L~상제#125~인제S/S
A39: 154KV 양구T/L | B39: 양구S/S ~ 상남S/S | D39: 0.22 | E39: 0.12 | F39: 0.5 | G39: =G13 -> 53.368 | H39: =H13 -> 31 | I39: 1 | J39: =D39*G39 -> 11.74096 | K39: =H39*E39 -> 3.72 | L39: =F39*I39 -> 0.5 | M39: =(L39+K39+J39)*-1 -> -15.96096 | N39: 양구S/S~양구T/L~상제#125~상남S/S
A40: 154KV 인성T/L | B40: 인제S/S ∼ 간성S/S | D40: 0.22 | E40: 0.12 | F40: 0.5 | G40: =G14 -> 52.9166 | H40: =H14 -> 29 | I40: 1 | J40: =D40*G40 -> 11.641652 | K40: =H40*E40 -> 3.48 | L40: =F40*I40 -> 0.5 | M40: =(L40+K40+J40)*-1 -> -15.621652 | N40: 인제S/S~간성S/S
A41: 154KV 철원-화천T/L | B41: 철원S/S ∼ 화천S/S | D41: 0.22 | E41: 0.12 | F41: 0.5 | G41: =G15 -> 0 | H41: =H15 -> 18 | I41: 1 | J41: =D41*G41 -> 0 | K41: =H41*E41 -> 2.16 | L41: =F41*I41 -> 0.5 | M41: =(L41+K41+J41)*-1 -> -2.66 | N41: 철원S/S~철원화천#100~화천수력#45~화천S/S
A42: 154KV 운천-철원T/L | B42: 운천S/S ∼ 철원S/S | D42: 0.22 | E42: 0.12 | F42: 0.5 | G42: =G16 -> 18.4624 | H42: =H16 -> 10 | I42: 1 | J42: =D42*G42 -> 4.061728 | K42: =H42*E42 -> 1.2 | L42: =F42*I42 -> 0.5 | M42: =(L42+K42+J42)*-1 -> -5.761728 | N42: 운천S/S~철원S/S
A43: 154KV 춘천-북춘천T/L | B43: 춘천S/S ∼ 북춘천S/S | D43: 0.22 | E43: 0.12 | F43: 0.5 | G43: =G17 -> 18.749 | H43: =H17 -> 12 | I43: 1 | J43: =D43*G43 -> 4.12478 | K43: =H43*E43 -> 1.44 | L43: =F43*I43 -> 0.5 | M43: =(L43+K43+J43)*-1 -> -6.06478 | N43: 춘천S/S~춘천분기#11~춘천북춘천T/L~북춘천S/S
A44: 154KV 춘천분기T/L | B44: 춘천S/S ~ 소양H/P | D44: 0.22 | E44: 0.12 | F44: 0.5 | G44: =G18 -> 0 | H44: =H18 -> 10 | I44: 1 | J44: =D44*G44 -> 0 | K44: =H44*E44 -> 1.2 | L44: =F44*I44 -> 0.5 | M44: 미측정 | N44: 춘천S/S~춘천분기#15~소양#23~소양강H/P
...

Sheet 강원DD
A1: 관리사업소 | D1: 장소 | E1: 업데이트 | F1: 측정현황 (미실시) / 선번확인자 최준영 | K1: 선로명 | L1: 긍장/실장 (km) | M1: 비금속 (km) | N1: =COUNTIF(N4:N198,0)/COUNT(A:A) -> 0.34444444
A2: 강원본부 전자제어부 | D2: 본부 4층 ICT실 | E2: 2024.11.21 | F2: 1310um | H2: 1550um | J2: 비고
A3: No. | B3: 상대국명 | C3: 유형 | D3: 회선수용내역 | E3: 비고 | F3: 손실Data(dB) | G3: 측정거리(km) | H3: 손실Data(dB) | I3: 측정거리(km)
A4: 1 | B4: 구춘천 #1 | J4: 비금속광케이블 | N4: =IF(C4="",0,1) -> 0
A5: 2 | J5: 비금속광케이블 | N5: =IF(C5="",0,1) -> 0
A6: 3 | C6: 기타 | D6: ICT관제소(후비) SCADA망 KVM | J6: 비금속광케이블 | N6: =IF(C6="",0,1) -> 1
A7: 4 | C7: 기타 | D7: ICT관제소(후비) PSM5000 KVM | J7: 비금속광케이블 | N7: =IF(C7="",0,1) -> 1
A8: 5 | C8: 소형광 | D8: 송광치 PTPU 춘천-홍천 | J8: 비금속광케이블 | N8: =IF(C8="",0,1) -> 1
A9: 6 | J9: 비금속광케이블 | N9: =IF(C9="",0,1) -> 0
A10: 7 | C10: 기타 | D10: 본부-신춘천 PDAS 패치 | J10: 비금속광케이블 | N10: =IF(C10="",0,1) -> 1
A11: 8 | C11: 기타 | D11: 신춘천 직할급전분소 CATV 패치 | J11: 비금속광케이블 | N11: =IF(C11="",0,1) -> 1
A12: 9 | C12: SCADA | D12: 남춘천 SA 화면공유 | J12: 비금속광케이블 | N12: =IF(C12="",0,1) -> 1
A13: 10 | J13: 비금속광케이블 | N13: =IF(C13="",0,1) -> 0
A14: 11 | J14: 비금속광케이블 | N14: =IF(C14="",0,1) -> 0
A15: 12 | C15: SCADA | D15: RTU 예비회선용 광스위치(본부향) | J15: 비금속광케이블 | N15: =IF(C15="",0,1) -> 1
A16: 13 | C16: 기타 | D16: 송변전IP급전~강원본부KepCIT | J16: 비금속광케이블 | N16: =IF(C16="",0,1) -> 1
A17: 14 | C17: 기타 | D17: 송변전IP급전~강원본부KepCIT | J17: 비금속광케이블 | N17: =IF(C17="",0,1) -> 1
A18: 15 | C18: 기타 | D18: 송변전IP급전~강원본부 IPT백본 | J18: 비금속광케이블 | N18: =IF(C18="",0,1) -> 1
A19: 16 | C19: 기타 | D19: 송변전IP급전~강원본부 IPT백본 | J19: 비금속광케이블 | N19: =IF(C19="",0,1) -> 1
A20: 17 | C20: 기타 | D20: 사택CCTV | J20: 비금속광케이블 | N20: =IF(C20="",0,1) -> 1
A21: 18 | C21: 기타 | D21: 본부-춘천 PDAS L3S/W-통합단말 | J21: 비금속광케이블 | N21: =IF(C21="",0,1) -> 1
A22: 19 | C22: KepCIT | D22: 2.5G 강원#1링 (강원D/D-화천B/O) Tx | J22: 비금속광케이블 | N22: =IF(C22="",0,1) -> 1
A23: 20 | C23: KepCIT | D23: 2.5G 강원#1링 (강원D/D-화천B/O) Rx | J23: 비금속광케이블 | N23: =IF(C23="",0,1) -> 1
A24: 21 | C24: 기타 | D24: 춘천-송변전사업실 PNA 패치 | J24: 비금속광케이블 | N24: =IF(C24="",0,1) -> 1
A25: 22 | E25: 불량 | J25: 비금속광케이블 | N25: =IF(C25="",0,1) -> 0
A26: 23 | C26: 통합단말 | D26: 서홍천-춘천 통합단말 Tx | J26: 비금속광케이블 | N26: =IF(C26="",0,1) -> 1
A27: 24 | C27: 통합단말 | D27: 서홍천-춘천 통합단말 Rx | J27: 비금속광케이블 | N27: =IF(C27="",0,1) -> 1
A28: 25 | B28: 구춘천 #1 | C28: SCADA | D28: SCADA-DAS 자료연계 서버~배전센터(광컨버터) | J28: 비금속광케이블 | N28: =IF(C28="",0,1) -> 1
A29: 26 | C29: SCADA | D29: SCADA-DAS 자료연계 서버~배전센터(광컨버터) | J29: 비금속광케이블 | N29: =IF(C29="",0,1) -> 1
A30: 27 | C30: SCADA | D30: 중앙SCADA㈜ | J30: 비금속광케이블 | N30: =IF(C30="",0,1) -> 1
A31: 28 | C31: SCADA | D31: SCADA용 본부-춘천(예) | J31: 비금속광케이블 | N31: =IF(C31="",0,1) -> 1
A32: 29 | C32: 소형광 | D32: 본부-춘천 통합PTP #1 EAST (1Core) | J32: 비금속광케이블 | N32: =IF(C32="",0,1) -> 1
A33: 30 | C33: 소형광 | D33: 본부-춘천 통합PTP #1 WEST (1Core) | J33: 비금속광케이블 | N33: =IF(C33="",0,1) -> 1
A34: 31 | J34: 비금속광케이블 | N34: =IF(C34="",0,1) -> 0
A35: 32 | J35: 비금속광케이블 | N35: =IF(C35="",0,1) -> 0
A36: 33 | C36: 기타 | D36: 관리처 급전분소 | E36: 태그X | J36: 비금속광케이블 | N36: =IF(C36="",0,1) -> 1
A37: 34 | C37: 기타 | D37: 송변전감시시스템(관리처-본부-춘천) | E37: 태그X | J37: 비금속광케이블 | N37: =IF(C37="",0,1) -> 1
A38: 35 | C38: 기타 | D38: 사택CCTV | J38: 비금속광케이블 | N38: =IF(C38="",0,1) -> 1
A39: 36 | C39: 기타 | D39: 출입통제보안장치 | J39: 비금속광케이블 | N39: =IF(C39="",0,1) -> 1
A40: 37 | C40: 기타 | D40: DTRS 콘솔 | J40: 비금속광케이블 | N40: =IF(C40="",0,1) -> 1
...

Sheet (구)춘천
A1: 관리사업소 | D1: 장소 | E1: 업데이트 | F1: 측정현황 (2024-09-25) / 측정자 유상민 | K1: 선로명 | L1: 긍장/실장 (km) | M1: 비금속 (km) | N1: =COUNTIF(N5:N505,0)/COUNT(A:A) -> 0.34649123
A2: 강원본부 전자제어부 | D2: (구)춘천 변전소 | E2: 2025.12.30 | F2: 1310um | H2: 1550um | J2: 결 과 [표준손실 기준]
F3: 표준손실(dB) | G3: =전송손실!M10 -> -15.9554 | H3: 표준손실(dB) | I3: =전송손실!M36 -> -10.4833
A4: No. | B4: 상대국명 | C4: 유형 | D4: 회선수용내역 | E4: 비고 | F4: 손실Data(dB) | G4: 측정거리(km) | H4: 손실Data(dB) | I4: 측정거리(km)
A5: 1 | B5: 홍천S/S | F5: -12.218 | G5: 34.984 | H5: -8.352 | I5: 34.989 | J5: 적 합 | K5: 154kV 춘천분기T/L 154kV 춘천-남춘천T/L 154kV 소양T/L | N5: =IF(C5="",0,1) -> 0
A6: 2 | F6: -12.377 | G6: 34.948 | H6: -8.362 | I6: 34.997 | J6: 적 합 | N6: =IF(C6="",0,1) -> 0
A7: 3 | F7: -12.043 | G7: 34.984 | H7: -7.981 | I7: 34.999 | J7: 적 합 | N7: =IF(C7="",0,1) -> 0
A8: 4 | F8: -12.063 | G8: 34.984 | H8: -8.775 | I8: 34.997 | J8: 적 합 | N8: =IF(C8="",0,1) -> 0
A9: 5 | N9: =IF(C9="",0,1) -> 0
A10: 6 | N10: =IF(C10="",0,1) -> 0
A11: 7 | C11: 소형광 | D11: 송광치 PTPU 춘천-홍천(W) | N11: =IF(C11="",0,1) -> 1
A12: 8 | F12: -11.796 | G12: 34.984 | H12: -7.674 | I12: 35.007 | J12: 적 합 | N12: =IF(C12="",0,1) -> 0
A13: 9 | C13: 소형광 | D13: 송광치 PTPU 춘천-소양(E) | N13: =IF(C13="",0,1) -> 1
A14: 10 | C14: 소형광 | D14: 송광치 PTPU 춘천-소양(W) | N14: =IF(C14="",0,1) -> 1
A15: 11 | N15: =IF(C15="",0,1) -> 0
A16: 12 | N16: =IF(C16="",0,1) -> 0
A17: 13 | F17: -12.082 | G17: 34.999 | H17: -8.084 | I17: 35.015 | J17: 적 합 | N17: =IF(C17="",0,1) -> 0
A18: 14 | F18: -12.212 | G18: 34.999 | H18: -7.993 | I18: 35.007 | J18: 적 합 | N18: =IF(C18="",0,1) -> 0
A19: 15 | F19: -11.998 | G19: 34.997 | H19: -7.963 | I19: 35.012 | J19: 적 합 | N19: =IF(C19="",0,1) -> 0
A20: 16 | F20: -11.748 | G20: 34.999 | H20: -8.836 | I20: 35.012 | J20: 적 합 | N20: =IF(C20="",0,1) -> 0
A21: 17 | C21: 차세대KepCIT | D21: 차세대KepCIT 권역망 중부#2링 강원DD-원주PO 패치 | N21: =IF(C21="",0,1) -> 1
A22: 18 | C22: 차세대KepCIT | D22: 차세대KepCIT 권역망 중부#2링 강원DD-원주PO 패치 | N22: =IF(C22="",0,1) -> 1
A23: 19 | C23: 송광치 | D23: 송변전광단말1링(인제-신춘천패치)Tx | N23: =IF(C23="",0,1) -> 1
A24: 20 | C24: 송광치 | D24: 송변전광단말1링(인제-신춘천패치)Rx | N24: =IF(C24="",0,1) -> 1
A25: 21 | C25: 송광치 | D25: 송변전광단말2링(신춘천-남춘천패치)Rx | N25: =IF(C25="",0,1) -> 1
A26: 22 | C26: 송광치 | D26: 송변전광단말2링(신춘천-남춘천패치)Tx | N26: =IF(C26="",0,1) -> 1
A27: 23 | C27: DAS | D27: 배전자가망 본부직할#51링 | N27: =IF(C27="",0,1) -> 1
A28: 24 | C28: DAS | D28: 배전자가망 본부직할#50링 | N28: =IF(C28="",0,1) -> 1 | O28: =SUM(F5,F6,F7,F8,F12,F17,F18,F19,F20)/9 -> -12.059667 | P28: =SUM(H5,H6,H7,H8,H12,H17,H18,H19,H20)/9 -> -8.2244444
A29: 관리사업소 | D29: 장소 | E29: 업데이트 | F29: 측정현황 (2024-09-25) / 측정자 유상민 | K29: 선로명 | L29: 긍장/실장 (km) | M29: 비금속 (km)
A30: 강원본부 전자제어부 | D30: (구)춘천 변전소 | E30: 2025.12.30 | F30: 1310um | H30: 1550um | J30: 결 과 [표준손실 기준]
F31: 표준손실(dB) | G31: =전송손실!M17 -> -9.04964 | H31: 표준손실(dB) | I31: =전송손실!M43 -> -6.06478
A32: No. | B32: 상대국명 | C32: 유형 | D32: 회선수용내역 | E32: 비고 | F32: 손실Data(dB) | G32: 측정거리(km) | H32: 손실Data(dB) | I32: 측정거리(km)
A33: 25 | B33: 북춘천S/S | D33: 단선(융착) / 북춘천변전소 OFD 내 융착으로 인한 단선 / (구)kepcit 10G | J33: 측정불가 | K33: 154kV 춘천분기T/L 154kV 춘천-북춘천T/L | N33: =IF(C33="",0,1) -> 0
A34: 26 | D34: 단선(융착) / 북춘천변전소 OFD 내 융착으로 인한 단선 / (구)kepcit 10G | J34: 측정불가 | N34: =IF(C34="",0,1) -> 0
A35: 27 | C35: 소형광 | D35: PTP(춘천-북춘천) EAST | N35: =IF(C35="",0,1) -> 1
A36: 28 | C36: 소형광 | D36: PTP(춘천-북춘천) WEST | N36: =IF(C36="",0,1) -> 1
A37: 29 | F37: -6.469 | G37: 18.741 | H37: -4.473 | I37: 18.749 | J37: 적 합 | N37: =IF(C37="",0,1) -> 0
A38: 30 | F38: -6.595 | G38: 18.738 | H38: -4.397 | I38: 18.746 | J38: 적 합 | N38: =IF(C38="",0,1) -> 0
A39: 31 | D39: 단선(융착) / 북춘천변전소 OFD 내 융착으로 인한 단선 / (구)kepcit 2.5G | J39: 측정불가 | N39: =IF(C39="",0,1) -> 0
A40: 32 | D40: 단선(융착) / 북춘천변전소 OFD 내 융착으로 인한 단선 / (구)kepcit 2.5G | J40: 측정불가 | N40: =IF(C40="",0,1) -> 0
...

Sheet (신)춘천
A1: 관리사업소 | D1: 장소 | E1: 업데이트 | F1: 측정현황 (미실시) / 선번확인자 유상민 | K1: 선로명 | L1: 긍장/실장 (km) | M1: 비금속 (km) | N1: =COUNTIF(N4:N500,0)/COUNT(A:A) -> 0.041666667
A2: 강원본부 전자제어부 | D2: (신)춘천 변전소 | E2: 2025.12.30 | F2: 1310um | H2: 1550um | J2: 비고
A3: No. | B3: 상대국명 | C3: 유형 | D3: 회선수용내역 | E3: 비고 | F3: 손실Data(dB) | G3: 측정거리(km) | H3: 손실Data(dB) | I3: 측정거리(km)
A4: 1 | B4: 구춘천 #1 | C4: 소형광 | D4: 신춘천-구춘천 통합PTP #1 EAST | J4: 비금속광케이블 | N4: =IF(C4="",0,1) -> 1
A5: 2 | C5: 소형광 | D5: 신춘천-구춘천 통합PTP #1 WEST | J5: 비금속광케이블 | N5: =IF(C5="",0,1) -> 1
A6: 3 | C6: 기타 | D6: FA_감시정보망 임시 | J6: 비금속광케이블 | N6: =IF(C6="",0,1) -> 1
A7: 4 | C7: 기타 | D7: FA_감시정보망 임시 | J7: 비금속광케이블 | N7: =IF(C7="",0,1) -> 1
A8: 5 | C8: 소형광 | D8: 신춘천-구춘천 통합PTP #2 EAST | J8: 비금속광케이블 | N8: =IF(C8="",0,1) -> 1
A9: 6 | C9: 소형광 | D9: 신춘천-구춘천 통합PTP #2 WEST | J9: 비금속광케이블 | N9: =IF(C9="",0,1) -> 1
A10: 7 | C10: SCADA | D10: RTU 예비회선용 광스위치(신춘천향) | J10: 비금속광케이블 | N10: =IF(C10="",0,1) -> 1
A11: 8 | C11: 기타 | D11: 광컨버터_ 신춘천-계통운영센터 직결 콘솔용 | J11: 비금속광케이블 | N11: =IF(C11="",0,1) -> 1
A12: 9 | C12: 기타 | D12: 신춘천FA망 From 구춘천 FA망 스위치 | J12: 비금속광케이블 | N12: =IF(C12="",0,1) -> 1
A13: 10 | C13: 기타 | D13: 신춘천FA망 From 구춘천 FA망 스위치 | J13: 비금속광케이블 | N13: =IF(C13="",0,1) -> 1
A14: 11 | C14: 기타 | D14: 서홍천-신춘천 송변전광단말 #2링 패치 | J14: 비금속광케이블 | N14: =IF(C14="",0,1) -> 1
A15: 12 | C15: 기타 | D15: 서홍천-신춘천 송변전광단말 #2링 패치 | J15: 비금속광케이블 | N15: =IF(C15="",0,1) -> 1
A16: 13 | C16: 기타 | D16: IP급전전화망 | J16: 비금속광케이블 | N16: =IF(C16="",0,1) -> 1
... A27: 24 | C27: 송광치 | D27: 신춘천-남춘천 송변전광단말 #2링 패치 | J27: 비금속광케이블 | N27: =IF(C27="",0,1) -> 1
A28: 관리사업소 | D28: 장소 | E28: 업데이트 | F28: 측정현황 (미실시) / 선번확인자 최준영 | K28: 선로명 | L28: 긍장/실장 (km) | M28: 비금속 (km) | N28: =IF(C28="",0,1) -> 0
A29: 강원본부 전자제어부 | D29: (신)춘천 변전소 | E29: 2025.12.30 | F29: 1310um | H29: 1550um | J29: 비고 | N29: =IF(C29="",0,1) -> 0
A30: No. | B30: 상대국명 | C30: 유형 | D30: 회선수용내역 | E30: 비고 | F30: 손실Data(dB) | G30: 측정거리(km) | H30: 손실Data(dB) | I30: 측정거리(km) | N30: =IF(C30="",0,1) -> 1
A31: 1 | B31: 구춘천 #2 | C31: 기타 | D31: 인터넷망 L2S/W | J31: 비금속광케이블 | N31: =IF(C31="",0,1) -> 1
A32: 2 | C32: 기타 | D32: 인터넷망 L2S/W | J32: 비금속광케이블 | N32: =IF(C32="",0,1) -> 1
A33: 3 | C33: 기타 | D33: IPT망 L2S/W | J33: 비금속광케이블 | N33: =IF(C33="",0,1) -> 1
A34: 4 | C34: 기타 | D34: 본부-신춘천 PDAS 패치 | J34: 비금속광케이블 | N34: =IF(C34="",0,1) -> 1
A35: 5 | C35: SCADA | D35: 춘천(신)-춘천(구) 송광치 SCADA 주회선용 L2 패치 | J35: 비금속광케이블 | N35: =IF(C35="",0,1) -> 1
A36: 6 | C36: 기타 | D36: 춘천OA SW-신춘천 OA망 | J36: 비금속광케이블 | N36: =IF(C36="",0,1) -> 1
A37: 7 | C37: 기타 | D37: 춘천OA SW-신춘천 OA망 | J37: 비금속광케이블 | N37: =IF(C37="",0,1) -> 1
A38: 8 | C38: 송광치 | D38: 인제-신춘천 송변전광단말장치 직할#1링 패치 | J38: 비금속광케이블 | N38: =IF(C38="",0,1) -> 1
A39: 9 | C39: 송광치 | D39: 인제-신춘천 송변전광단말장치 직할#1링 패치 | J39: 비금속광케이블 | N39: =IF(C39="",0,1) -> 1
A40: 10 | C40: 기타 | D40: 춘천FA SW-신춘천 FA망 | J40: 비금속광케이블 | N40: =IF(C40="",0,1) -> 1
A41: 11 | C41: 기타 | D41: 춘천FA SW-신춘천 IP급전망 | J41: 비금속광케이블 | N41: =IF(C41="",0,1) -> 1
A42: 12 | C42: 기타 | D42: 춘천FA SW-신춘천 IP급전망 | J42: 비금속광케이블 | N42: =IF(C42="",0,1) -> 1
A43: 13 | C43: 전력구감시 | D43: 전력구운영시스템 From 강릉T/P to 관리처 | J43: 비금속광케이블 | N43: =IF(C43="",0,1) -> 1
... A51: 21 | C51: SCADA | D51: 급전분소 L3 S/W #2 | J51: 비금속광케이블 | N51: =IF(C51="",0,1) -> 1
A52: 22 | C52: SCADA | D52: 급전분소 L3 S/W #2 | J52: 비금속광케이블
A53: 23 | C53: 기타 | D53: 출입통제망 | J53: 비금속광케이블
A54: 24 | C54: 기타 | D54: 출입통제망 | J54: 비금속광케이블

Sheet 북춘천
A1: 관리사업소 | D1: 장소 | E1: 업데이트 | F1: 측정현황 (2024-10-08) / 측정자 박근호 | K1: 선로명 | L1: 긍장/실장 (km) | M1: 비금속 (km) | N1: =COUNTIF(N5:N503,0)/COUNT(A:A) -> 0.69444444
A2: 강원본부 전자제어부 | D2: 북춘천 변전소 | E2: 2025.12.30 | F2: 1310um | H2: 1550um | J2: 결 과 [표준손실 기준]
F3: 표준손실(dB) | G3: =전송손실!M17 -> -9.04964 | H3: 표준손실(dB) | I3: =전송손실!M43 -> -6.06478
A4: No. | B4: 상대국명 | C4: 유형 | D4: 회선수용내역 | E4: 비고 | F4: 손실Data(dB) | G4: 측정거리(km) | H4: 손실Data(dB) | I4: 측정거리(km)
A5: 1 | B5: 춘천S/S | D5: 단선(융착) / 춘천계1,2-춘천HP계 11,12 | J5: (구) KEPCIT 10G | K5: 154kV 춘천-북춘천 T/L 154kV 춘천분기T/L | N5: =IF(C5="",0,1) -> 0
A6: 2 | D6: 단선(융착) / 춘천계1,2-춘천HP계 11,12 | J6: (구) KEPCIT 10G | N6: =IF(C6="",0,1) -> 0
A7: 3 | C7: 소형광 | D7: PTP(춘천-북춘천) WEST | N7: =IF(C7="",0,1) -> 1
A8: 4 | C8: 소형광 | D8: PTP(춘천-북춘천) EAST | N8: =IF(C8="",0,1) -> 1
A9: 5 | F9: -6.435 | G9: 18.74 | H9: -4.42 | I9: 18.747 | J9: 적 합 | N9: =IF(C9="",0,1) -> 0
A10: 6 | F10: -6.516 | G10: 18.737 | H10: -4.341 | I10: 18.745 | J10: 적 합 | N10: =IF(C10="",0,1) -> 0
A11: 7 | D11: 단선(융착) / 춘천계7,8-춘천HP계 23,24 | J11: (구) KEPCIT 2.5G | N11: =IF(C11="",0,1) -> 0
A12: 8 | D12: 단선(융착) / 춘천계7,8-춘천HP계 23,24 | J12: (구) KEPCIT 2.5G | N12: =IF(C12="",0,1) -> 0
A13: 9 | N13: =IF(C13="",0,1) -> 0
A14: 10 | N14: =IF(C14="",0,1) -> 0
A15: 11 | N15: =IF(C15="",0,1) -> 0
A16: 12 | N16: =IF(C16="",0,1) -> 0
A17: 13 | C17: SCADA | D17: RTU 예비회선용 광스위치(북춘천향 13번/구춘천 중계) | N17: =IF(C17="",0,1) -> 1
A18: 14 | F18: -6.527 | G18: 18.735 | H18: -3.994 | I18: 18.743 | J18: 적 합 | N18: =IF(C18="",0,1) -> 0
A19: 15 | C19: 송광치 | D19: 송광치1링(신춘천-북춘천 패치) EAST Tx | N19: =IF(C19="",0,1) -> 1
A20: 16 | C20: 송광치 | D20: 송광치1링(신춘천-북춘천 패치) EAST Rx | N20: =IF(C20="",0,1) -> 1
A21: 17 | C21: 차세대KepCIT | D21: 차세대KepCIT 강원#1링(화천B/O-본부) | E21: 라벨링 필요 | N21: =IF(C21="",0,1) -> 1
A22: 18 | C22: 차세대KepCIT | D22: 차세대KepCIT 강원#1링(화천B/O-본부) | E22: 라벨링 필요 | N22: =IF(C22="",0,1) -> 1
A23: 19 | F23: -6.536 | G23: 18.737 | H23: -4.076 | I23: 18.745 | J23: 적 합 | N23: =IF(C23="",0,1) -> 0
A24: 20 | F24: -6.458 | G24: 18.737 | H24: -3.997 | I24: 18.746 | J24: 적 합 | N24: =IF(C24="",0,1) -> 0
A25: 21 | E25: 실제 21~24코어는 사용불가. 그 아래 FDF의 3~6코어만 사용 가능 | N25: =IF(C25="",0,1) -> 0
A26: 22 | N26: =IF(C26="",0,1) -> 0
A27: 23 | N27: =IF(C27="",0,1) -> 0
A28: 24 | N28: =IF(C28="",0,1) -> 0 | O28: =SUM(F9:F10,F18,F23,F24)/5 -> -6.4944 | P28: =SUM(H9,H10,H18,H23,H24)/5 -> -4.1656
A29: 관리사업소 | D29: 장소 | E29: 업데이트 | F29: 측정현황 (2024-10-08) / 측정자 박근호 | K29: 선로명 | L29: 긍장/실장 (km) | M29: 비금속 (km) | N29: =IF(C29="",0,1) -> 0
A30: 강원본부 전자제어부 | D30: 북춘천 변전소 | E30: 2025.12.30 | F30: 1310um | H30: 1550um | J30: 결 과 [표준손실 기준] | N30: =IF(C30="",0,1) -> 0
F31: 표준손실(dB) | G31: =전송손실!M19 -> -4.49096 | H31: 표준손실(dB) | I31: =전송손실!M45 -> -3.10892
A32: No. | B32: 상대국명 | C32: 유형 | D32: 회선수용내역 | E32: 비고 | F32: 손실Data(dB) | G32: 측정거리(km) | H32: 손실Data(dB) | I32: 측정거리(km) | N32: =IF(C32="",0,1) -> 1
A33: 1 | B33: 춘천H/P #1 | C33: 소형광 | D33: 통합PTP 북춘천-춘천H/P WEST Rx㈜ | K33: 154kV 춘천수력T/L | N33: =IF(C33="",0,1) -> 1
A34: 2 | C34: 소형광 | D34: 통합PTP 북춘천-춘천H/P WEST Tx㈜ | N34: =IF(C34="",0,1) -> 1
A35: 3 | C35: 소형광 | D35: 송광PTP 북춘천-화천H/P EAST Tx/Rx | N35: =IF(C35="",0,1) -> 1
A36: 4 | C36: 소형광 | D36: 송광PTP 북춘천-화천H/P WEST Tx/Rx | N36: =IF(C36="",0,1) -> 1
A37: 5 | C37: 소형광 | D37: I-MUX(B) Tx | N37: =IF(C37="",0,1) -> 1
A38: 6 | C38: 소형광 | D38: I-MUX(B) Rx 5dB 감쇄기 | N38: =IF(C38="",0,1) -> 1
A39: 7 | C39: 소형광 | D39: 통합PTP 북춘천-춘천H/P EAST Tx(예) | N39: =IF(C39="",0,1) -> 1
A40: 8 | C40: 소형광 | D40: 통합PTP 북춘천-춘천H/P EAST Rx(예) | N40: =IF(C40="",0,1) -> 1
...

Sheet 남춘천
A1: 관리사업소 | D1: 장소 | E1: 업데이트 | F1: 측정현황 (2024-10-11) / 측정자 박근호 | K1: 선로명 | L1: 긍장/실장 (km) | M1: 비금속 (km) | N1: =COUNTIF(N5:N506,0)/COUNT(A:A) -> 0.625
A2: 강원본부 전자제어부 | D2: 남춘천 변전소 | E2: 2025.12.30 | F2: 1310um | H2: 1550um | J2: 결 과 [표준손실 기준]
F3: 표준손실(dB) | G3: =전송손실!M23 -> -7.20428 | H3: 표준손실(dB) | I3: =전송손실!M49 -> -4.85206
A4: No. | B4: 상대국명 | C4: 유형 | D4: 회선수용내역 | E4: 비고 | F4: 손실Data(dB) | G4: 측정거리(km) | H4: 손실Data(dB) | I4: 측정거리(km)
A5: 1 | B5: 홍천 | C5: 송광치 | D5: 송변전광단말 신춘천-남춘천 EAST(Rx) | K5: 154kV 홍천-남춘천T/L 154kV 남춘천분기T/L | N5: =IF(C5="",0,1) -> 1
A6: 2 | C6: 송광치 | D6: 송변전광단말 신춘천-남춘천 EAST(Tx) | N6: =IF(C6="",0,1) -> 1
A7: 3 | C7: SCADA | D7: RTU 예비회선용 광스위치 남춘천-홍천 | N7: =IF(C7="",0,1) -> 1
A8: 4 | F8: -10.141 | G8: 29.727 | H8: -9.946 | I8: 29.74 | J8: 부적합 | N8: =IF(C8="",0,1) -> 0
A9: 5 | N9: =IF(C9="",0,1) -> 0
A10: 6 | N10: =IF(C10="",0,1) -> 0
A11: 7 | C11: 차세대KepCIT | D11: 차세대KepCIT 강원#2링(본부-홍천D/O) | N11: =IF(C11="",0,1) -> 1
A12: 8 | C12: 차세대KepCIT | D12: 차세대KepCIT 강원#2링(본부-홍천D/O) | N12: =IF(C12="",0,1) -> 1
A13: 9 | C13: 소형광 | D13: 송광치PTPU 남춘천-홍천S/S WEST | N13: =IF(C13="",0,1) -> 1
A14: 10 | C14: 소형광 | D14: 송광치PTPU 남춘천-홍천S/S EAST | N14: =IF(C14="",0,1) -> 1
A15: 11 | C15: 소형광 | D15: 통합PTP 홍천S/S-남춘천 EAST | N15: =IF(C15="",0,1) -> 1
A16: 12 | F16: -10.201 | G16: 29.722 | H16: -10.754 | I16: 29.72 | J16: 부적합 | N16: =IF(C16="",0,1) -> 0
A17: 13 | F17: -9.973 | G17: 29.72 | H17: -7.65 | I17: 29.73 | J17: 적 합 | N17: =IF(C17="",0,1) -> 0
A18: 14 | F18: -10.149 | G18: 29.72 | H18: -8.119 | I18: 29.732 | J18: 적 합 | N18: =IF(C18="",0,1) -> 0
A19: 15 | C19: 기타 | D19: 동해전력구 화상감시L2S/W | N19: =IF(C19="",0,1) -> 1
A20: 16 | C20: DAS | D20: 배전자가망 홍천지사#39링 | N20: =IF(C20="",0,1) -> 1
A21: 17 | F21: -10.321 | G21: 29.696 | H21: -11.795 | I21: 27.676 | J21: 부적합 | N21: =IF(C21="",0,1) -> 0
A22: 18 | F22: -10.425 | G22: 29.714 | H22: -13.393 | I22: 29.732 | J22: 부적합 | N22: =IF(C22="",0,1) -> 0
A23: 19 | F23: -10.474 | G23: 29.717 | H23: -10.949 | I23: 27.669 | J23: 부적합 | N23: =IF(C23="",0,1) -> 0
A24: 20 | F24: -10.311 | G24: 29.717 | H24: -10.374 | I24: 27.176 | J24: 부적합 | N24: =IF(C24="",0,1) -> 0
A25: 21 | C25: 소형광 | D25: OMS-Plus 춘천-홍천 Tx(예) | E25: 라벨링필요 | N25: =IF(C25="",0,1) -> 1
A26: 22 | C26: 소형광 | D26: OMS-Plus 춘천-홍천 Rx(예) | E26: 라벨링필요 | N26: =IF(C26="",0,1) -> 1
A27: 23 | F27: -10.378 | G27: 29.722 | H27: -13.854 | I27: 29.73 | J27: 부적합 | N27: =IF(C27="",0,1) -> 0
A28: 24 | F28: -10.443 | G28: 29.722 | H28: -11.189 | I28: 23.156 | J28: 부적합 | N28: =IF(C28="",0,1) -> 0 | P28: =SUM(F8,F16,F17,F18,F21,F22,F23,F24,F27,F28)/10 -> -10.2816 | Q28: =SUM(H8,H16,H17,H18,H21,H22,H23,H24,H27,H28)/10 -> -10.8023
A29: 관리사업소 | D29: 장소 | E29: 업데이트 | F29: 측정현황 (2024-10-11) / 측정자 박근호 | K29: 선로명 | L29: 긍장/실장 (km) | M29: 비금속 (km)
A30: 강원본부 전자제어부 | D30: 남춘천 변전소 | E30: 2025.12.30 | F30: 1310um | H30: 1550um | J30: 결 과 [표준손실 기준]
F31: 표준손실(dB) | G31: =전송손실!M35 -> -9.324326 | H31: 표준손실(dB) | I31: =전송손실!M61 -> 0
A32: No. | B32: 상대국명 | C32: 유형 | D32: 회선수용내역 | E32: 비고 | F32: 손실Data(dB) | G32: 측정거리(km) | H32: 손실Data(dB) | I32: 측정거리(km)
A33: 25 | B33: 열병합S/Y | C33: 소형광 | D33: 통합PTP 남춘천S/S-열병합S/Y WEST(Rx) | K33: 154kV 남춘천-열병합T/L 154kV 남춘천분기 T/L | N33: =IF(C33="",0,1) -> 1
A34: 26 | C34: 소형광 | D34: 통합PTP 남춘천S/S-열병합S/Y WEST(Tx) | N34: =IF(C34="",0,1) -> 1
A35: 27 | C35: SCADA | D35: RTU 예비회선용 광스위치 열병합-남춘천 | N35: =IF(C35="",0,1) -> 1
A36: 28 | F36: -6.074 | G36: 14.863 | H36: -4.81 | I36: 14.868 | J36: 적 합 | N36: =IF(C36="",0,1) -> 0
A37: 29 | C37: 소형광 | D37: 통합PTP 남춘천S/S-열병합S/Y EAST(Rx) | N37: =IF(C37="",0,1) -> 1
A38: 30 | C38: 소형광 | D38: 통합PTP 남춘천S/S-열병합S/Y EAST(Tx) | N38: =IF(C38="",0,1) -> 1
A39: 31 | C39: 송광치 | D39: 송변전광단말 남춘천-열병합 WEST(Tx) | N39: =IF(C39="",0,1) -> 1
A40: 32 | C40: 송광치 | D40: 송변전광단말 남춘천-열병합 WEST(Rx) | N40: =IF(C40="",0,1) -> 1
...

Sheet 서홍천
A1: 관리사업소 | D1: 장소 | E1: 업데이트 | F1: 측정현황 (2025-12-30) / 측정자 유상민 | K1: 선로명 | L1: 긍장/실장 (km) | M1: 비금속 (km) | N1: =COUNTIF(N5:N505,0)/COUNT(A:A) -> 0.5
A2: 강원본부 전자제어부 | D2: 서홍천 변전소 | E2: 2025.12.30 | F2: 1310um | H2: 1550um | J2: 결 과 [표준손실 기준]
F3: 표준손실(dB) | G3: =전송손실!M7 -> 미측정 | H3: 표준손실(dB) | I3: =전송손실!M33 -> 미측정
A4: No. | B4: 상대국명 | C4: 유형 | D4: 회선수용내역 | E4: 비고 | F4: 손실Data(dB) | G4: 측정거리(km) | H4: 손실Data(dB) | I4: 측정거리(km)
A5: 1 | B5: 열병합S/Y | C5: 송광치 | D5: 송변전광단말 #2링 EAST Rx | K5: 154kV 서홍천분기T/L 154kV 청평양수#3,4 T/L 154kV 서홍천-열병합T/L | N5: =IF(C5="",0,1) -> 1
A6: 2 | C6: 송광치 | D6: 송변전광단말 #2링 EAST Tx | N6: =IF(C6="",0,1) -> 1
A7: 3 | C7: 소형광 | D7: 송광치 PTPU 서홍천-열병합 WEST | N7: =IF(C7="",0,1) -> 1
A8: 4 | C8: 차세대KepCIT | D8: 차세대KepCIT 권역망 중부#2링 | N8: =IF(C8="",0,1) -> 1
A9: 5 | C9: 소형광 | D9: 송광치 PTPU 서홍천-열병합 EAST | N9: =IF(C9="",0,1) -> 1
A10: 6 | C10: 차세대KepCIT | D10: 차세대KepCIT 권역망 중부#2링 | N10: =IF(C10="",0,1) -> 1
A11: 7 | C11: 송광치 | D11: 송광치 춘천#2링 서홍천-춘천 WEST(Tx) | N11: =IF(C11="",0,1) -> 1
A12: 8 | C12: 송광치 | D12: 송광치 춘천#2링 서홍천-춘천 WEST(Rx) | N12: =IF(C12="",0,1) -> 1
A13: 9 | N13: =IF(C13="",0,1) -> 0
A14: 10 | F14: -12.842 | G14: 34.316 | H14: -8.486 | I14: 34.3129 | N14: =IF(C14="",0,1) -> 0
A15: 11 | C15: SCADA | D15: RTU 예비회선용 광스위치 서홍천-열병합 | N15: =IF(C15="",0,1) -> 1
A16: 12 | C16: SCADA | D16: RTU 예비회선용 광스위치 본부-서홍천(남춘천-열병합 중계) | N16: =IF(C16="",0,1) -> 1
A17: 관리사업소 | D17: 장소 | E17: 업데이트 | F17: 측정현황 (2025-12-30) / 측정자 박근호 | K17: 선로명 | L17: 긍장/실장 (km) | M17: 비금속 (km)
A18: 강원본부 전자제어부 | D18: 서홍천 변전소 | E18: 2025.12.30 | F18: 1310um | H18: 1550um | J18: 결 과 [표준손실 기준]
F19: 표준손실(dB) | G19: =전송손실!M8 -> -2.15 | H19: 표준손실(dB) | I19: =전송손실!M34 -> -1.82
A20: No. | B20: 상대국명 | C20: 유형 | D20: 회선수용내역 | E20: 비고 | F20: 손실Data(dB) | G20: 측정거리(km) | H20: 손실Data(dB) | I20: 측정거리(km)
A21: 13 | B21: 청평P/P | F21: -7.467 | G21: 18.1849 | H21: -5.057 | I21: 18.1807 | K21: 154kV 서홍천분기T/L 154kV 청평양수#3,4 T/L 154kV 서홍천-열병합T/L | N21: =IF(C21="",0,1) -> 0
A22: 14 | F22: -8.558 | G22: 18.1874 | H22: -5.941 | I22: 18.1829 | N22: =IF(C22="",0,1) -> 0
A23: 15 | N23: =IF(C23="",0,1) -> 0
A24: 16 | F24: -6.859 | G24: 18.1858 | H24: -5.129 | I24: 18.1813 | N24: =IF(C24="",0,1) -> 0
A25: 17 | F25: -7.324 | G25: 18.1686 | H25: -5.374 | I25: 18.1673 | N25: =IF(C25="",0,1) -> 0
A26: 18 | C26: 차세대KepCIT | D26: 차세대KepCIT 권역망 중부#2링 (Rx) | N26: =IF(C26="",0,1) -> 1
A27: 19 | C27: 차세대KepCIT | D27: 차세대KepCIT 권역망 중부#2링 (Tx) | N27: =IF(C27="",0,1) -> 1
A28: 20 | N28: =IF(C28="",0,1) -> 0
A29: 21 | D29: 청평계 PTPU WEST | N29: =IF(C29="",0,1) -> 0
A30: 22 | D30: 청평계 PTPU EAST | N30: =IF(C30="",0,1) -> 0
A31: 23 | F31: -7.218 | G31: 18.1689 | H31: -4.807 | I31: 18.1673 | N31: =IF(C31="",0,1) -> 0
A32: 24 | F32: -6.682 | G32: 18.1696 | H32: -4.279 | I32: 18.1676 | N32: =IF(C32="",0,1) -> 0 | O32: =SUM(F25,F28,F29,F30,F31,F32)/6 -> -3.5373333 | P32: =SUM(H25,H28,H29,H30,H31,H32)/6 -> -2.41

Sheet 열병합
A1: 관리사업소 | D1: 장소 | E1: 업데이트 | F1: 측정현황 (2025-12-30) / 측정자 유상민 | K1: 선로명 | L1: 긍장/실장 (km) | M1: 비금속 (km) | N1: =COUNTIF(N5:N506,0)/COUNT(A:A) -> 0.28125
A2: 강원본부 전자제어부 | D2: 열병합S/Y | E2: 2025.12.30 | F2: 1310um | H2: 1550um | J2: 결 과 [표준손실 기준]
F3: 표준손실(dB) | G3: =전송손실!M23 -> -7.20428 | H3: 표준손실(dB) | I3: =전송손실!M49 -> -4.85206
A4: No. | B4: 상대국명 | C4: 유형 | D4: 회선수용내역 | E4: 비고 | F4: 손실Data(dB) | G4: 측정거리(km) | H4: 손실Data(dB) | I4: 측정거리(km)
A5: 1 | B5: 남춘천S/S | C5: 소형광 | D5: 남춘천S/S-열병합 통합PTP WEST(Rx) | K5: 154kV 남춘천-춘천열병합 T/L 154kV 남춘천분기T/L | N5: =IF(C5="",0,1) -> 1
A6: 2 | C6: 소형광 | D6: 남춘천S/S-열병합 통합PTP WEST(Tx) | N6: =IF(C6="",0,1) -> 1
A7: 3 | C7: SCADA | D7: RTU 예비회선용 광스위치 열병합-남춘천 | N7: =IF(C7="",0,1) -> 1
A8: 4 | F8: -6.108 | G8: 14.7824 | H8: -4.434 | I8: 14.7793 | N8: =IF(C8="",0,1) -> 0
A9: 5 | C9: 소형광 | D9: 남춘천S/S-열병합 통합PTP EAST(Rx) | N9: =IF(C9="",0,1) -> 1
A10: 6 | C10: 소형광 | D10: 남춘천S/S-열병합 통합PTP EAST(Tx) | N10: =IF(C10="",0,1) -> 1
A11: 7 | C11: 송광치 | D11: 송광치 남춘천S/S-열병합 EAST(Rx) | N11: =IF(C11="",0,1) -> 1
A12: 8 | C12: 송광치 | D12: 송광치 남춘천S/S-열병합 EAST(Tx) | N12: =IF(C12="",0,1) -> 1
A13: 9 | F13: -5.694 | G13: 14.7852 | H13: -3.66 | I13: 14.7834 | N13: =IF(C13="",0,1) -> 0
A14: 10 | F14: -5.705 | G14: 14.7843 | H14: -4.111 | I14: 14.7828 | N14: =IF(C14="",0,1) -> 0
A15: 11 | F15: -5.699 | G15: 14.7843 | H15: -3.757 | I15: 14.784 | N15: =IF(C15="",0,1) -> 0
A16: 12 | F16: -6.062 | G16: 14.7846 | H16: -4.091 | I16: 14.7825 | N16: =IF(C16="",0,1) -> 0
A17: 13 | C17: 차세대KepCIT | D17: 차세대KepCIT 권역망 중부#2링 | N17: =IF(C17="",0,1) -> 1
A18: 14 | C18: 차세대KepCIT | D18: 차세대KepCIT 권역망 중부#2링 | N18: =IF(C18="",0,1) -> 1
A19: 15 | F19: -6.239 | G19: 14.7814 | H19: -4.771 | I19: 14.7802 | N19: =IF(C19="",0,1) -> 0
A20: 16 | F20: -5.768 | G20: 14.7843 | H20: -3.853 | I20: 14.7831 | N20: =IF(C20="",0,1) -> 0
A21: 17 | F21: -5.992 | G21: 14.7795 | H21: -4.749 | I21: 14.777 | N21: =IF(C21="",0,1) -> 0
A22: 18 | F22: -5.916 | G22: 14.7833 | H22: -3.955 | I22: 14.7809 | N22: =IF(C22="",0,1) -> 0
A23: 19 | F23: -6.297 | G23: 14.7801 | H23: -4.743 | I23: 14.7786 | N23: =IF(C23="",0,1) -> 0
A24: 20 | F24: -5.527 | G24: 14.7814 | H24: -3.85 | I24: 14.7805 | N24: =IF(C24="",0,1) -> 0
A25: 21 | F25: -5.733 | G25: 14.8022 | H25: -4.217 | I25: 14.7997 | N25: =IF(C25="",0,1) -> 0
A26: 22 | N26: =IF(C26="",0,1) -> 0
A27: 23 | F27: -5.911 | G27: 14.7827 | H27: -4.059 | I27: 14.7825 | N27: =IF(C27="",0,1) -> 0
A28: 24 | F28: -6.168 | G28: 14.7824 | H28: -4.865 | I28: 14.7799 | N28: =IF(C28="",0,1) -> 0 | O28: =SUM(F8,F13,F14,F15,F16,F19,F20,F21,F22,F23,F24)/11 -> -5.9097273 | P28: =SUM(H8,H13,H14,H15,H16,H19,H19,H20,H21,H22,H23,H24)/11 -> -4.6131818
A29: 관리사업소 | D29: 장소 | E29: 업데이트 | F29: 측정현황 (2025-12-30) / 측정자 유상민 | K29: 선로명 | L29: 긍장/실장 (km) | M29: 비금속 (km) | N29: =IF(C29="",0,1) -> 0
A30: 강원본부 전자제어부 | D30: 열병합S/Y | E30: 2025.12.30 | F30: 1310um | H30: 1550um | J30: 결 과 [표준손실 기준] | N30: =IF(C30="",0,1) -> 0
F31: 표준손실(dB) | G31: =전송손실!M9 -> -14.197988 | H31: 표준손실(dB) | I31: =전송손실!M35 -> -9.324326
A32: No. | B32: 상대국명 | C32: 유형 | D32: 회선수용내역 | E32: 비고 | F32: 손실Data(dB) | G32: 측정거리(km) | H32: 손실Data(dB) | I32: 측정거리(km) | N32: =IF(C32="",0,1) -> 1
A33: 1 | B33: 청평P/P | C33: 소형광 | D33: 청평P/P-열병합 통합PTP EAST(Tx) | K33: 154kV 청평양수#3,4 T/L 154kV 서홍천-열병합 T/L | N33: =IF(C33="",0,1) -> 1
A34: 2 | C34: 소형광 | D34: 청평P/P-열병합 통합PTP EAST(Rx) | N34: =IF(C34="",0,1) -> 1
A35: 3 | F35: -12.721 | G35: 31.3836 | H35: -9.33 | I35: 31.3856 | N35: =IF(C35="",0,1) -> 0
A36: 4 | F36: -12.294 | G36: 31.383 | H36: -8.602 | I36: 31.3789 | N36: =IF(C36="",0,1) -> 0
A37: 5 | C37: 소형광 | D37: 청평P/P-열병합 통합PTP WEST(Tx) | N37: =IF(C37="",0,1) -> 1
A38: 6 | C38: 소형광 | D38: 청평P/P-열병합 통합PTP WEST(Rx) | N38: =IF(C38="",0,1) -> 1
A39: 7 | F39: -13.221 | G39: 31.3791 | H39: -9.665 | I39: 31.3769 | N39: =IF(C39="",0,1) -> 0
A40: 8 | F40: -12.395 | G40: 31.3804 | H40: -8.014 | I40: 31.3804 | N40: =IF(C40="",0,1) -> 0
...

Sheet 인제
A1: 관리사업소 | D1: 장소 | E1: 업데이트 | F1: 측정현황 (2025-12-30) / 측정자 유상민 | K1: 선로명 | L1: 긍장/실장 (km) | M1: 비금속 (km) | N1: =COUNTIF(N5:N507,0)/COUNT(A:A) -> 0.4702381
A2: 강원본부 전자제어부 | D2: 인제 변전소 | E2: 2025.12.30 | F2: 1310um | H2: 1550um | J2: 결 과 [표준손실 기준]
F3: 표준손실(dB) | G3: =전송손실!M14 -> -23.899976 | H3: 표준손실(dB) | I3: =전송손실!M40 -> -15.621652
A4: No. | B4: 상대국명 | C4: 유형 | D4: 회선수용내역 | E4: 비고 | F4: 손실Data(dB) | G4: 측정거리(km) | H4: 손실Data(dB) | I4: 측정거리(km)
A5: 1 | B5: 간성S/S | F5: -20.094 | G5: 52.9187 | H5: -11.822 | I5: 52.9166 | K5: 154kV 인성T/L | N5: =IF(C5="",0,1) -> 0
A6: 2 | F6: -20.163 | G6: 52.9187 | H6: -12.105 | I6: 52.9064 | N6: =IF(C6="",0,1) -> 0
A7: 3 | F7: -19.687 | G7: 52.8012 | H7: -11.676 | I7: 52.9242 | N7: =IF(C7="",0,1) -> 0
A8: 4 | F8: -19.874 | G8: 52.9161 | H8: -11.828 | I8: 52.9115 | N8: =IF(C8="",0,1) -> 0
A9: 5 | F9: -19.983 | G9: 52.9136 | H9: -12.05 | I9: 52.914 | N9: =IF(C9="",0,1) -> 0
A10: 6 | F10: -20.123 | G10: 52.9085 | H10: -11.869 | I10: 52.9166 | N10: =IF(C10="",0,1) -> 0
A11: 7 | C11: 기타 | D11: 빙설해 풍향풍속(인성T/L No.87호) | E11: 라벨링 다시 | N11: =IF(C11="",0,1) -> 1
A12: 8 | F12: -20.244 | G12: 52.9136 | H12: -12.11 | I12: 52.9166 | N12: =IF(C12="",0,1) -> 0
A13: 9 | D13: 측정불가(간성 연장) | F13: -27.625 | G13: 70.6433 | H13: -18.349 | I13: 79.9797 | J13: 측정불가 | N13: =IF(C13="",0,1) -> 0 | R13: =H13/I13 -> -0.22942072
A14: 10 | D14: 측정불가(간성 연장) | F14: -27.266 | G14: 70.6663 | H14: -18.295 | I14: 79.9797 | J14: 측정불가 | N14: =IF(C14="",0,1) -> 0
A15: 11 | C15: 송광치 | D15: 송광치 간성계 EAST(Tx) | N15: =IF(C15="",0,1) -> 1
A16: 12 | C16: 송광치 | D16: 송광치 간성계 EAST(Rx) | N16: =IF(C16="",0,1) -> 1
A17: 13 | C17: 소형광 | D17: PTPU 인제-간성 WEST(Rx) | N17: =IF(C17="",0,1) -> 1
A18: 14 | C18: 소형광 | D18: PTPU 인제-간성 WEST(Tx) | N18: =IF(C18="",0,1) -> 1
A19: 15 | F19: -19.945 | G19: 52.8855 | H19: -11.729 | I19: 52.8961 | N19: =IF(C19="",0,1) -> 0
A20: 16 | D20: 단선 | F20: -13.455 | G20: 35.8042 | H20: -11.942 | I20: 52.8936 | N20: =IF(C20="",0,1) -> 0
A21: 17 | F21: -19.723 | G21: 52.8829 | H21: -11.817 | I21: 52.8834 | N21: =IF(C21="",0,1) -> 0
A22: 18 | F22: -20.11 | G22: 52.888 | H22: -11.884 | I22: 52.8859 | N22: =IF(C22="",0,1) -> 0
A23: 19 | D23: 측정불가(간성 연장) | F23: -23.144 | G23: 57.8771 | H23: -14.236 | I23: 57.8754 | N23: =IF(C23="",0,1) -> 0
A24: 20 | D24: 측정불가(간성 연장) | F24: -24.883 | G24: 57.8771 | H24: -15.675 | I24: 57.8729 | N24: =IF(C24="",0,1) -> 0
A25: 21 | C25: 소형광 | D25: PTPU 인제-간성 EAST(Tx) | N25: =IF(C25="",0,1) -> 1
A26: 22 | C26: 소형광 | D26: PTPU 인제-간성 EAST(Rx) | N26: =IF(C26="",0,1) -> 1
A27: 23 | C27: 차세대KepCIT | D27: 차세대 KepCIT 강원#2링 | N27: =IF(C27="",0,1) -> 1
A28: 24 | C28: 차세대KepCIT | D28: 차세대 KepCIT 강원#2링 | N28: =IF(C28="",0,1) -> 1
A29: 25 | B29: 간성S/S | C29: 임대 | D29: U+ Oracle 10G | K29: 154kV 인성T/L | N29: =IF(C29="",0,1) -> 1
A30: 26 | C30: 임대 | D30: U+ Oracle 10G | N30: =IF(C30="",0,1) -> 1
A31: 27 | F31: -19.879 | G31: 52.9008 | H31: -11.849 | I31: 52.9012 | N31: =IF(C31="",0,1) -> 0
A32: 28 | F32: -19.994 | G32: 52.8957 | H32: -11.84 | I32: 52.8987 | N32: =IF(C32="",0,1) -> 0
A33: 29 | F33: -19.982 | G33: 52.7604 | H33: -12.346 | I33: 52.8961 | N33: =IF(C33="",0,1) -> 0
A34: 30 | F34: -19.432 | G34: 52.8931 | H34: -11.642 | I34: 52.8961 | N34: =IF(C34="",0,1) -> 0
A35: 31 | C35: 임대 | D35: Metro 강원#1링 양구상리~고성간 | N35: =IF(C35="",0,1) -> 1
A36: 32 | C36: 임대 | D36: Metro 강원#1링 양구상리~고성간 | N36: =IF(C36="",0,1) -> 1
A37: 33 | F37: -19.843 | G37: 52.8931 | H37: -11.819 | I37: 52.891 | N37: =IF(C37="",0,1) -> 0
A38: 34 | F38: -19.783 | G38: 52.8906 | H38: -11.857 | I38: 52.8936 | N38: =IF(C38="",0,1) -> 0
A39: 35 | F39: -19.494 | G39: 52.8906 | H39: -11.615 | I39: 52.8885 | N39: =IF(C39="",0,1) -> 0
A40: 36 | F40: -19.868 | G40: 52.8855 | H40: -12.014 | I40: 52.8808 | N40: =IF(C40="",0,1) -> 0
...

Sheet 양구
A1: 관리사업소 | D1: 장소 | E1: 업데이트 | F1: 측정현황 (2025-12-30) / 측정자 유상민 | K1: 선로명 | L1: 긍장/실장 (km) | M1: 비금속 (km) | N1: =COUNTIF(N5:N506,0)/COUNT(A:A) -> 0.425
A2: 강원본부 전자제어부 | D2: 양구 변전소 | E2: 2025.12.30 | F2: 1310um | H2: 1550um | J2: 결 과 [표준손실 기준]
F3: 표준손실(dB) | G3: =전송손실!M12 -> -9.498272 | H3: 표준손실(dB) | I3: =전송손실!M38 -> -6.338944
A4: No. | B4: 상대국명 | C4: 유형 | D4: 회선수용내역 | E4: 비고 | F4: 손실Data(dB) | G4: 측정거리(km) | H4: 손실Data(dB) | I4: 측정거리(km)
A5: 1 | B5: 인제S/S | C5: 소형광 | D5: 송광치 PTPU 인제-양구 EAST | K5: 154kV 인제양구1,2T/L | N5: =IF(C5="",0,1) -> 1
A6: 2 | C6: 소형광 | D6: 송광치 PTPU 인제-양구 WEST | N6: =IF(C6="",0,1) -> 1
A7: 3 | C7: SCADA | D7: RTU 광스위치 인제-양구 | N7: =IF(C7="",0,1) -> 1
A8: 4 | F8: -7.968 | G8: 21.5143 | H8: -4.955 | I8: 21.5122 | N8: =IF(C8="",0,1) -> 0
A9: 5 | C9: 기타 | D9: 빙설해카메라 양구T/L No.35 | N9: =IF(C9="",0,1) -> 1
A10: 6 | F10: -7.856 | G10: 21.5054 | H10: -5.016 | I10: 21.5026 | N10: =IF(C10="",0,1) -> 0
A11: 7 | F11: -7.8 | G11: 21.5156 | H11: -4.994 | I11: 21.5128 | N11: =IF(C11="",0,1) -> 0
A12: 8 | F12: -7.81 | G12: 21.5156 | H12: -4.968 | I12: 21.5135 | N12: =IF(C12="",0,1) -> 0
A13: 9 | F13: -8.078 | G13: 21.5182 | H13: -5.276 | I13: 21.5173 | N13: =IF(C13="",0,1) -> 0
A14: 10 | F14: -7.752 | G14: 21.5182 | H14: -4.846 | I14: 21.5167 | N14: =IF(C14="",0,1) -> 0
A15: 11 | C15: 차세대KepCIT | D15: 차세대KepCIT 강원#2링 (양구B/O-인제B/O 패치) | N15: =IF(C15="",0,1) -> 1
A16: 12 | C16: 차세대KepCIT | D16: 차세대KepCIT 강원#2링 (양구B/O-인제B/O 패치) | N16: =IF(C16="",0,1) -> 1 | U16: =H13/I13 -> -0.24519805
A17: 13 | F17: -8.268 | G17: 21.5233 | H17: -5.355 | I17: 21.5224 | N17: =IF(C17="",0,1) -> 0
A18: 14 | F18: -8.2 | G18: 21.5162 | H18: -5.288 | I18: 21.5147 | N18: =IF(C18="",0,1) -> 0
A19: 15 | F19: -8.129 | G19: 21.5162 | H19: -5.175 | I19: 21.5141 | N19: =IF(C19="",0,1) -> 0
A20: 16 | F20: -7.9 | G20: 21.511 | H20: -5.174 | I20: 21.5096 | N20: =IF(C20="",0,1) -> 0
A21: 17 | C21: 송광치 | D21: 송광치 춘천#1링 양구-인제 WEST(Rx) | N21: =IF(C21="",0,1) -> 1
A22: 18 | C22: 송광치 | D22: 송광치 춘천#1링 양구-인제 WEST(Tx) | N22: =IF(C22="",0,1) -> 1
A23: 19 | F23: -7.82 | G23: 21.5175 | H23: -4.882 | I23: 21.5141 | N23: =IF(C23="",0,1) -> 0
A24: 20 | F24: -8.122 | G24: 21.5143 | H24: -5.132 | I24: 21.5122 | N24: =IF(C24="",0,1) -> 0
A25: 21 | F25: -8.225 | G25: 21.5162 | H25: -5.289 | I25: 21.5141 | N25: =IF(C25="",0,1) -> 0
A26: 22 | F26: -7.898 | G26: 21.5182 | H26: -4.988 | I26: 21.5167 | N26: =IF(C26="",0,1) -> 0
A27: 23 | N27: =IF(C27="",0,1) -> 0
A28: 24 | N28: =IF(C28="",0,1) -> 0 | O28: =SUM(F8,F10:F14,F17:F20,F23:F24)/12 -> -7.97525 | P28: =SUM(H8,H10:H14,H17:H20,H23:H24)/12 -> -5.0884167
A29: 관리사업소 | D29: 장소 | E29: 업데이트 | F29: 측정현황 (2024-10-14) / 측정자 유상민 | K29: 선로명 | L29: 긍장/실장 (km) | M29: 비금속 (km)
A30: 강원본부 전자제어부 | D30: 양구 변전소 | E30: 2025.12.30 | F30: 1310um | H30: 1550um | J30: 결 과 [표준손실 기준]
F31: 표준손실(dB) | G31: =전송손실!M13 -> -24.36248 | H31: 표준손실(dB) | I31: =전송손실!M39 -> -15.96096
A32: No. | B32: 상대국명 | C32: 유형 | D32: 회선수용내역 | E32: 비고 | F32: 손실Data(dB) | G32: 측정거리(km) | H32: 손실Data(dB) | I32: 측정거리(km)
A33: 1 | B33: 상남S/S | F33: -19.59 | G33: 53.5697 | H33: -13.251 | I33: 56.5349 | K33: 154kV 인제양구T/L 154kV 상제T/L | N33: =IF(C33="",0,1) -> 0
A34: 2 | F34: -19.176 | G34: 52.1859 | H34: -13.053 | I34: 56.5451 | N34: =IF(C34="",0,1) -> 0
A35: 3 | F35: -20.237 | G35: 53.8117 | H35: -13.34 | I35: 56.5387 | N35: =IF(C35="",0,1) -> 0
A36: 4 | F36: -19.599 | G36: 51.4518 | H36: -13.779 | I36: 56.5406 | N36: =IF(C36="",0,1) -> 0
A37: 5 | F37: -19.991 | G37: 53.0789 | H37: -12.927 | I37: 56.5425 | N37: =IF(C37="",0,1) -> 0
A38: 6 | F38: -20.29 | G38: 53.0425 | H38: -13.525 | I38: 56.5425 | N38: =IF(C38="",0,1) -> 0
A39: 7 | F39: -20.103 | G39: 54.7417 | H39: -12.529 | I39: 56.5432 | N39: =IF(C39="",0,1) -> 0
A40: 8 | F40: -20.087 | G40: 53.8883 | H40: -12.931 | I40: 56.5413 | N40: =IF(C40="",0,1) -> 0
...

Sheet 철원
A1: 관리사업소 | D1: 장소 | E1: 업데이트 | F1: 측정현황 (2024-10-10) / 측정자 유상민 | K1: 선로명 | L1: 긍장/실장 (km) | M1: 비금속 (km) | N1: =COUNTIF(N5:N502,0)/COUNT(A:A) -> 0.28125
A2: 강원본부 전자제어부 | D2: 철원 변전소 | E2: 2025.12.30 | F2: 1310um | H2: 1550um | J2: 결 과 [표준손실 기준]
F3: 표준손실(dB) | G3: =전송손실!M15 -> -3.2 | H3: 표준손실(dB) | I3: =전송손실!M41 -> -2.66
A4: No. | B4: 상대국명 | C4: 유형 | D4: 회선수용내역 | E4: 비고 | F4: 손실Data(dB) | G4: 측정거리(km) | H4: 손실Data(dB) | I4: 측정거리(km)
A5: 1 | B5: 화천S/S | F5: -14.316 | G5: 38.7711 | H5: -13.561 | I5: 38.7699 | K5: 154kV 철원-화천T/L | L5: 35.231 / | N5: =IF(C5="",0,1) -> 0
A6: 2 | F6: -14.99 | G6: 38.7251 | H6: -8.183 | I6: 36.8622 | N6: =IF(C6="",0,1) -> 0
A7: 3 | F7: -14.951 | G7: 38.7686 | H7: -8.207 | I7: 36.8558 | N7: =IF(C7="",0,1) -> 0
A8: 4 | F8: -14.539 | G8: 38.7724 | H8: -13.067 | I8: 38.724 | N8: =IF(C8="",0,1) -> 0
A9: 5 | N9: =IF(C9="",0,1) -> 0
A10: 6 | N10: =IF(C10="",0,1) -> 0
A11: 7 | C11: SCADA | D11: RTU 예비회선용 광스위치 화천-철원 | N11: =IF(C11="",0,1) -> 1
A12: 8 | C12: 차세대KepCIT | D12: 차세대KepCIT 강원#1링(화천B/O-본부) | N12: =IF(C12="",0,1) -> 1
A13: 9 | C13: 송광치 | D13: 송광치 직할#1링 화천-철원 WEST(Rx) | N13: =IF(C13="",0,1) -> 1
A14: 10 | C14: 송광치 | D14: 송광치 직할#1링 화천-철원 WEST(Tx) | N14: =IF(C14="",0,1) -> 1
A15: 11 | C15: 차세대KepCIT | D15: 차세대KepCIT 경기북부링 | N15: =IF(C15="",0,1) -> 1
A16: 12 | C16: 차세대KepCIT | D16: 차세대KepCIT 경기북부링 | N16: =IF(C16="",0,1) -> 1
A17: 13 | C17: SCADA | D17: RTU 예비회선용 광스위치 북춘천-철원(춘천수력-화천수력 중계) | N17: =IF(C17="",0,1) -> 1
A18: 14 | F18: -14.736 | G18: 38.7762 | H18: -8.815 | I18: 38.7725 | N18: =IF(C18="",0,1) -> 0
A19: 15 | F19: -14.089 | G19: 38.7251 | H19: -8.766 | I19: 38.724 | N19: =IF(C19="",0,1) -> 0
A20: 16 | F20: -14.668 | G20: 38.7686 | H20: -8.119 | I20: 36.8635 | N20: =IF(C20="",0,1) -> 0
A21: 17 | C21: 소형광 | D21: 통합PTP 철원S/S-화천S/S EAST | N21: =IF(C21="",0,1) -> 1
A22: 18 | C22: 소형광 | D22: 통합PTP 철원S/S-화천S/S WEST | N22: =IF(C22="",0,1) -> 1
A23: 19 | F23: -8.316 | G23: 22.4584 | H23: -4.996 | I23: 22.4578 | J23: 기존 빙설해 | N23: =IF(C23="",0,1) -> 0
A24: 20 | C24: 차세대KepCIT | D24: 차세대KepCIT 강원#1링(화천B/O-본부) | N24: =IF(C24="",0,1) -> 1
A25: 21 | N25: =IF(C25="",0,1) -> 0
A26: 22 | N26: =IF(C26="",0,1) -> 0
A27: 23 | N27: =IF(C27="",0,1) -> 0
A28: 24 | N28: =IF(C28="",0,1) -> 0 | O28: =SUM(F9:F10,F15:F16,F18:F20)/7 -> -6.2132857 | P28: =SUM(H9:H10,H15:H16,H18:H20)/7 -> -3.6714286
A29: 관리사업소 | D29: 장소 | E29: 업데이트 | F29: 측정현황 (2024-10-10) / 측정자 유상민 | K29: 선로명 | L29: 긍장/실장 (km) | M29: 비금속 (km) | N29: =IF(C29="",0,1) -> 0
A30: 강원본부 전자제어부 | D30: 철원 변전소 | E30: 2025.12.30 | F30: 1310um | H30: 1550um | J30: 결 과 [표준손실 기준] | N30: =IF(C30="",0,1) -> 0
F31: 표준손실(dB) | G31: =전송손실!M16 -> -8.646464 | H31: 표준손실(dB) | I31: =전송손실!M42 -> -5.761728
A32: No. | B32: 상대국명 | C32: 유형 | D32: 회선수용내역 | E32: 비고 | F32: 손실Data(dB) | G32: 측정거리(km) | H32: 손실Data(dB) | I32: 측정거리(km) | N32: =IF(C32="",0,1) -> 1
A33: 1 | B33: 운천S/S | C33: 소형광 | D33: 운천계 OMS WEST(Tx) 주 | K33: 154kV 운천-철원T/L | L33: 16.94 / | N33: =IF(C33="",0,1) -> 1
A34: 2 | C34: 소형광 | D34: 운천계 OMS WEST(Rx) 주 | N34: =IF(C34="",0,1) -> 1
A35: 3 | C35: 소형광 | D35: 운천계 OMS EAST(Tx) 주 | N35: =IF(C35="",0,1) -> 1
A36: 4 | C36: 소형광 | D36: 운천계 OMS EAST(Rx) 주 | N36: =IF(C36="",0,1) -> 1
A37: 5 | C37: 차세대KepCIT | D37: 차세대KepCIT 강원#1링(신가평-철원B/O) | N37: =IF(C37="",0,1) -> 1
A38: 6 | C38: 차세대KepCIT | D38: 차세대KepCIT 강원#1링(신가평-철원B/O) | N38: =IF(C38="",0,1) -> 1
A39: 7 | C39: 소형광 | D39: 운천계 OMS WEST(Tx) 예 | N39: =IF(C39="",0,1) -> 1
A40: 8 | C40: 소형광 | D40: 운천계 OMS WEST(Rx) 예 | N40: =IF(C40="",0,1) -> 1
...

Sheet 화천
A1: 관리사업소 | D1: 장소 | E1: 업데이트 | F1: 측정현황 (2024-10-10) / 측정자 유상민 | K1: 선로명 | L1: 긍장/실장 (km) | M1: 비금속 (km) | N1: =COUNTIF(N5:N502,0)/COUNT(A:A) -> 0.26041667
A2: 강원본부 전자제어부 | D2: 화천 변전소 | E2: 2025.12.30 | F2: 1310um | H2: 1550um | J2: 결 과 [표준손실 기준]
F3: 표준손실(dB) | G3: =전송손실!M21 -> -11.017604 | H3: 표준손실(dB) | I3: =전송손실!M47 -> -7.295758
A4: No. | B4: 상대국명 | C4: 유형 | D4: 회선수용내역 | E4: 비고 | F4: 손실Data(dB) | G4: 측정거리(km) | H4: 손실Data(dB) | I4: 측정거리(km)
A5: 1 | B5: 화천H/P | C5: SCADA | D5: RTU 예비회선용 광스위치 북춘천-철원(화천수력-화천 중계) | K5: 154kV 화천수럭T/L | N5: =IF(C5="",0,1) -> 1
A6: 2 | C6: SCADA | D6: RTU 예비회선용 광스위치 화천-양구(화천수력 중계) | N6: =IF(C6="",0,1) -> 1
A7: 3 | C7: 소형광 | D7: 통합PTP 화천S/S-화천H/P WEST Tx | N7: =IF(C7="",0,1) -> 1
A8: 4 | C8: 소형광 | D8: 통합PTP 화천S/S-화천H/P WEST Rx | N8: =IF(C8="",0,1) -> 1
A9: 5 | F9: -16.516 | G9: 18.7945 | H9: -18.265 | I9: 18.7941 | N9: =IF(C9="",0,1) -> 0
A10: 6 | F10: -14.438 | G10: 18.7958 | H10: -17.216 | I10: 18.7941 | N10: =IF(C10="",0,1) -> 0
A11: 7 | F11: -17.751 | G11: 18.7958 | H11: -21.975 | I11: 18.7941 | N11: =IF(C11="",0,1) -> 0
A12: 8 | F12: -8.056 | G12: 18.7932 | H12: -5.853 | I12: 18.7903 | N12: =IF(C12="",0,1) -> 0
A13: 9 | F13: -14.687 | G13: 18.7932 | H13: -16.57 | I13: 18.7916 | N13: =IF(C13="",0,1) -> 0
A14: 10 | F14: -12.33 | G14: 18.7945 | H14: -12.905 | I14: 18.7916 | N14: =IF(C14="",0,1) -> 0
A15: 11 | C15: 송광치 | D15: 송광치 직할#1링 화천H/P-철원S/S EAST(Rx) | N15: =IF(C15="",0,1) -> 1
A16: 12 | C16: 송광치 | D16: 송광치 직할#1링 화천H/P-철원S/S EAST(Tx) | N16: =IF(C16="",0,1) -> 1
A17: 13 | C17: 송광치 | D17: 송광치 직할#1링 춘천H/P-화천 패치 | N17: =IF(C17="",0,1) -> 1
A18: 14 | C18: 송광치 | D18: 송광치 직할#1링 춘천H/P-화천 패치 | N18: =IF(C18="",0,1) -> 1
A19: 15 | C19: 차세대KepCIT | D19: 차세대KepCIT 경기북부링 패치 | N19: =IF(C19="",0,1) -> 1
A20: 16 | C20: 차세대KepCIT | D20: 차세대KepCIT 경기북부링 패치 | N20: =IF(C20="",0,1) -> 1
A21: 17 | F21: -13.781 | G21: 18.7881 | H21: -16.523 | I21: 18.7865 | N21: =IF(C21="",0,1) -> 0
A22: 18 | D22: 측정불가(연장) | F22: -14.192 | G22: 18.7881 | H22: 17.856 | I22: 18.7865 | N22: =IF(C22="",0,1) -> 0
A23: 19 | F23: -11.574 | G23: 18.7881 | H23: -13.498 | I23: 18.7865 | N23: =IF(C23="",0,1) -> 0
A24: 20 | F24: -8.313 | G24: 18.7855 | H24: -7.13 | I24: 18.7839 | N24: =IF(C24="",0,1) -> 0
A25: 21 | F25: -17.446 | G25: 18.7855 | H25: -21.781 | I25: 18.7839 | N25: =IF(C25="",0,1) -> 0
A26: 22 | F26: -17.446 | G26: 18.7855 | H26: -14.978 | I26: 18.7852 | N26: =IF(C26="",0,1) -> 0
A27: 23 | C27: 차세대KepCIT | D27: 차세대KepCIT 강원#1링(화천B/O-본부) | N27: =IF(C27="",0,1) -> 1
A28: 24 | C28: 차세대KepCIT | D28: 차세대KepCIT 강원#1링(화천B/O-본부) | E28: 수 | N28: =IF(C28="",0,1) -> 1 | O28: =SUM(F9,F11,F12,F22,F24,F25,F10,F13,F14,F21,F23,F26)/12 -> -13.8775 | P28: =SUM(H9,H25,H24,H22,H12,H11,H10,H13,H14,H21,H23,H26)/12 -> -12.403167
A29: 관리사업소 | D29: 장소 | E29: 업데이트 | F29: 측정현황 (2024-10-10) / 측정자 유상민 | K29: 선로명 | L29: 긍장/실장 (km) | M29: 비금속 (km) | N29: =IF(C29="",0,1) -> 0
A30: 강원본부 전자제어부 | D30: 화천 변전소 | E30: 2025.12.30 | F30: 1310um | H30: 1550um | J30: 결 과 [표준손실 기준] | N30: =IF(C30="",0,1) -> 0
F31: 표준손실(dB) | G31: =전송손실!M15 -> -3.2 | H31: 표준손실(dB) | I31: =전송손실!M41 -> -2.66
A32: No. | B32: 상대국명 | C32: 유형 | D32: 회선수용내역 | E32: 비고 | F32: 손실Data(dB) | G32: 측정거리(km) | H32: 손실Data(dB) | I32: 측정거리(km) | N32: =IF(C32="",0,1) -> 1
A33: 1 | B33: 철원S/S | C33: 송광치 | D33: 송광치 직할#1링 철원-화천H/P Tx 패치 | K33: 154kV 철원-화천T/L | N33: =IF(C33="",0,1) -> 1
A34: 2 | C34: 송광치 | D34: 송광치 직할#1링 철원-화천H/P Rx 패치 | N34: =IF(C34="",0,1) -> 1
A35: 3 | F35: -14.491 | G35: 38.7647 | H35: -13.214 | I35: 38.7623 | N35: =IF(C35="",0,1) -> 0
A36: 4 | F36: -14.627 | G36: 38.7634 | H36: -1.204 | I36: 1.9141 | N36: =IF(C36="",0,1) -> 0
A37: 5 | F37: -14.818 | G37: 38.7647 | H37: -1.664 | I37: 1.918 | N37: =IF(C37="",0,1) -> 0
A38: 6 | F38: -14.192 | G38: 38.7647 | H38: -13.645 | I38: 38.7623 | N38: =IF(C38="",0,1) -> 0
A39: 7 | C39: SCADA | D39: RTU 예비회선용 광스위치 화천-철원 | N39: =IF(C39="",0,1) -> 1
A40: 8 | C40: 차세대KepCIT | D40: 차세대KepCIT 강원#1링(화천B/O-본부) | N40: =IF(C40="",0,1) -> 1
...

Sheet 화천HP
A1: 관리사업소 | D1: 장소 | E1: 업데이트 | F1: 측정현황 (2024-10-17) / 측정자 유상민 | K1: 선로명 | L1: 긍장/실장 (km) | M1: 비금속 (km) | N1: =COUNTIF(N5:N503,0)/COUNT(A:A) -> 0.63888889
A2: 강원본부 전자제어부 | D2: 화천수력발전소 | E2: 2025.12.30 | F2: 1310um | H2: 1550um | J2: 결 과 [표준손실 기준]
F3: 표준손실(dB) | G3: =전송손실!M21 -> -11.017604 | H3: 표준손실(dB) | I3: =전송손실!M47 -> -7.295758
A4: No. | B4: 상대국명 | C4: 유형 | D4: 회선수용내역 | E4: 비고 | F4: 손실Data(dB) | G4: 측정거리(km) | H4: 손실Data(dB) | I4: 측정거리(km)
A5: 1 | B5: 춘천H/P | C5: 소형광 | D5: 송광PTP 화천H/P-북춘천S/S EAST | K5: 154kV 북춘천- 화천HPT/L | N5: =IF(C5="",0,1) -> 1
A6: 2 | C6: 소형광 | D6: 송광PTP 화천H/P-북춘천S/S WEST | N6: =IF(C6="",0,1) -> 1
A7: 3 | F7: -12.241 | G7: 32.3139 | H7: -8.541 | I7: 32.318 | N7: =IF(C7="",0,1) -> 0
A8: 4 | F8: -12.316 | G8: 32.3203 | H8: -8.328 | I8: 32.3168 | N8: =IF(C8="",0,1) -> 0
A9: 5 | C9: 송광치 | D9: 송광치 가평연계링 춘천H/P-화천H/P WEST(Tx) | N9: =IF(C9="",0,1) -> 1
A10: 6 | C10: 송광치 | D10: 송광치 가평연계링 춘천H/P-화천H/P WEST(Rx) | N10: =IF(C10="",0,1) -> 1
A11: 7 | C11: 차세대KepCIT | D11: 차세대KepCIT 강원#1링(화천B/O-본부) | N11: =IF(C11="",0,1) -> 1
A12: 8 | C12: 차세대KepCIT | D12: 차세대KepCIT 강원#1링(화천B/O-본부) | N12: =IF(C12="",0,1) -> 1
A13: 9 | C13: 송광치 | D13: 송광치 춘천#1링 춘천H/P-화천 WEST 패치 | N13: =IF(C13="",0,1) -> 1
A14: 10 | C14: 송광치 | D14: 송광치 춘천#1링 춘천H/P-화천 WEST 패치 | N14: =IF(C14="",0,1) -> 1
A15: 11 | C15: 송광치 | D15: 송광치 가평링 춘천H/P 패치(화천H/P-가평S/S) EAST(Tx) | N15: =IF(C15="",0,1) -> 1
A16: 12 | C16: 송광치 | D16: 송광치 가평링 춘천H/P 패치(화천H/P-가평S/S) EAST(Rx) | N16: =IF(C16="",0,1) -> 1
A17: 13 | C17: 차세대KepCIT | D17: 차세대KepCIT 경기북부링 패치 | N17: =IF(C17="",0,1) -> 1
A18: 14 | C18: 차세대KepCIT | D18: 차세대KepCIT 경기북부링 패치 | N18: =IF(C18="",0,1) -> 1
A19: 15 | F19: -8.636 | G19: 23.7988 | H19: -5.253 | I19: 23.7989 | N19: =IF(C19="",0,1) -> 0
A20: 16 | F20: -12.682 | G20: 32.3165 | H20: -8.972 | I20: 32.318 | N20: =IF(C20="",0,1) -> 0
A21: 17 | F21: -12.396 | G21: 32.102 | H21: -8.812 | I21: 32.1037 | N21: =IF(C21="",0,1) -> 0
A22: 18 | F22: -12.457 | G22: 32.1046 | H22: -8.889 | I22: 32.101 | N22: =IF(C22="",0,1) -> 0
A23: 19 | F23: -8.77 | G23: 23.7988 | H23: -5.171 | I23: 23.7989 | N23: =IF(C23="",0,1) -> 0
A24: 20 | C24: SCADA | D24: RTU 예비회선용 광스위치 북춘천-철원(화천수력-화천 중계) | N24: =IF(C24="",0,1) -> 1
A25: 21 | F25: -11.923 | G25: 32.1161 | H25: -7.418 | I25: 32.1126 | N25: =IF(C25="",0,1) -> 0
A26: 22 | F26: -11.923 | G26: 32.1173 | H26: -7.823 | I26: 32.1152 | N26: =IF(C26="",0,1) -> 0
A27: 23 | F27: -12.985 | G27: 32.1173 | H27: -8.288 | I27: 32.1139 | N27: =IF(C27="",0,1) -> 0
A28: 24 | F28: -12.402 | G28: 32.1135 | H28: -7.709 | I28: 32.1177 | N28: =IF(C28="",0,1) -> 0 | O28: =SUM(F7:F8,F19:F23,F25:F28)/11 -> -11.702818 | P28: =SUM(H7:H8,H19:H23,H25:H28)/11 -> -7.7458182
A29: 관리사업소 | D29: 장소 | E29: 업데이트 | F29: 측정현황 (2024-10-17) / 측정자 유상민 | K29: 선로명 | L29: 긍장/실장 (km) | M29: 비금속 (km) | N29: =IF(C29="",0,1) -> 0
A30: 강원본부 전자제어부 | D30: 화천수력발전소 | E30: 2025.12.30 | F30: 1310um | H30: 1550um | J30: 결 과 [표준손실 기준] | N30: =IF(C30="",0,1) -> 0
F31: 표준손실(dB) | G31: =전송손실!M21 -> -11.017604 | H31: 표준손실(dB) | I31: =전송손실!M47 -> -7.295758
A32: No. | B32: 상대국명 | C32: 유형 | D32: 회선수용내역 | E32: 비고 | F32: 손실Data(dB) | G32: 측정거리(km) | H32: 손실Data(dB) | I32: 측정거리(km) | N32: =IF(C32="",0,1) -> 1
A33: 1 | B33: 화천S/S | C33: SCADA | D33: RTU 예비회선용 광스위치 북춘천-철원(화천수력-화천 중계) | K33: 154kV 화천수력T/L | N33: =IF(C33="",0,1) -> 1
A34: 2 | C34: SCADA | D34: RTU 예비회선용 광스위치 화천-양구(화천수력 중계) | N34: =IF(C34="",0,1) -> 1
A35: 3 | C35: 소형광 | D35: 통합PTP 화천S/S-화천H/P EAST (Rx) | N35: =IF(C35="",0,1) -> 1
A36: 4 | C36: 소형광 | D36: 통합PTP 화천S/S-화천H/P EAST (Tx) | N36: =IF(C36="",0,1) -> 1
A37: 5 | F37: -15.241 | G37: 18.7945 | H37: -18.331 | I37: 18.7929 | N37: =IF(C37="",0,1) -> 0
A38: 6 | F38: -14.013 | G38: 18.7945 | H38: -17.678 | I38: 18.7929 | N38: =IF(C38="",0,1) -> 0
A39: 7 | F39: -17.347 | G39: 18.797 | H39: -21.963 | I39: 18.7967 | N39: =IF(C39="",0,1) -> 0
A40: 8 | F40: -8.143 | G40: 18.7945 | H40: -5.84 | I40: 18.7929 | N40: =IF(C40="",0,1) -> 0
...

Sheet 춘천HP
A1: 관리사업소 | D1: 장소 | E1: 업데이트 | F1: 측정현황 (2024-11-27) / 측정자 최준영 | K1: 선로명 | L1: 긍장/실장 (km) | M1: 비금속 (km) | N1: =COUNTIF(N5:N507,0)/COUNT(A:A) -> 0.5
A2: 강원본부 전자제어부 | D2: 춘천수력발전소 | E2: 2025.12.30 | F2: 1310um | H2: 1550um | J2: 결 과 [표준손실 기준]
F3: 표준손실(dB) | G3: =전송손실!M20 -> -14.64836 | H3: 표준손실(dB) | I3: =전송손실!M46 -> -9.65622
A4: No. | B4: 상대국명 | C4: 유형 | D4: 회선수용내역 | E4: 비고 | F4: 손실Data(dB) | G4: 측정거리(km) | H4: 손실Data(dB) | I4: 측정거리(km)
A5: 1 | B5: 가평S/S (좌측 2열) | C5: 송광치 | D5: 송광치 가평연계링 가평-화천H/P 패치 가평EAST 패치(Tx) | K5: 154kV 한강분기T/L 154kV 화천T/L | N5: =IF(C5="",0,1) -> 1
A6: 2 | C6: 송광치 | D6: 송광치 가평연계링 가평-화천H/P 패치 가평EAST 패치(Rx) | N6: =IF(C6="",0,1) -> 1
A7: 3 | C7: 송광치 | D7: 송광치 가평연계링 가평-화천WEST 패치 가평WEST(Tx) | N7: =IF(C7="",0,1) -> 1
A8: 4 | C8: 송광치 | D8: 송광치 가평연계링 가평-화천WEST 패치 가평WEST(Rx) | N8: =IF(C8="",0,1) -> 1
A9: 5 | C9: 차세대KepCIT | D9: 차세대KepCIT 경기북부링 패치 | N9: =IF(C9="",0,1) -> 1
A10: 6 | C10: 차세대KepCIT | D10: 차세대KepCIT 경기북부링 패치 | N10: =IF(C10="",0,1) -> 1
A11: 7 | D11: 구KepCIt(철거X) | N11: =IF(C11="",0,1) -> 0
A12: 8 | D12: 구KepCIt(철거X) | N12: =IF(C12="",0,1) -> 0
A13: 9 | F13: -11.375 | G13: 31.781 | H13: -8.657 | I13: 31.799 | J13: 적 합 | N13: =IF(C13="",0,1) -> 0
A14: 10 | F14: -11.288 | G14: 31.783 | H14: -7.113 | I14: 31.793 | J14: 적 합 | N14: =IF(C14="",0,1) -> 0
A15: 11 | D15: 구KepCIt(철거X) | N15: =IF(C15="",0,1) -> 0
A16: 12 | D16: 구KepCIt(철거X) | N16: =IF(C16="",0,1) -> 0
A17: 13 | F17: -11.436 | G17: 31.786 | H17: -8.182 | I17: 31.801 | J17: 적 합 | N17: =IF(C17="",0,1) -> 0
