Workbook

Sheet 개정이력
A1: 광단국 선번장 개정이력
A3: 개정일자 | B3: 선번장 | F3: 변경내역 | H3: 사 유 | I3: 비 고
B4: 설치장소 | C4: 설비종류 | D4: 카드종류 | E4: 포트번호 | F4: 회선내역(개정전) | G4: 회선내역(개정후)
A5: 2017.01.13 | B5: 화천S/S | C5: 통합PTP | D5: LIU | E5: 1,2,4,5 | F5: - | G5: - | H5: 현황정리
A6: 2017.01.13 | B6: 화천S/S | C6: 통합단말 | D6: LIU | E6: 1-8 | F6: - | G6: - | H6: 현황정리
A7: 2017.03.09 | B7: 양구S/S | C7: P32T(인제계) | D7: 4W E/M | E7: 3, 4 | H7: 현황정리
B8: 양구S/S | C8: P32T(상남계) | D8: 4W E/M | E8: 2 | H8: 현황정리
A9: 2017.11.06 | B9: 춘천S/S | C9: CMUX(강릉) | D9: 4W E/M | E9: 12 | F9: - | G9: 신평창ADS | H9: 포트생성
B10: 본부 | C10: CMUX(강릉) | D10: 4W E/M | E10: 11 | F10: 영월CC DAS | G10: 신평창DAS | H10: 포트생성
A11: 2017.11.07 | B11: 춘천S/S | C11: OMS(본부계) | D11: ETU | E11: 8 | F11: - | G11: CMUX | H11: 포트생성
B12: 본부 | C12: OMS(춘천계) | D12: ETU | E12: 8 | F12: - | G12: CMUX | H12: 포트생성
A13: 2017.11.08 | B13: 춘천S/S | C13: PTP(본부계) | D13: E1 | E13: 6,9 | F13: - | G13: 송변전감시 | H13: 포트생성
B14: 본부 | C14: PTP(춘천계) | D14: E1 | E14: 6,9 | F14: - | G14: 송변전감시 | H14: 포트생성

Sheet 본부통신실
A1: 본부통신실 광단국선번장('25.06.23)
A2: 설치장소 | B2: 대국장소 | C2: 순번 | D2: 카드 | E2: 회선 사용 내역 | I2: 카드 | J2: 중계경로
A3: 본부 | B3: 춘천(구) | C3: 1 | D3: E1/T1 | E3: E1 | F3: C-MUX | H3: 본부-춘천#1 | I3: E1/T1 | J3: 본부-(송변PTPU:1)-춘천
A4: 송변PTPU | C4: 2 | E4: E1 | F4: 데이터링크 | H4: 거래소(의왕)-춘천 | J4: 춘천-(송변PTPU:2)-강원본부[KepCIT PQM()]-원주PO[MSPP PQM()]
A5: 2022.05 UPDATE | C5: 3 | E5: T1 | F5: C-MUX | H5: 본부-춘천#2 | J5: 춘천-(송변PTPU:3)-춘천
C6: 4 | E6: E1 | F6: C-MUX | H6: 춘천S/S-강릉P/O | J6: 춘천-(송변PTPU:4)-강원본부[MSPP PQM52(38)-강릉PO[MSPP PQM2(24)]
C7: 5 | D7: E1/T1 | E7: E1 | F7: C-MUX | H7: 춘천-동해 | I7: E1/T1 | J7: 춘천-(송변PTPU:5)-강원본부#2[MSPP PQM(4)-동해PO[MSPP PQM(4)]
C8: 6 | E8: E1 | F8: 배전전력구 | H8: 남춘천 배전전력구 화상감시#1 | J8: 남춘천-(9:통합단말:10)-춘천-(송변PTPU:6)-본부
C9: 7 | E9: E1 | F9: 배전전력구 | H9: 남춘천 배전전력구 화상감시#2 | J9: 남춘천-(10:통합단말:11)-춘천-(송변PTPU:7)-본부
C10: 8 | E10: E1 | F10: 배전전력구 | H10: 남춘천 배전전력구 화상감시#3 | J10: 남춘천-(11:통합단말:12)-춘천-(송변PTPU:8)-본부
C11: 9 | D11: E1/T1 | I11: E1/T1
C12: 10
C13: 11
C14: 12
A15: 본부 | B15: 춘천(구) | C15: 1 | D15: E1/T1 | E15: T1 | F15: 데이터링크 | H15: 거래소-춘천 | I15: E1/T1 | J15: 본사[MSPP_W 52-PQM-17]-(MSPP 52-PQM-15]강원DD-통합[1]-춘천S/S(급전소)
A16: 통합(P-to-P)#1 | C16: 2 | E16: E1 | K16: 동해 LIUDS 로 바꿀것
C17: 3 | E17: E1
C18: 4 | E18: E1 | F18: 급전분소 후비 | H18: 급전소-강릉 | J18: 강릉[MSPP_2_PQM-25]-강원DD[MSPP_52_PQM-30]-통합[4]-춘천S/S-ETH_CSU
C19: 5 | E19: E1 | F19: 급전분소 후비 | H19: 급전소-원주 | J19: 원주[MSPP_2_PQM-28]-강원DD[MSPP_52_PQM-41]-통합[5]-춘천S/S-ETH_CSU
C20: 6 | E20: E1 | F20: 송변전감시 | H20: 춘천-횡계 | J20: 춘천-6(PTP)본부#2[MSPP PQM(2)-강릉PO[MSPP PQM(2)]
C21: 7 | E21: E1 | F21: CMS-PLUS | H21: 춘천(구)-원주 | J21: 춘천-7(PTP)-본부[MSPP PQM()-원주PO[MSPP PQM()]
C22: 8 | E22: E1
C23: 9 | E23: E1 | F23: 송변전감시 | H23: 춘천-영월 | J23: 춘천-9(PTP)-본부#2[MSPP PQM(3)-태백PO[MSPP PQM(1)]
C24: 10 | E24: E1 | F24: D-SCADA | H24: 원주 LIU DS | J24: 춘천-10(PTP)-본부[MSPP PQM(12)-원주PO[MSPP PQM(12)]
C25: 11 | E25: E1 | F25: MMI | H25: 강릉 원격MMI | J25: 춘천-11(PTP)-본부[MSPP PQM()-강릉PO[MSPP PQM()]
C26: 12 | E26: E1
C27: 1 | D27: 4W E&M | E27: 9.6K | I27: 4W E&M
C28: 2 | E28: 9.6K
C29: 3 | E29: 9.6K
C30: 4 | E30: 9.6K
A31: 본부 | B31: 춘천(구) | C31: 1 | D31: E1/T1 | E31: E1 | I31: E1/T1
A32: 통합(P-to-P)#2 | C32: 2 | E32: E1 | F32: 신재생 감시 | H32: 동해변전소 제어동 | J32: 동해 : 동해-(MSPP:49 - MSPP#2:5) - 강원본부 - (PTP#2:2) - 춘천(구) - 신재생발전원스위치3
C33: 3 | E33: E1
C34: 4 | E34: E1 | F34: 배전전력구 | H34: 화천배전전력구 | J34: 화천 ECSU-(4:통합단말:9)-춘천(구)(PTP#2 : 4 ) - 본부CSU - ~
C35: 5 | E35: E1 | F35: 배전전력구 | H35: 서홍천배전전력구 | J35: 서홍천 ECSU-(2:통합단말:9)-춘천(구)(PTP#2 : 5) - 본부CSU - ~
C36: 6 | E36: E1 | F36: 신재생 감시 | H36: 북평화력 | J36: 북평TP : 동해-(MSPP:50 - MSPP#2:6) - 강원본부 - (PTP#2:6) - 춘천(구) - 신재생발전원스위치4
C37: 7 | E37: E1 | F37: 신재생 감시 | H37: 삼척G/P | J37: 삼척GP : 동해-(MSPP:51 - MSPP#2:7) - 강원본부 - (PTP#2:7) - 춘천(구) - 신재생발전원스위치5
C38: 8
C39: 9
C40: 10 | L40: 2017.08수정
...

Sheet 춘천SS(구)
A1: (구)춘천S/S 광단국 선번장
A4: 설치장소 | B4: 대국장소 | C4: 순번 | D4: 카드 | E4: 회선 사용 내역 | I4: 카드 | J4: 중계경로
A5: 춘천(구) | B5: 본부 | C5: 1 | D5: E1/T1 | E5: E1 | F5: C-MUX | G5: =본부통신실!G3 | H5: 본부-춘천#1 | I5: E1/T1 | J5: 본부-(송변PTPU:1)-춘천
A6: 송변PTPU | C6: 2 | E6: E1 | F6: 데이터링크 | G6: =본부통신실!G4 | H6: 거래소(의왕)-춘천 | J6: 춘천-(송변PTPU:2)-강원본부[MSPP PQM()]-원주PO[MSPP PQM()]
A7: 2022.05 UPDATE | C7: 3 | E7: T1 | F7: C-MUX | G7: =본부통신실!G5 | H7: 본부-춘천#2 | J7: 춘천-(송변PTPU:3)-춘천
C8: 4 | E8: E1 | F8: C-MUX | G8: =본부통신실!G6 | H8: 춘천S/S-강릉P/O | J8: 춘천-(송변PTPU:4)-강원본부[MSPP PQM52(38)-강릉PO[MSPP PQM2(24)]
C9: 5 | E9: E1 | F9: C-MUX | H9: 춘천-동해 | J9: 춘천-(송변PTPU:5)-강원본부#2[MSPP PQM(4)-동해PO[MSPP PQM(4)]
C10: 6 | E10: E1 | F10: 배전전력구 | H10: 남춘천 배전전력구 화상감시#1 | J10: 남춘천-(9:통합단말:10)-춘천-(송변PTPU:6)-본부
C11: 7 | E11: E1 | F11: 배전전력구 | H11: 남춘천 배전전력구 화상감시#2 | J11: 남춘천-(10:통합단말:11)-춘천-(송변PTPU:7)-본부
C12: 8 | E12: E1 | F12: 배전전력구 | H12: 남춘천 배전전력구 화상감시#3 | J12: 남춘천-(11:통합단말:12)-춘천-(송변PTPU:8)-본부
C13: 9 | E13: =본부통신실!E11 | F13: =본부통신실!F11 | G13: =본부통신실!G11 | H13: =본부통신실!H11 | J13: =본부통신실!J11
C14: 10
C15: 11
C16: 12
A17: 춘천(구) | B17: 홍천 | C17: 1 | D17: E1/T1 | E17: E1 | F17: PIU | G17: 예비 | H17: 154 남춘천-춘천 T/L | I17: E1/T1 | J17: (신)춘천-(PTP#2:2)-(구)춘천-(PTP:1)-홍천-(PTP:2)-남춘천 | K17: 22.10 구성
A18: 송변PTPU | C18: 2 | E18: E1 | F18: CMS-PLUS | H18: 춘천-인제 | J18: 춘천-2(송변PTPU)-홍천-10-상남-6-인제 | K18: 22.10 구성
A19: 2022.10 UPDATE | C19: 3 | E19: T1 | F19: PITR | G19: 예비 | H19: 154 홍천-소양강HP T/L | J19: 홍천-3(송변PTPU)-춘천-5(OMS)-소양HP | K19: 22.10 구성
C20: 4 | E20: T1 | F20: PITR | G20: 예비 | H20: 154 춘천-소양강HP T/L | J20: 춘천-4(송변PTPU)-홍천-5소양H/P | K20: 22.10 구성
C21: 5
C22: 6
C23: 7
C24: 8
C25: 9
C26: 10
C27: 11
C28: 12
A29: 남춘천 | B29: 춘천(구) | C29: 1 | D29: T1/E1 | I29: T1/E1
A30: 통합PTP | C30: 2
A31: 2018.02 UPDATE | C31: 3
C32: 4
C33: 5
C34: 6
C35: 7
C36: 8
C37: 9
C38: 10
C39: 11
C40: 12
C41: 1 | D41: 4W E&M | I41: 4W E&M
C42: 2
...

Sheet 춘천SS(신)
A1: (신)춘천SS 광단국 선번장
A4: 설치장소 | B4: 대국장소 | C4: 순번 | D4: 카드 | E4: 회선 사용 내역 | I4: 카드 | J4: 중계경로
A5: 춘천(신) | B5: 춘천(구) | C5: 1 | D5: T1/E1 | E5: ='춘천SS(구)'!E93 -> T1 | F5: ='춘천SS(구)'!F93 -> PITR | G5: ='춘천SS(구)'!G93 -> 주 | H5: ='춘천SS(구)'!H93 -> 춘천-소양HP PITR㈜ | I5: T1/E1 | J5: ='춘천SS(구)'!J93 -> (구)춘천-(PTP#1:1)-(신)춘천-1-소양HP
A6: 통합PTP #1 E1/T1 | C6: 2
A7: 2017.07 UPDATE | C7: 3
C8: 4 | E8: ='춘천SS(구)'!E96 | F8: ='춘천SS(구)'!F96 | G8: ='춘천SS(구)'!G96 | H8: ='춘천SS(구)'!H96 | J8: ='춘천SS(구)'!J96
C9: 5 | E9: ='춘천SS(구)'!E97 -> E1 | F9: ='춘천SS(구)'!F97 -> 차세대SCADA | G9: ='춘천SS(구)'!G97 -> 주 | H9: ='춘천SS(구)'!H97 -> 춘천 D-SCADA | J9: ='춘천SS(구)'!J97 -> (구)춘천S/S - (PTP#1:5) - (신)춘천S/S
C10: 6 | E10: ='춘천SS(구)'!E98 | F10: ='춘천SS(구)'!F98 | G10: ='춘천SS(구)'!G98 | H10: ='춘천SS(구)'!H98 | J10: ='춘천SS(구)'!J98
C11: 7 | E11: ='춘천SS(구)'!E99 | F11: ='춘천SS(구)'!F99 | G11: ='춘천SS(구)'!G99 | H11: ='춘천SS(구)'!H99 | J11: ='춘천SS(구)'!J99
C12: 8 | E12: ='춘천SS(구)'!E100 | F12: ='춘천SS(구)'!F100 | G12: ='춘천SS(구)'!G100 | H12: ='춘천SS(구)'!H100 | J12: ='춘천SS(구)'!J100
C13: 9 | E13: ='춘천SS(구)'!E101 | F13: ='춘천SS(구)'!F101 | G13: ='춘천SS(구)'!G101 | H13: ='춘천SS(구)'!H101 | J13: ='춘천SS(구)'!J101
C14: 10 | E14: ='춘천SS(구)'!E102 | F14: ='춘천SS(구)'!F102 | G14: ='춘천SS(구)'!G102 | H14: ='춘천SS(구)'!H102 | J14: ='춘천SS(구)'!J102
C15: 11 | E15: ='춘천SS(구)'!E103 | F15: ='춘천SS(구)'!F103 | G15: ='춘천SS(구)'!G103 | H15: ='춘천SS(구)'!H103 | J15: ='춘천SS(구)'!J103
C16: 12 | E16: ='춘천SS(구)'!E104 | F16: ='춘천SS(구)'!F104 | G16: ='춘천SS(구)'!G104 | H16: ='춘천SS(구)'!H104 | J16: ='춘천SS(구)'!J104
C17: 1 | D17: 4W E&M | I17: 4W E&M
C18: 2
C19: 3
C20: 4 | E20: ='춘천SS(구)'!E108 | F20: ='춘천SS(구)'!F108 | G20: ='춘천SS(구)'!G108 | H20: ='춘천SS(구)'!H108
A21: 춘천(신) | B21: 춘천(구) | C21: 1 | D21: T1/E1 | E21: ='춘천SS(구)'!E109 -> T1 | F21: ='춘천SS(구)'!F109 -> PITR | G21: ='춘천SS(구)'!G109 -> 예비 | H21: ='춘천SS(구)'!H109 -> 춘천-소양HP PITR(예비) | I21: T1/E1 | J21: ='춘천SS(구)'!J109 -> (신)춘천-(PTP#2:1)-(구)춘천-15-홍천-5소양H/P
A22: 통합PTP #2 E1/T1 | C22: 2 | E22: E1 | F22: PIU | G22: ='춘천SS(구)'!G110 -> 예비 | H22: ='춘천SS(구)'!H110 -> 남춘천-춘천 PIU(예비) | J22: (신)춘천-(PTP#2:2)-(구)춘천-(PTP:1)-홍천-(PTP:2)-남춘천
A23: 2017.07 UPDATE | C23: 3 | E23: ='춘천SS(구)'!E111 -> T1 | F23: ='춘천SS(구)'!F111 -> PITR | G23: ='춘천SS(구)'!G111 -> 예비 | H23: ='춘천SS(구)'!H111 -> 춘천-북춘천#1,2T/L PITR(예비) | J23: ='춘천SS(구)'!J111 -> (신)춘천-(통합PTP#2:3)-(구)춘천-(통합PTP:1)-북춘천
C24: 4 | E24: ='춘천SS(구)'!E112 | F24: ='춘천SS(구)'!F112 | G24: ='춘천SS(구)'!G112 | H24: ='춘천SS(구)'!H112 | J24: ='춘천SS(구)'!J112
C25: 5 | E25: ='춘천SS(구)'!E113 | F25: ='춘천SS(구)'!F113 | G25: ='춘천SS(구)'!G113 | H25: ='춘천SS(구)'!H113 | J25: ='춘천SS(구)'!J113
C26: 6 | E26: ='춘천SS(구)'!E114 | F26: ='춘천SS(구)'!F114 | G26: ='춘천SS(구)'!G114 | H26: ='춘천SS(구)'!H114 | J26: ='춘천SS(구)'!J114
C27: 7 | E27: ='춘천SS(구)'!E115 | F27: ='춘천SS(구)'!F115 | G27: ='춘천SS(구)'!G115 | H27: ='춘천SS(구)'!H115 | J27: ='춘천SS(구)'!J115
C28: 8 | E28: ='춘천SS(구)'!E116 | F28: ='춘천SS(구)'!F116 | G28: ='춘천SS(구)'!G116 | H28: ='춘천SS(구)'!H116 | J28: ='춘천SS(구)'!J116
C29: 9 | E29: ='춘천SS(구)'!E117 | F29: ='춘천SS(구)'!F117 | G29: ='춘천SS(구)'!G117 | H29: ='춘천SS(구)'!H117 | J29: ='춘천SS(구)'!J117
C30: 10 | E30: ='춘천SS(구)'!E118 | F30: ='춘천SS(구)'!F118 | G30: ='춘천SS(구)'!G118 | H30: ='춘천SS(구)'!H118 | J30: ='춘천SS(구)'!J118
C31: 11 | E31: ='춘천SS(구)'!E119 | F31: ='춘천SS(구)'!F119 | G31: ='춘천SS(구)'!G119 | H31: ='춘천SS(구)'!H119 | J31: ='춘천SS(구)'!J119
C32: 12 | E32: ='춘천SS(구)'!E120 | F32: ='춘천SS(구)'!F120 | G32: ='춘천SS(구)'!G120 | H32: ='춘천SS(구)'!H120 | J32: ='춘천SS(구)'!J120
C33: 1 | D33: 4W E&M | I33: 4W E&M
C34: 2 | E34: ='춘천SS(구)'!E122 | F34: ='춘천SS(구)'!F122 | G34: ='춘천SS(구)'!G122 | H34: ='춘천SS(구)'!H122 | J34: ='춘천SS(구)'!J122
C35: 3 | E35: ='춘천SS(구)'!E123 | F35: ='춘천SS(구)'!F123 | G35: ='춘천SS(구)'!G123 | H35: ='춘천SS(구)'!H123 | J35: ='춘천SS(구)'!J123
C36: 4 | E36: ='춘천SS(구)'!E124 | F36: ='춘천SS(구)'!F124 | G36: ='춘천SS(구)'!G124 | H36: ='춘천SS(구)'!H124 | J36: ='춘천SS(구)'!J124

Sheet 남춘천SS
A1: 남춘천S/S 광단국 선번장
A4: 설치장소 | B4: 대국장소 | C4: 순번 | D4: 카드 | E4: 회선 사용 내역 | I4: 카드 | J4: 중계경로
A5: 남춘천 | B5: 홍천 | C5: 1 | D5: E1/T1 | E5: E1 | F5: PIU | G5: 예비 | H5: 남춘천-홍천 PIU | J5: 남춘천-(PTP:1)-홍천 | K5: 22년 10.구성
A6: 송변PTPU | C6: 2 | E6: E1 | F6: PIU | G6: 예비 | H6: 남춘천-춘천 PIU | J6: (신)춘천-(PTP#2:2)-(구)춘천-(PTP:1)-홍천-(PTP:2)-남춘천 | K6: 22년 10.구성
A7: 2022.10 UPDATE | C7: 3
C8: 4
C9: 5
C10: 6
C11: 7
C12: 8
C13: 9
C14: 10
C15: 11
C16: 12
A17: 남춘천 | B17: 춘천(구) | C17: 1 | D17: T1/E1 | I17: T1/E1
A18: 통합PTP | C18: 2
A19: 2018.02 UPDATE | C19: 3
C20: 4
C21: 5
C22: 6
C23: 7 | E23: ='춘천SS(구)'!E35 | F23: ='춘천SS(구)'!F35 | G23: ='춘천SS(구)'!G35 | H23: ='춘천SS(구)'!H35 | J23: ='춘천SS(구)'!J35
C24: 8 | E24: ='춘천SS(구)'!E36 | F24: ='춘천SS(구)'!F36 | G24: ='춘천SS(구)'!G36 | H24: ='춘천SS(구)'!H36 | J24: ='춘천SS(구)'!J36
C25: 9 | E25: ='춘천SS(구)'!E37 | F25: ='춘천SS(구)'!F37 | G25: ='춘천SS(구)'!G37 | H25: ='춘천SS(구)'!H37 | J25: ='춘천SS(구)'!J37
C26: 10 | E26: ='춘천SS(구)'!E38 | F26: ='춘천SS(구)'!F38 | G26: ='춘천SS(구)'!G38 | H26: ='춘천SS(구)'!H38 | J26: ='춘천SS(구)'!J38
C27: 11 | E27: ='춘천SS(구)'!E39 | F27: ='춘천SS(구)'!F39 | G27: ='춘천SS(구)'!G39 | H27: ='춘천SS(구)'!H39 | J27: ='춘천SS(구)'!J39
C28: 12 | E28: ='춘천SS(구)'!E40 | F28: ='춘천SS(구)'!F40 | G28: ='춘천SS(구)'!G40 | H28: ='춘천SS(구)'!H40 | J28: ='춘천SS(구)'!J40
A29: 남춘천 | B29: 홍천 | C29: 1 | D29: T1/E1 | I29: T1/E1
A30: 통합PTP | C30: 2
A31: 2018.02 UPDATE | C31: 3
C32: 4 | E32: E1 | F32: 차세대SCADA | G32: 주 | H32: 양구 D-SCADA | J32: 양구-(PTP:1)-상남-(PTP:6)-홍천-(PTP:4)-남춘천-(PTP:4)-춘천(구)
C33: 5 | E33: E1 | F33: 차세대SCADA | G33: 주 | H33: 인제 D-SCADA | J33: 인제-(PTP:3)-상남-(PTP:7)-홍천(PTP:5)-남춘천-(PTP:5)-춘천
C34: 6
C35: 7
C36: 8
C37: 9
C38: 10
C39: 11
C40: 12
A41: 남춘천 | B41: 열병합 | C41: 1 | D41: T1/E1 | E41: E1 | F41: PITR | G41: 주 | H41: 남춘천-열병합#2 PITR | I41: T1/E1 | J41: 남춘천-1(PTP)-열병합
A42: 통합PTP | C42: 2 | E42: E1 | F42: PITR | G42: 주 | H42: 남춘천-열병합#1 PITR | J42: 남춘천-2(PTP)-열병합
...

Sheet 북춘천SS
A1: 북춘천S/S 광단국 선번장
A4: 설치장소 | B4: 대국장소 | C4: 순번 | D4: 카드 | E4: 회선 사용 내역 | I4: 카드 | J4: 중계경로
A5: 북춘천 | B5: 춘천(구) | C5: 1 | D5: T1/E1 | E5: ='춘천SS(구)'!E125 -> T1 | F5: ='춘천SS(구)'!F125 -> PITR | G5: ='춘천SS(구)'!G125 -> 예비 | H5: ='춘천SS(구)'!H125 -> 춘천-북춘천 | I5: T1/E1 | J5: ='춘천SS(구)'!J125 -> (신)춘천-(통합PTP#2:3)-(구)춘천-(통합PTP:1)-북춘천
A6: 통합PTP | C6: 2 | E6: ='춘천SS(구)'!E126 -> E1 | F6: ='춘천SS(구)'!F126 -> CMS-PLUS | G6: ='춘천SS(구)'!G126 | H6: ='춘천SS(구)'!H126 -> 춘천-북춘천 | J6: ='춘천SS(구)'!J126 -> 춘천-(PTPU:2)-북춘천
A7: 2018.02 UPDATE | C7: 3 | E7: ='춘천SS(구)'!E127 -> E1 | F7: ='춘천SS(구)'!F127 -> PDAS | G7: ='춘천SS(구)'!G127 | H7: ='춘천SS(구)'!H127 -> 춘천-화천수력 | J7: ='춘천SS(구)'!J127 -> 춘천-(PTPU:3)-북춘천-5-화천수력
C8: 4 | E8: ='춘천SS(구)'!E128 -> E1 | F8: ='춘천SS(구)'!F128 -> PDAS | G8: ='춘천SS(구)'!G128 | H8: ='춘천SS(구)'!H128 -> 춘천수력 | J8: ='춘천SS(구)'!J128 -> 춘천-4(통합PTP)4-북춘천-4(통합PTP)4-가평-3(OMS)3-춘천HP
C9: 5 | E9: ='춘천SS(구)'!E129 -> E1 | F9: ='춘천SS(구)'!F129 -> 디지털SCADA | G9: ='춘천SS(구)'!G129 -> 예비 | H9: ='춘천SS(구)'!H129 -> 인제디지털SCADA | J9: ='춘천SS(구)'!J129 -> 춘천(구)-(PTP:5)-북춘천-(PTPU:2)-화천HP-(PTPU:3)-양구-(OMS:2)-인제
C10: 6 | E10: ='춘천SS(구)'!E130 | F10: ='춘천SS(구)'!F130 | G10: ='춘천SS(구)'!G130 | H10: ='춘천SS(구)'!H130 | J10: ='춘천SS(구)'!J130
C11: 7 | E11: ='춘천SS(구)'!E131 -> E1 | F11: ='춘천SS(구)'!F131 -> 차세대SCADA | G11: ='춘천SS(구)'!G131 -> 주 | H11: ='춘천SS(구)'!H131 -> 북춘천 D-SCADA | J11: ='춘천SS(구)'!J131 -> 북춘천 - (PTP:7) - 춘천(구)
C12: 8
C13: 9
C14: 10 | E14: ='춘천SS(구)'!E134 | F14: ='춘천SS(구)'!F134 | G14: ='춘천SS(구)'!G134 | H14: ='춘천SS(구)'!H134 | J14: ='춘천SS(구)'!J134
C15: 11 | E15: ='춘천SS(구)'!E135 | F15: ='춘천SS(구)'!F135 | G15: ='춘천SS(구)'!G135 | H15: ='춘천SS(구)'!H135 | J15: ='춘천SS(구)'!J135
C16: 12 | E16: ='춘천SS(구)'!E136 | F16: ='춘천SS(구)'!F136 | G16: ='춘천SS(구)'!G136 | H16: ='춘천SS(구)'!H136 | J16: ='춘천SS(구)'!J136
C17: 1 | D17: 4W E&M | E17: ='춘천SS(구)'!E137 | F17: ='춘천SS(구)'!F137 | G17: ='춘천SS(구)'!G137 | H17: ='춘천SS(구)'!H137 | I17: 4W E&M | J17: ='춘천SS(구)'!J137
C18: 2 | E18: ='춘천SS(구)'!E138 | F18: ='춘천SS(구)'!F138 | G18: ='춘천SS(구)'!G138 | H18: ='춘천SS(구)'!H138 | J18: ='춘천SS(구)'!J138
C19: 3 | E19: ='춘천SS(구)'!E139 | F19: ='춘천SS(구)'!F139 | G19: ='춘천SS(구)'!G139 | H19: ='춘천SS(구)'!H139 | J19: ='춘천SS(구)'!J139
C20: 4 | E20: ='춘천SS(구)'!E140 | F20: ='춘천SS(구)'!F140 | G20: ='춘천SS(구)'!G140 | H20: ='춘천SS(구)'!H140 | J20: ='춘천SS(구)'!J140
A21: 북춘천 | B21: 화천HP | C21: 1 | D21: T1/E1
A22: 통합PTP | C22: 2
A23: 2018.02 UPDATE | C23: 3
C24: 4 | E24: E1 | F24: P32-T | H24: 북춘천-화천수력 P32T | J24: 북춘천-4(통합PTP)4-화천HP
C25: 5
C26: 6
C27: 7 | E27: E1 | F27: PIU | G27: 예비 | H27: 가평-화천수력 PIU(예) | J27: 가평-1(통합PTP)1-북춘천-7(PTP)-화천HP
C28: 8
C29: 9 | E29: E1 | F29: PIU | G29: 예비 | H29: 북춘천-화천수력 PIU(예) | J29: 북춘천-9(통합PTP)9-화천HP
C30: 10
C31: 11
C32: 12
C33: 1 | D33: 4W E&M | I33: 4W E&M
C34: 2
C35: 3
C36: 4
A37: 북춘천 | B37: 춘천HP | C37: 1 | D37: T1/E1 | E37: E1 | F37: P32-T | H37: 북춘천-춘천HP P32T | I37: T1/E1 | J37: 북춘천-1(PTP)-춘천HP
A38: 통합PTP | C38: 2
A39: 2018.02 UPDATE | C39: 3
C40: 4
C41: 5
C42: 6
...

Sheet 열병합
A1: 열병합SY 광단국선번장
A4: 설치장소 | B4: 대국장소 | C4: 순번 | D4: 카드 | E4: 회선 사용 내역 | I4: 카드 | J4: 중계경로
A5: 열병합 | B5: 서홍천 | C5: 1 | D5: E1/T1 | E5: E1 | F5: PITR | G5: 예비 | H5: 청평PP-열병합 PITR | I5: E1/T1 | J5: 청평PP-(OMS:1)-서홍천-(송변PTPU:1)-열병합
A6: 송변PTPU | C6: 2 | E6: E1 | F6: PITR | G6: 예비 | H6: 서홍천-청평PP PITR | J6: 서홍천-(송변PTPU:2)-열병합-(PTP:2)-청평PP
A7: 2022.05 UPDATE | C7: 3 | E7: T1 | F7: PITR | G7: 예비 | H7: 열병합-서종 SPS PITR | J7: 청평PP-(OMS:3)-서홍천-(송변PTPU:3)-열병합-(PTP#2:2)-춘천에너지
C8: 4
C9: 5 | D9: E1/T1 | E9: T1 | F9: PITR | G9: 주 | H9: 서홍천-열병합 PITR | I9: E1/T1 | J9: 서홍천-(송변PTPU:5)-열병합
C10: 6 | E10: E1 | F10: 차세대SCADA | G10: 주 | H10: 서홍천 D-SCADA | J10: 서홍천-(송변PTPU:6)-열병합-(PTP:5)-남춘천-(PTP:3)-춘천(구)
C11: 7
C12: 8
C13: 9 | D13: E1/T1 | I13: E1/T1
C14: 10
C15: 11
C16: 12
A17: 열병합 | B17: 남춘천 | C17: 1 | D17: T1/E1 | E17: =남춘천SS!E41 -> E1 | F17: =남춘천SS!F41 -> PITR | G17: =남춘천SS!G41 -> 주 | H17: =남춘천SS!H41 -> 남춘천-열병합#2 PITR | I17: T1/E1 | J17: =남춘천SS!J41 -> 남춘천-1(PTP)-열병합
A18: 통합PTP | C18: 2 | E18: =남춘천SS!E42 -> E1 | F18: =남춘천SS!F42 -> PITR | G18: =남춘천SS!G42 -> 주 | H18: =남춘천SS!H42 -> 남춘천-열병합#1 PITR | J18: =남춘천SS!J42 -> 남춘천-2(PTP)-열병합
A19: 2018.03 UPDATE | C19: 3 | E19: =남춘천SS!E43 -> T1 | F19: =남춘천SS!F43 -> PITR | G19: =남춘천SS!G43 -> 주 | H19: =남춘천SS!H43 -> 남춘천-열병합 SPS PITR | J19: =남춘천SS!J43 -> 남춘천-3(PTP)-열병합
C20: 4 | E20: =남춘천SS!E44 -> E1 | F20: =남춘천SS!F44 -> 차세대SCADA | G20: =남춘천SS!G44 -> 주 | H20: =남춘천SS!H44 -> 열병합 D-SCADA | J20: =남춘천SS!J44 -> 열병합-(PTP:4)-남춘천-(PTP:2)-춘천(구)
C21: 5 | E21: =남춘천SS!E45 -> E1 | F21: =남춘천SS!F45 -> 차세대SCADA | G21: =남춘천SS!G45 -> 주 | H21: =남춘천SS!H45 -> 서홍천 D-SCADA | J21: =남춘천SS!J45 -> 서홍천-(OMS:6)-열병합-(PTP:5)-남춘천-(PTP:3)-춘천(구)
C22: 6 | E22: =남춘천SS!E46 | F22: =남춘천SS!F46 | G22: =남춘천SS!G46 | H22: =남춘천SS!H46 | J22: =남춘천SS!J46
C23: 7 | E23: =남춘천SS!E47 | F23: =남춘천SS!F47 | G23: =남춘천SS!G47 | H23: =남춘천SS!H47 | J23: =남춘천SS!J47
C24: 8 | E24: =남춘천SS!E48 | F24: =남춘천SS!F48 | G24: =남춘천SS!G48 | H24: =남춘천SS!H48 | J24: =남춘천SS!J48
C25: 9 | E25: =남춘천SS!E49 | F25: =남춘천SS!F49 | G25: =남춘천SS!G49 | H25: =남춘천SS!H49 | J25: =남춘천SS!J49
C26: 10 | E26: =남춘천SS!E50 | F26: =남춘천SS!F50 | G26: =남춘천SS!G50 | H26: =남춘천SS!H50 | J26: =남춘천SS!J50
C27: 11 | E27: =남춘천SS!E51 | F27: =남춘천SS!F51 | G27: =남춘천SS!G51 | H27: =남춘천SS!H51 | J27: =남춘천SS!J51
C28: 12 | E28: =남춘천SS!E52 | F28: =남춘천SS!F52 | G28: =남춘천SS!G52 | H28: =남춘천SS!H52 | J28: =남춘천SS!J52
C29: 1 | D29: 4W E&M | E29: =남춘천SS!E53 | F29: =남춘천SS!F53 | G29: =남춘천SS!G53 | H29: =남춘천SS!H53 | I29: 4W E&M | J29: =남춘천SS!J53
C30: 2 | E30: =남춘천SS!E54 | F30: =남춘천SS!F54 | G30: =남춘천SS!G54 | H30: =남춘천SS!H54 | J30: =남춘천SS!J54
C31: 3 | E31: =남춘천SS!E55 | F31: =남춘천SS!F55 | G31: =남춘천SS!G55 | H31: =남춘천SS!H55 | J31: =남춘천SS!J55
C32: 4 | E32: =남춘천SS!E56 | F32: =남춘천SS!F56 | G32: =남춘천SS!G56 | H32: =남춘천SS!H56 | J32: =남춘천SS!J56
A33: 열병합 | B33: 서홍천 | C33: 1 | D33: T1/E1 | I33: T1/E1
A34: 통합PTP | C34: 2
A35: 2018.03 UPDATE | C35: 3
A36: 장비 안살림 | C36: 4
C37: 5
C38: 6
C39: 7
C40: 8
C41: 9
C42: 10
...

Sheet 서홍천SS
A1: 서홍천S/S 광단국선번장
A4: 설치장소 | B4: 대국장소 | C4: 순번 | D4: 카드 | E4: 회선 사용 내역 | I4: 카드 | J4: 중계경로
A5: 서홍천 | B5: 열병합 | C5: 1 | D5: E1/T1 | E5: =열병합!E5 -> E1 | F5: =열병합!F5 -> PITR | G5: =열병합!G5 -> 예비 | H5: =열병합!H5 -> 청평PP-열병합 PITR | I5: E1/T1 | J5: =열병합!J5 -> 청평PP-(OMS:1)-서홍천-(송변PTPU:1)-열병합
A6: 송변PTPU | C6: 2 | E6: =열병합!E6 -> E1 | F6: =열병합!F6 -> PITR | G6: =열병합!G6 -> 예비 | H6: =열병합!H6 -> 서홍천-청평PP PITR | J6: =열병합!J6 -> 서홍천-(송변PTPU:2)-열병합-(PTP:2)-청평PP
A7: 2022.05 UPDATE | C7: 3 | E7: =열병합!E7 -> T1 | F7: =열병합!F7 -> PITR | G7: =열병합!G7 -> 예비 | H7: =열병합!H7 -> 열병합-서종 SPS PITR | J7: =열병합!J7 -> 청평PP-(OMS:3)-서홍천-(송변PTPU:3)-열병합-(PTP#2:2)-춘천에너지
C8: 4 | E8: =열병합!E8 | F8: =열병합!F8 | G8: =열병합!G8 | H8: =열병합!H8 | J8: =열병합!J8
C9: 5 | D9: E1/T1 | E9: =열병합!E9 -> T1 | F9: =열병합!F9 -> PITR | G9: =열병합!G9 -> 주 | H9: =열병합!H9 -> 서홍천-열병합 PITR | I9: E1/T1 | J9: =열병합!J9 -> 서홍천-(송변PTPU:5)-열병합
C10: 6 | E10: =열병합!E10 -> E1 | F10: =열병합!F10 -> 차세대SCADA | G10: =열병합!G10 -> 주 | H10: =열병합!H10 -> 서홍천 D-SCADA | J10: =열병합!J10 -> 서홍천-(송변PTPU:6)-열병합-(PTP:5)-남춘천-(PTP:3)-춘천(구)
C11: 7 | E11: =열병합!E11 | F11: =열병합!F11 | G11: =열병합!G11 | H11: =열병합!H11 | J11: =열병합!J11
C12: 8 | E12: =열병합!E12 | F12: =열병합!F12 | G12: =열병합!G12 | H12: =열병합!H12 | J12: =열병합!J12
C13: 9 | D13: E1/T1 | E13: =열병합!E13 | F13: =열병합!F13 | G13: =열병합!G13 | H13: =열병합!H13 | I13: E1/T1 | J13: =열병합!J13
C14: 10 | E14: =열병합!E14 | F14: =열병합!F14 | G14: =열병합!G14 | H14: =열병합!H14 | J14: =열병합!J14
C15: 11 | E15: =열병합!E15 | F15: =열병합!F15 | G15: =열병합!G15 | H15: =열병합!H15 | J15: =열병합!J15
C16: 12 | E16: =열병합!E16 | F16: =열병합!F16 | G16: =열병합!G16 | H16: =열병합!H16 | J16: =열병합!J16
A17: 서홍천 | B17: 청평PP | C17: 1 | D17: ETU | E17: E1 | F17: PITR | G17: 예비 | H17: 청평PP-열병합 PITR | I17: ETU | J17: 청평PP-1-서홍천-1-열병합
A18: OMS-PLUS | C18: 2 | E18: E1 | F18: P32T | H18: 서홍천-청평PP P32T | J18: 청평PP-2-서홍천
A19: 2018.02 UPDATE | C19: 3 | E19: E1 | F19: PITR | G19: 예비 | H19: 열병합-서종 SPS PITR | J19: 청평PP-3-서홍천-3-열병합
C20: 4
C21: 5 | D21: ETU | E21: E1 | F21: PITR | G21: 주 | H21: 서홍천-청평PP PITR | I21: ETU | J21: 청평PP-5-서홍천
C22: 6
C23: 7
C24: 8
C25: 9 | D25: ETU | I25: ETU
C26: 10
C27: 11
C28: 12
C29: 13
C30: 14
C31: 15
C32: 16
A33: 서홍천 | B33: 청평양수 | C33: 1 | D33: 2W 4W E&M | F33: 급전전화 | H33: 급전소~청평양수 | I33: SLC-T/E | J33: =본부통신실!J65 -> 본부-19(CMUX)-춘천-17(통합단말)13-서홍천-1(P32T)-청평PP
A34: P32-T | C34: 2
A35: 2018.02 UPDATE | C35: 3
C36: 4
C37: 5
C38: 6
C39: 7
C40: 8
C41: 9
C42: 10
...

Sheet 화천SS
A1: 화천S/S 광단국선번장
A4: 설치장소 | B4: 대국장소 | C4: 순번 | D4: 카드 | E4: 회선 사용 내역 | I4: 카드 | J4: 중계경로
A5: 화천 | B5: 철원 | C5: 1 | D5: LIU | E5: E1 | F5: PIU | G5: 예비 | H5: 철원-화천 #1T/L | I5: LIU | J5: 철원-1-화천
A6: 통합(P-to-P) E1/T1 | C6: 2 | E6: E1 | F6: PIU | G6: 예비 | H6: 철원-화천 #2T/L | J6: 철원-2-화천
A7: 2018.02 UPDATE | C7: 3
C8: 4
C9: 5
C10: 6
C11: 7
C12: 8
C13: 9
C14: 10
C15: 11
C16: 12
A17: 통합(P-to-P) 4W/EM | C17: 1 | D17: 4W E&M | I17: 4W E&M
C18: 2
C19: 3
C20: 4
A21: 화천 | B21: 화천HP | C21: 1 | D21: LIU | E21: E1 | F21: PIU | G21: 예비 | H21: 화천-화천HP #1T/L | I21: LIU | J21: 화천-(PTP:1)-화천HP | K21: `22.09.14 구성
A22: 통합(P-to-P) E1/T1 | C22: 2 | E22: E1 | F22: PIU | G22: 예비 | H22: 화천-화천HP #2T/L | J22: 화천-(PTP:2)-화천HP | K22: `22.09.14 구성
A23: 2018.02 UPDATE | C23: 3
C24: 4
C25: 5
C26: 6
C27: 7
C28: 8
C29: 9
C30: 10
C31: 11
C32: 12
A33: 통합(P-to-P) 4W/EM | C33: 1 | D33: 4W E&M | I33: 4W E&M
C34: 2
C35: 3
C36: 4

Sheet 철원SS
A1: 철원S/S 광단국선번장
A4: 설치장소 | B4: 대국장소 | C4: 순번 | D4: 카드 | E4: 회선 사용 내역 | I4: 카드 | J4: 중계경로
A5: 철원 | B5: 운천 | C5: 1 | D5: ETU | E5: E1 | F5: PITR | G5: 주 | H5: 철원-운천#1 PITR | I5: ETU | J5: 철원-1(OMS)-운천
A6: OMS-PLUS#1 | C6: 2
A7: 2018.05 UPDATE | C7: 3 | E7: E1 | F7: PITR | G7: 주 | H7: 철원-운천#2 PITR | J7: 철원-3(OMS)-운천
C8: 4
C9: 5
C10: 6
C11: 7
C12: 8
C13: 9
C14: 10
C15: 11
C16: 12
C17: 13
C18: 14
C19: 15
C20: 16
A21: 철원 | B21: 운천 | C21: 1 | D21: ETU | I21: ETU
A22: OMS-PLUS#2 | C22: 2 | E22: E1 | F22: PITR | G22: 예비 | H22: 철원-운천#1 PITR | J22: 철원-2(OMS)-운천
A23: 2018.05 UPDATE | C23: 3 | E23: E1 | F23: PITR | G23: 예비 | H23: 철원-운천#2 PITR | J23: 철원-3(OMS)-운천
C24: 4
C25: 5 | D25: ETU | I25: ETU
C26: 6
C27: 7
C28: 8
C29: 9
C30: 10
C31: 11
C32: 12
C33: 13
C34: 14
C35: 15
C36: 16
A37: 철원 | B37: 화천 | C37: 1 | D37: LIU | E37: E1 | F37: PIU | G37: 예비 | H37: 철원-화천 #1T/L | I37: LIU | J37: =화천SS!J5 -> 철원-1-화천
A38: 통합(P-to-P) E1/T1 | C38: 2 | E38: E1 | F38: PIU | G38: 예비 | H38: 철원-화천 #2T/L | J38: =화천SS!J6 -> 철원-2-화천
A39: 2018.05 UPDATE | C39: 3 | E39: =화천SS!E7 | F39: =화천SS!F7 | G39: =화천SS!G7 | H39: =화천SS!H7 | J39: =화천SS!J7
C40: 4 | E40: =화천SS!E8 | F40: =화천SS!F8 | G40: =화천SS!G8 | H40: =화천SS!H8 | J40: =화천SS!J8
C41: 5 | E41: =화천SS!E9 | F41: =화천SS!F9 | G41: =화천SS!G9 | H41: =화천SS!H9 | J41: =화천SS!J9
C42: 6 | E42: =화천SS!E10 | F42: =화천SS!F10 | G42: =화천SS!G10 | H42: =화천SS!H10 | J42: =화천SS!J10
...

Sheet 양구SS
A1: 양구S/S 광단국선번장 | L1: 260311
A2: 설치장소 | B2: 대국장소 | C2: 순번 | D2: 카드 | E2: 회선 사용 내역 | I2: 카드 | J2: 중계경로 | K2: 회선ID
A3: 양구 | B3: 인제 | C3: 1 | D3: E1/T1 | I3: E1/T1 | K3: 5520000219
A4: 송변PTPU | C4: 2 | E4: E1 | F4: PITR | G4: 예비 | H4: 인제-상남#1 | J4: 인제-(PTPU:2)-양구-(통합PTP:5)-상남
A5: 2022.05 UPDATE | C5: 3
C6: 4 | E6: E1 | F6: PITR | G6: 주 | H6: 양구-인제#2 | J6: 양구-(송변PTPU:4)-인제
C7: 5 | D7: E1/T1 | E7: E1 | F7: PITR | G7: 주 | H7: 양구-인제#1 | I7: E1/T1 | J7: 양구-(송변PTPU:5)-인제
C8: 6
C9: 7
C10: 8
C11: 9 | D11: E1/T1 | E11: E1 | F11: PITR | G11: 예비 | H11: 인제-상남#2 | I11: E1/T1 | J11: 인제-(PTPU:9)-양구-(통합PTP:9)-상남
C12: 10
C13: 11
C14: 12
A15: 양구 | B15: 화천HP | C15: 1 | D15: LIU | E15: E1 | F15: PIU | G15: 예비 | H15: 양구-화천HP#1 | I15: LIU | J15: 양구-(PTP:1)-화천HP
A16: 통합(P-to-P) E1/T1 | C16: 2 | E16: E1 | F16: PIU | G16: 예비 | H16: 양구-화천HP#2 | J16: 양구-(PTP:2)-화천HP
C17: 3 | E17: E1 | F17: 디지털SCADA | G17: 예비 | H17: 인제 D-SCADA | J17: 춘천(구)-(PTP:5)-북춘천-(PTPU:2)-화천HP-(PTPU:3)-양구-(OMS:2)-인제 | K17: 미사용
C18: 4
C19: 5
C20: 6
C21: 7
C22: 8
C23: 9
C24: 10
C25: 11
C26: 12
A27: 양구 | B27: 상남 | C27: 1 | D27: LIU | E27: E1 | F27: 차세대SCADA | G27: 주 | H27: 양구 D-SCADA | I27: LIU | J27: 양구-(PTP:1)-상남-(PTP:6)-홍천-(PTP:4)-남춘천-(PTP:4)-춘천(구)
A28: 통합(P-to-P) E1/T1 | C28: 2 | E28: E1 | F28: PITR | G28: 예비 | H28: 양구-인제#2 | J28: 양구-(PTPU:2)-상남-(PTPU:6)-인제
A29: 2018.03 UPDATE | C29: 3 | E29: E1 | F29: PITR | G29: 예비 | H29: 양구-인제#1 | J29: 양구-(PTPU:3)-상남-(PTPU:7)-인제
C30: 4
C31: 5 | E31: E1 | F31: PITR | G31: 예비 | H31: 인제-상남#1 | J31: 인제-(PTPU:2)-양구-(통합PTP:5)-상남
C32: 6
C33: 7
C34: 8
C35: 9 | E35: E1 | F35: PITR | G35: 예비 | H35: 인제-상남#2 | J35: 인제-(PTPU:9)-양구-(통합PTP:9)-상남
C36: 10
C37: 11
C38: 12
C39: 1 | D39: 4W E&M | I39: 4W E&M
C40: 2
...

Sheet 인제SS
A1: 인제S/S 광단국 선번장 | K1: 260326
A4: 설치장소 | B4: 대국장소 | C4: 순번 | D4: 카드 | E4: 회선 사용 내역 | I4: 카드 | J4: 중계경로
A5: 인제 | B5: 양구 | C5: 1 | D5: E1/T1 | I5: E1/T1
A6: 송변PTPU | C6: 2 | E6: E1 | F6: PITR | G6: 예비 | H6: 인제-상남#1 | J6: 인제-(PTPU:2)-양구-(통합PTP:5)-상남 | K6: 26. 3.11 변경
A7: 2022.05 UPDATE | C7: 3
C8: 4 | E8: =양구SS!E6 -> E1 | F8: =양구SS!F6 -> PITR | G8: =양구SS!G6 -> 주 | H8: =양구SS!H6 -> 양구-인제#2 | J8: =양구SS!J6 -> 양구-(송변PTPU:4)-인제
C9: 5 | D9: E1/T1 | E9: =양구SS!E7 -> E1 | F9: =양구SS!F7 -> PITR | G9: =양구SS!G7 -> 주 | H9: =양구SS!H7 -> 양구-인제#1 | I9: E1/T1 | J9: =양구SS!J7 -> 양구-(송변PTPU:5)-인제
C10: 6
C11: 7
C12: 8
C13: 9 | D13: E1/T1 | E13: E1 | F13: PITR | G13: 예비 | H13: 인제-상남#2 | I13: E1/T1 | J13: 인제-(PTPU:9)-양구-(통합PTP:9)-상남 | K13: 26. 3.11 변경
C14: 10 | E14: =양구SS!E12 | F14: =양구SS!F12 | G14: =양구SS!G12 | H14: =양구SS!H12 | J14: =양구SS!J12
C15: 11 | E15: =양구SS!E13 | F15: =양구SS!F13 | G15: =양구SS!G13 | H15: =양구SS!H13 | J15: =양구SS!J13
C16: 12 | E16: =양구SS!E14 | F16: =양구SS!F14 | G16: =양구SS!G14 | H16: =양구SS!H14 | J16: =양구SS!J14
A17: 인제 | B17: 신양양 | C17: 1 | D17: LIU | I17: LIU
A18: 통합(P-to-P) E1/T1 | C18: 2
A19: 2018.02 UPDATE | C19: 3 | E19: E1 | F19: PIU | G19: 예비 | H19: 신양양-인제#1T/L | J19: 인제-(PTP:3)-신양양
C20: 4 | E20: E1 | F20: PIU | G20: 예비 | H20: 신양양-인제#2T/L | J20: 인제-(PTP:4)-신양양
C21: 5
C22: 6
C23: 7
C24: 8
C25: 9
C26: 10
C27: 11
C28: 12
C29: 1 | D29: 4W E&M | I29: 4W E&M
C30: 2
C31: 3
C32: 4
A33: 인제 | B33: 간성 | C33: 1 | D33: LIU | I33: LIU
A34: 통합(P-to-P) E1/T1 | C34: 2
A35: 2018.02 UPDATE | C35: 3
C36: 4
C37: 5 | E37: E1 | F37: PIU | G37: 예비 | H37: 간성-인제#1T/L | J37: 인제-5-간성
C38: 6
C39: 7
C40: 8
C41: 9 | E41: E1 | F41: PIU | G41: 예비 | H41: 간성-인제#2T/L | J41: 인제-5-간성
C42: 10
...

Sheet 춘천HP
A1: 춘천HP 광단국선번장
A2: 설치장소 | B2: 대국장소 | C2: 순번 | D2: 카드 | E2: 회선 사용 내역 | I2: 카드 | J2: 중계경로
A3: 가평 | B3: 춘천HP | C3: 1 | D3: ETU | E3: E1 | F3: PIU | G3: 예비 | H3: 가평-춘천HP T/L | I3: ETU | J3: 가평-1춘천H/P
A4: OMS-5116 | C4: 2
C5: 3
C6: 4
C7: 5 | D7: ETU | I7: ETU
C8: 6 | E8: T1 | F8: PITR | G8: 주 | H8: 가평-화천HP T/L | J8: 가평-6-춘천HP-IMUX[3]-북춘천-6-화천H/P | K8: 케이블미철거
C9: 7
C10: 8
C11: 9 | D11: ETU | E11: E1 | F11: PIU | G11: 예비 | H11: 북춘천-춘천HP | I11: ETU | J11: 북춘천-3(통합PTP)3-가평-9(OMS)9-춘천HP
C12: 10
C13: 11
C14: 12
C15: 13
C16: 14
C17: 15
C18: 16
A19: 북춘천 | B19: 춘천HP | C19: 1 | D19: LIU | E19: E1 | F19: P32-T | H19: 북춘천-춘천HP | I19: LIU | J19: 북춘천-1-춘천HP
A20: 통합(P-to-P) E1/T1 | C20: 2
C21: 3
C22: 4
C23: 5
C24: 6
C25: 7
C26: 8
C27: 9
C28: 10
C29: 11
C30: 12
A31: 통합(P-to-P) 4W/EM | C31: 1 | D31: 4W E&M | I31: 4W E&M
C32: 2
C33: 3
C34: 4
A35: 북춘천 | B35: 춘천HP | C35: 1 | D35: 2W 4W E&M | I35: 2W 4W E&M
A36: P32-T | C36: 2
C37: 3
C38: 4 | D38: SLC-T/E | I38: 2W 4W E&M
C39: 5
C40: 6
...

Sheet 화천HP
A1: 화천HP 소형광단국 선번장
K2: 260324
L3: P-32T 철거
A4: 설치장소 | B4: 대국장소 | C4: 순번 | D4: 카드 | E4: 회선 사용 내역 | I4: 카드 | J4: 중계경로 | K4: 회선ID
A6: 북춘천 | B6: 화천HP | C6: 1 | D6: LIU | E6: =북춘천SS!E21 | F6: =북춘천SS!F21 | G6: =북춘천SS!G21 | H6: =북춘천SS!H21 | I6: LIU | J6: =북춘천SS!J21
A7: 통합(P-to-P) E1/T1 | C7: 2
A8: 2018.02 UPDATE | C8: 3
C9: 4
C10: 5
C11: 6
C12: 7 | E12: =북춘천SS!E27 -> E1 | F12: PIU | G12: =북춘천SS!G27 -> 예비 | H12: =북춘천SS!H27 -> 가평-화천수력 PIU(예) | J12: =북춘천SS!J27 -> 가평-1(통합PTP)1-북춘천-7(PTP)-화천HP
C13: 8
C14: 9 | E14: =북춘천SS!E29 -> E1 | F14: =북춘천SS!F29 -> PIU | G14: =북춘천SS!G29 -> 예비 | H14: =북춘천SS!H29 -> 북춘천-화천수력 PIU(예) | J14: =북춘천SS!J29 -> 북춘천-9(통합PTP)9-화천HP
C15: 10
C16: 11
C17: 12
A18: 통합(P-to-P) 4W/EM | C18: 1 | D18: 4W E&M | I18: 4W E&M
C19: 2
C20: 3
C21: 4
A22: 화천HP | B22: 양구 | C22: 1 | D22: LIU | E22: E1 | F22: PITR | G22: 예비 | H22: 양구-화천HP#1 | I22: LIU | J22: 양구-(PTP:1)-화천HP
A23: 통합(P-to-P) E1/T1 | C23: 2 | E23: E1 | F23: PITR | G23: 예비 | H23: 양구-화천HP#2 | J23: 양구-(PTP:2)-화천HP
C24: 3 | E24: E1 | F24: 디지털SCADA | G24: 예비 | H24: 인제디지털SCADA | J24: 춘천(구)-(PTP:5)-북춘천-(PTPU:2)-화천HP-(PTPU:3)-양구-(OMS:2)-인제
C25: 4
C26: 5
C27: 6
C28: 7
C29: 8
C30: 9
C31: 10
C32: 11
C33: 12
A34: 화천 | B34: 화천HP | C34: 1 | D34: LIU | E34: E1 | F34: PITR | G34: 예비 | H34: 화천-화천HP #1T/L | I34: LIU | J34: 화천-(PTP:1)-화천HP | K34: `22.09.14 구성
A35: 통합(P-to-P) E1/T1 | C35: 2 | E35: E1 | F35: PITR | G35: 예비 | H35: 화천-화천HP #2T/L | J35: 화천-(PTP:2)-화천HP | K35: `22.09.14 구성
A36: 2018.02 UPDATE | C36: 3
C37: 4
C38: 5
C39: 6
C40: 7
C41: 8
...

Sheet 통합단말(춘천#1-DS1)
A1: 통합단말 선번장(춘천#1-DS1)
A4: 설치장소 | B4: 순번 | C4: 카드 | D4: 회선내역 | H4: 중계경로
A5: 춘천 | B5: 1 | C5: LIU(B) | D5: T1 | E5: PITR | F5: 주 | G5: 154kV 춘천-북춘천#1,2 | H5: 춘천-(1:통합단말:1)-북춘천 | J5: 신
A6: COT | B6: 2 | D6: E1 | E6: SCADA | G6: 북춘천 Digital SCADA | H6: 춘천-(2:통합단말:9)-북춘천-RTU | I6: 10.11.29 CH | J6: 구
B8: 4 | D8: E1 | E8: LAN | G8: 화천 | H8: 춘천-(4:통합단말:3)-화천
B9: 5
B10: 6 | D10: E1 | E10: LAN | G10: 춘천수력 | H10: 춘천-(6:통합단말:8)-북춘천-11-춘천HP | I10: 10.1.14, HS
B11: 7
B12: 8
B13: 9 | D13: E1 | E13: 배전전력구 | G13: 화천 배전전력구 감시시스템 | H13: 화천 ECSU-(4:통합단말:9)-춘천(구)(PTP#2 : 3 ) - 본부CSU - ~
B14: 10 | D14: E1 | E14: 배전전력구 | G14: 북춘천 배전전력구 감시시스템 | H14: 춘천-(10:통합단말:13)-북춘천
B15: 11 | D15: E1 | E15: FRU | G15: 화천 | H15: 춘천-(11:통합단말:CU)-화천
B16: 12 | D16: E1 | E16: FRU | G16: 북춘천 | H16: 춘천-(12:통합단말:CU)-북춘천
B17: 13 | D17: E1 | E17: CCTV | G17: 북춘천 집수정 카메라 | H17: 춘천-(13:통합단말:7)-북춘천
B18: 14 | D18: E1 | E18: SCADA | G18: 화천 Digital SCADA | H18: 춘천-(14:통합단말:9)-화천-RTU
B19: 15 | D19: E1 | E19: SCADA | G19: 철원 Digital SCADA | H19: 춘천-(15:통합단말9:)-철원-RTU | I19: 확인필요(추정)
B20: 16 | D20: E1 | H20: 춘천-(16:통합단말11:)-철원-RTU | I20: 확인필요
B21: 17
B22: 18
B23: 19 | D23: E1 | E23: OA LAN_2 | G23: 화천B/O(파워콤OMA#2?) | H23: 춘천-(19:통합단말:14)-화천
B24: 20 | I24: 12.1.9 SH
B25: 21 | D25: E1 | E25: FRU | G25: 철원 | H25: 춘천-(21:통합단말:CU)-철원
B26: 22 | D26: E1 | H26: 춘천-(22:통합단말:10)-철원 | I26: 확인필요
B27: 23
B28: 24
A29: 북춘천 | B29: 1 | C29: FN 3 (LIU-A) | D29: =D5 -> T1 | E29: =E5 -> PITR | F29: =F5 -> 주 | G29: =G5 -> 154kV 춘천-북춘천#1,2 | H29: =H5 -> 춘천-(1:통합단말:1)-북춘천
A30: RT : 1 | B30: 2
A31: 2018.04 UPDATE | B31: 3 | I31: 11.4.21 SH
B32: 4 | I32: 11.4.14 SH
B33: 5 | I33: 11.5.13 SH
B34: 6
B35: 7 | D35: =D17 -> E1 | E35: =E17 -> CCTV | G35: =G17 -> 북춘천 집수정 카메라 | H35: =H17 -> 춘천-(13:통합단말:7)-북춘천 | I35: 21.1.6 07:16 LOS 알람발생/ 원주급전분소 배전센터 모두 확인했으나 CCTV 화면 두 장소 모두 감시 안하고있어서 포트 닫고 향후 철거 예정
B36: 8 | D36: =D10 -> E1 | E36: =E10 -> LAN | F36: =F10 -> 0 | G36: =G10 -> 춘천수력 | H36: =H10 -> 춘천-(6:통합단말:8)-북춘천-11-춘천HP | I36: 10.5.13, SH
B37: 1(9) | C37: FN 5 (LIU-C) | D37: LAN | E37: SCADA | F37: 예비 | G37: 북춘천 Digital SCADA | H37: 춘천-(2:통합단말:9)-북춘천-RTU | I37: 10.11.29 CH
B38: 2(10) | D38: LAN
B39: 3(11) | D39: LAN
B40: 4(12) | D40: LAN
B41: 5(13) | D41: E1 | E41: 배전전력구 | G41: 배전전력구 감시시스템 | H41: 춘천-(10:통합단말:13)-북춘천
B42: 6(14)
B43: 7(15)
...

Sheet 통합단말(춘천#2-DS1)
A1: 통합단말 선번장(춘천#2-DS1)
A4: 설치장소 | B4: 순번 | C4: 카드 | D4: 회선내역 | H4: 중계경로
A5: 춘천 | B5: 1 | C5: LIU(B)
A6: COT | B6: 2
A7: 2018.04 UPDATE | B7: 3
B8: 4
B9: 5 | D9: E1 | E9: FRU | G9: 춘천열병합 | H9: 춘천-(5:통합단말:CU)-춘천열병합
B10: 6 | D10: T1 | E10: PITR | F10: 주 | G10: 154kV 남춘천-춘천 | H10: 춘천-(6:통합단말:3)-남춘천
B11: 7 | D11: E1 | E11: CMS-PLUS | G11: 남춘천-춘천 | H11: 춘천-(7:통합단말:4)-남춘천
B12: 8
B13: 9 | D13: E1 | E13: 배전전력구 | G13: 서홍천 배전전력구 | H13: =H79 -> 서홍천 ECSU-(2:통합단말:9)-춘천(구)(PTP#2 : 4) - 본부CSU - ~
B14: 10 | D14: E1 | E14: 배전전력구 | G14: 남춘천 배전전력구 감시#1 | H14: 춘천-(10:통합단말:9)-남춘천
B15: 11 | D15: E1 | E15: 배전전력구 | G15: 남춘천 배전전력구 감시#2 | H15: 춘천-(11:통합단말:10)-남춘천
B16: 12 | D16: E1 | E16: 배전전력구 | G16: 남춘천 배전전력구 감시#3 | H16: 춘천-(12:통합단말:11)-남춘천
B17: 13
B18: 14 | D18: E1 | E18: SCADA | F18: 예비 | G18: 남춘천 Digital SCADA | H18: 춘천#2링 춘천-(14:통합단말:17)-남춘천-RTU | I18: 10.11.29 SH
B19: 15 | D19: E1 | E19: SCADA | F19: 예비 | G19: 서홍천 Digital SCADA | H19: 춘천#2링 춘천-(15:통합단말:17)-서홍천-RTU | I19: 10.11.25 SH
B20: 16 | D20: E1 | E20: SCADA | F20: 예비 | G20: 춘천열병합 Digital SCADA | H20: 춘천-(16:통합단말:17)-춘천열병합
B21: 17 | D21: E1 | G21: 춘천열병합 RTU 전원리셋 | H21: 춘천-(17:통합단말:18)-춘천열병합 | I21: `22.09.27 구성
B22: 18 | D22: E1 | E22: SCADA | F22: 예비 | G22: 남춘천S/S SA용 SCADA | H22: 춘천-(FN5 18:통합단말:FN5 2)-남춘천
B23: 19
B24: 20
B25: 21
B26: 22 | D26: E1 | E26: FRU | G26: 남춘천 | H26: 춘천-(22:통합단말:CU)-남춘천
B27: 23
B28: 24 | D28: E1 | E28: FRU | G28: 서홍천 | H28: 춘천-(24:통합단말:CU)-서홍천
A29: 남춘천 | B29: 1 | C29: FN 3 (LIU-E)
A30: RT : 1 | B30: 2
A31: 2018.04 UPDATE | B31: 3 | D31: T1 | E31: PITR | F31: 주 | G31: 154kV 남춘천-춘천 | H31: 춘천-(6:통합단말:3)-남춘천
B32: 4 | D32: E1 | E32: CMS-PLUS | G32: 남춘천-춘천 | H32: 춘천-(7:통합단말:4)-남춘천
B33: 5 | D33: T1 | E33: PITR | F33: 예 | G33: 남춘천-춘천열병합 SPS PITR | H33: 남춘천-(5:통합단말:2)-춘천열병합
B34: 6
B35: 7 | D35: E1 | E35: PITR | F35: 예비 | G35: 154kV 열병합-남춘천 #1 | H35: 남춘천-(7:통합단말:1)-열병합
B36: 8 | D36: E1 | E36: PITR | F36: 예비 | G36: 154kV 열병합-남춘천 #2 | H36: 남춘천-(8:통합단말:3)-열병합
B37: 9 | D37: E1 | E37: 배전전력구 | G37: 남춘천 배전 전력구 감시#1 | H37: 남춘천-(9:통합단말:10)-춘천-(송변PTPU:6)-본부
B38: 10 | D38: E1 | E38: 배전전력구 | G38: 남춘천 배전 전력구 감시#2 | H38: 남춘천-(10:통합단말:11)-춘천-(송변PTPU:7)-본부
B39: 11 | D39: E1 | E39: 배전전력구 | G39: 남춘천 배전 전력구 감시#3 | H39: 남춘천-(11:통합단말:12)-춘천-(송변PTPU:8)-본부
B40: 12
B41: 13
B42: 14
...

Sheet 통합단말(춘천#3-DS1)_인제_양구
A1: 통합단말 선번장(춘천#3-DS1_인제,양구)
A4: 설치장소 | B4: 순번 | C4: 카드 | D4: 회선내역 | H4: 중계경로
A5: 춘천 | B5: 1 | C5: LIU(B) | D5: LAN | E5: SCADA | F5: 예비 | G5: 양구 Digital SCADA | H5: 강릉#3링 강릉-(1:통합단말:1)-양구-RTU
A6: COT | B6: 2 | D6: LAN | E6: SCADA | F6: 예비 | G6: 인제 Digital SCADA | H6: 강릉#3링 강릉-(2:통합단말:2)-인제-RTU
A7: 2018.04 UPDATE | B7: 3
B8: 4 | D8: LAN | E8: 신재생 | G8: 양구S/S 신재생감시시스템 | H8: 춘천#3링 춘천-(4:통합단말:4)-양구S/S
B9: 5
B10: 6
B11: 7
B12: 8
B13: 9
B14: 10
B15: 11
B16: 12
B17: 13
B18: 14 | I18: 10.11.29 SH
B19: 15 | I19: 10.11.25 SH
B20: 16
B21: 17
B22: 18
B23: 19
B24: 20
B25: 21
B26: 22
B27: 23
B28: 24
A29: 인제 | B29: 1 | C29: FN 3 (LIU-A)
A30: RT : 2 | B30: 2
A31: 2018.02 UPDATE | B31: 3
B32: 4
B33: 5
B34: 6
B35: 7
B36: 8
B37: 1 | C37: FN 5 (LIU-C) | D37: LAN | E37: =E6 -> SCADA | F37: =F6 -> 예비 | G37: =G6 -> 인제 Digital SCADA | H37: =H6 -> 강릉#3링 강릉-(2:통합단말:2)-인제-RTU
B38: 2 | D38: LAN
B39: 3 | D39: LAN
B40: 4 | D40: LAN
B41: 1
B42: 2
...

Sheet 통합단말(춘천COT-DS0)
A1: 통합단말 선번장(춘천COT-DS0)
A4: 설치장소 | B4: 순번 | C4: 카드 | D4: 회선내역 | H4: 중계경로 | I4: 회선ID
A5: 춘천 | B5: 1 | C5: FX0
A6: COT | B6: 2
B7: 3
B8: 4
B9: 5
B10: 6
B11: 7
B12: 8
B13: 9 | C13: FX0
B14: 10
B15: 11
B16: 12
B17: 13
B18: 14
B19: 15
B20: 16
B21: 17 | C21: 4W E&M | E21: 급전 | G21: 급전소-청평PP | H21: =서홍천SS!J33 -> 본부-19(CMUX)-춘천-17(통합단말)13-서홍천-1(P32T)-청평PP
B22: 18 | E22: 급전 | G22: 급전소-한강RCC | H22: =북춘천SS!J116 -> 본부-20(C-MUX)-춘천-18(통합단말)11-북춘천-16(P32T)-춘천HP
B23: 19
B24: 20
B25: 21
B26: 22
B27: 23
B28: 24
B29: 25 | C29: 4W E&M
B30: 26
B31: 27
B32: 28
B33: 29
B34: 30
B35: 31
B36: 32
B37: 33 | C37: 4W E&M
B38: 34
B39: 35
B40: 36
B41: 37
B42: 38
...

Sheet 통합단말(춘천#1-DS0)
A1: 통합단말 선번장(춘천#1-DS0)
A4: 설치장소 | B4: 순번 | C4: 카드 | D4: 회선내역 | H4: 중계경로
A5: 북춘천 | B5: 1 | C5: FXS
A6: RT : 1 | B6: 2
B7: 3
B8: 4
B9: 5
B10: 6
B11: 7
B12: 8
B13: 9 | C13: 4W E&M
B14: 10
B15: 11 | E15: 급전 | G15: 급전소-한강RCC | H15: ='통합단말(춘천COT-DS0)'!H22 -> 본부-20(C-MUX)-춘천-18(통합단말)11-북춘천-16(P32T)-춘천HP
B16: 12
B17: 13
B18: 14
B19: 15
B20: 16
B21: 17 | C21: RD
B22: 18
B23: 19
B24: 20
B25: 21
B26: 22
B27: 23
B28: 24
B29: 25
B30: 26
B31: 27
B32: 28
B33: 29
... B36: 32
A37: 화천 | B37: 1 | C37: FXS
A38: RT : 2 | B38: 2
B39: 3
B40: 4
B41: 5
B42: 6
B43: 7
B44: 8
...

Sheet 통합단말(춘천#2-DS0)
A1: 통합단말 선번장(춘천#2-DS0)
A4: 설치장소 | B4: 순번 | C4: 카드 | D4: 회선내역 | H4: 중계경로
A5: 남춘천 | B5: 1 | C5: FXS
A6: RT : 1 | B6: 2
B7: 3
B8: 4
B9: 5
B10: 6
B11: 7
B12: 8
B13: 9 | C13: 4W E&M
B14: 10
B15: 11
B16: 12
B17: 13
B18: 14
B19: 15
B20: 16
B21: 17 | C21: RD
B22: 18
B23: 19
B24: 20
B25: 21
B26: 22
B27: 23
B28: 24
B29: 25
B30: 26
B31: 27
B32: 28
B33: 29
... B36: 32
A37: 열병합 | B37: 1 | C37: FXS
A38: RT : 2 | B38: 2
B39: 3
B40: 4
B41: 5
B42: 6
B43: 7
B44: 8
...

Sheet 통합단말(춘천LIU-DS)
A1: 통합단말 선번장(춘천LIU-DS)
A4: 설치장소 | B4: 순번 | C4: 카드 | D4: 회선내역 | H4: 중계경로
B5: 1 | C5: LIU-DS | D5: LAN | E5: SCADA | G5: 화천 Digital SCADA | H5: 춘천#1링 춘천-(14:통합단말:FN5[1])-화천-RTU
B6: 2 | D6: LAN | E6: SCADA | G6: 북춘천 Digital SCADA | H6: 춘천#1링 춘천-(2:통합단말:FN5[1])-북춘천-RTU | I6: 10.11.29 CH
B7: 3 | D7: LAN | E7: SCADA | G7: 서홍천 Digital SCADA | H7: 춘천#2링 춘천-(14:통합단말:FN5[1])-남춘천-RTU | I7: 10.11.29 SH
B8: 4 | D8: LAN | E8: SCADA | G8: 남춘천 Digital SCADA | H8: 춘천#2링 춘천-(15:통합단말:FN5[1])-서홍천-RTU | I8: 10.11.25 SH
B9: 5 | D9: LAN | E9: SCADA | G9: 춘천-동해 LIU-DS Digital SCADA | H9: 춘천-통합P[2]-본부-[40:MSPP:22]-동해-[22:통합:1]-인제-RTU | I9: 12.6.19 SH
B10: 6 | D10: LAN | E10: SCADA | G10: 철원 FN5:1
B11: 7 | D11: LAN | E11: SCADA | G11: 철원 FN5:2
B12: 8 | D12: LAN | E12: SCADA | G12: 열병합 FN5:1
B13: 9 | D13: LAN | E13: SCADA | G13: 열병합 FN5:2
B14: 10 | D14: LAN | E14: SCADA | G14: 철원 FN5:3
B15: 11
B16: 12
B17: 13 | D17: LAN | E17: SCADA | G17: 춘천-강릉 LIU-DS Digital SCADA | H17: 춘천-12(PTP)-본부[MSPP PQM()-강릉PO[MSPP PQM()]
B18: 14
B19: 15
B20: 16 | D20: LAN | E20: SCADA | G20: 양구 Digital SCADA | H20: 춘천#3링 춘천-(1:통합단말:FN5[1])-양구-RTU
B21: 17 | D21: LAN | E21: SCADA | G21: 인제 Digital SCADA | H21: 춘천#3링 춘천-(2:통합단말:FN5[1])-인제-RTU
B22: 18 | D22: LAN | E22: SCADA | G22: 남춘천 SA용 SCADA 예비 | H22: 춘천#2링 춘천-(18:통합단말:FN5[2])-남춘천 SA 시스템 | I22: `22.09.27 구성
B23: 19
B24: 20 | D24: LAN | E24: SCADA | G24: 춘천-원주 LIU-DS Digital SCADA | H24: 춘천-10(PTP)-본부[MSPP PQM()-원주PO[MSPP PQM()]
