Workbook

Sheet 원주
A1: ■ 강원본부 OFD 선번장(원주) | L1: ※ 코아명칭 부여 PTP : COT측 장비 광출력 기준 링 : 링방향 West 광출력 기준
AS2: 45601 | AX2: 용도
A3: 본부 | B3: 관리사업소 | C3: 설치장소 | D3: 상대국명 | E3: 코어 선번 | F3: 사용여부판단 | G3: 송전선로 관리번호 | H3: 송전, 배전 선로명 | I3: 사용 여부 | J3: 융착/ 패치 | K3: 용도 | L3: 수용내역 | M3: 사용회사 | N3: 측정가능 여부 | O3: 측정거리 (km) | P3: 측정DATA 1310 (dB) | Q3: 측정DATA 1550 (dB) | R3: 측정일자 | S3: 측정거리 (km) | T3: 측정DATA 1310 (dB) | U3: 측정DATA 1550 (dB) | V3: 측정일자 | W3: 측정거리 (km) | X3: 측정DATA 1310 (dB) | Y3: 측정DATA 1550 (dB) | Z3: 측정일자 | AA3: 측정거리 (km) | AB3: 측정DATA 1310 (dB) | AC3: 측정DATA 1550 (dB) | AD3: 측정일자 | AE3: 측정거리 (km) | AF3: 측정DATA 1310 (dB) | AG3: 측정DATA 1550 (dB) | AH3: 측정일자 | AI3: 측정거리 (km) | AJ3: 측정DATA 1310 (dB) | AK3: 측정DATA 1550 (dB) | AL3: 측정일자 | AM3: 측정거리 (km) | AN3: 측정DATA 1310 (dB) | AO3: 측정DATA 1550 (dB) | AP3: 측정일자 | AQ3: 접속개소 | AR3: 상태 판단 | AS3: 비고 | AX3: 소형광단국
A4: 강원본부 | B4: 원주전력소 | C4: 원주전력소 | D4: 홍천변전소 | E4: 1 | F4: =ISTEXT(L4) -> FALSE | G4: 1000000353, 1000005969 | H4: 원주문막#2 T/L, 원주북원주#2 T/L | I4: =IF(F4=TRUE,"사용","미사용") -> 미사용 | J4: 패치 | M4: KEPCO | N4: =IF(F4=TRUE,"X","O") -> O | AM4: 44.484 | AN4: 15.878 | AO4: 10.833 | AP4: 44972 | AX4: 통합단말
A5: 강원본부 | B5: 원주전력소 | C5: 원주전력소 | D5: 홍천변전소 | E5: 2 | F5: =ISTEXT(L5) -> FALSE | G5: 1000000353, 1000005969 | H5: 원주문막#2 T/L, 원주북원주#2 T/L | I5: =IF(F5=TRUE,"사용","미사용") -> 미사용 | J5: 패치 | M5: KEPCO | N5: =IF(F5=TRUE,"X","O") -> O | AM5: 44.361 | AN5: 15.737 | AO5: 10.688 | AP5: 44972 | AX5: KepCIT
A6: 강원본부 | B6: 원주전력소 | C6: 원주전력소 | D6: 홍천변전소 | E6: 3 | F6: =ISTEXT(L6) -> FALSE | G6: 1000000353, 1000005969 | H6: 원주문막#2 T/L, 원주북원주#2 T/L | I6: =IF(F6=TRUE,"사용","미사용") -> 미사용 | J6: 패치 | M6: KEPCO | N6: =IF(F6=TRUE,"X","O") -> O | AM6: 43.654 | AN6: 14.878 | AO6: 11.116 | AP6: 44972 | AX6: 광스위치
A7: 강원본부 | B7: 원주전력소 | C7: 원주전력소 | D7: 홍천변전소 | E7: 4 | F7: =ISTEXT(L7) -> FALSE | G7: 1000000353, 1000005969 | H7: 원주문막#2 T/L, 원주북원주#2 T/L | I7: =IF(F7=TRUE,"사용","미사용") -> 미사용 | J7: 패치 | M7: KEPCO | N7: =IF(F7=TRUE,"X","O") -> O | AM7: 43.556 | AN7: 14.821 | AO7: 10.186 | AP7: 44972 | AX7: 송변전광
A8: 강원본부 | B8: 원주전력소 | C8: 원주전력소 | D8: 홍천변전소 | E8: 5 | F8: =ISTEXT(L8) -> TRUE | G8: 1000000353, 1000005969 | H8: 원주문막#2 T/L, 원주북원주#2 T/L | I8: =IF(F8=TRUE,"사용","미사용") -> 사용 | J8: 패치 | K8: 통합단말 | L8: 원주전력소 GR2링(원주-홍천) OUT | M8: KEPCO | N8: =IF(F8=TRUE,"X","O") -> X | AX8: 임대
A9: 강원본부 | B9: 원주전력소 | C9: 원주전력소 | D9: 홍천변전소 | E9: 6 | F9: =ISTEXT(L9) -> TRUE | G9: 1000000353, 1000005969 | H9: 원주문막#2 T/L, 원주북원주#2 T/L | I9: =IF(F9=TRUE,"사용","미사용") -> 사용 | J9: 패치 | K9: 통합단말 | L9: 원주전력소 GR2링(원주-홍천) IN | M9: KEPCO | N9: =IF(F9=TRUE,"X","O") -> X | AX9: PTPU
A10: 강원본부 | B10: 원주전력소 | C10: 원주전력소 | D10: 홍천변전소 | E10: 7 | F10: =ISTEXT(L10) -> FALSE | G10: 1000000353, 1000005969 | H10: 원주문막#2 T/L, 원주북원주#2 T/L | I10: =IF(F10=TRUE,"사용","미사용") -> 미사용 | M10: KEPCO | N10: =IF(F10=TRUE,"X","O") -> O | AX10: SCADA
A11: 강원본부 | B11: 원주전력소 | C11: 원주전력소 | D11: 홍천변전소 | E11: 8 | F11: =ISTEXT(L11) -> FALSE | G11: 1000000353, 1000005969 | H11: 원주문막#2 T/L, 원주북원주#2 T/L | I11: =IF(F11=TRUE,"사용","미사용") -> 미사용 | M11: KEPCO | N11: =IF(F11=TRUE,"X","O") -> O | AX11: PITR
A12: 강원본부 | B12: 원주전력소 | C12: 원주전력소 | D12: 홍천변전소 | E12: 9 | F12: =ISTEXT(L12) -> TRUE | G12: 1000000353, 1000005969 | H12: 원주문막#2 T/L, 원주북원주#2 T/L | I12: =IF(F12=TRUE,"사용","미사용") -> 사용 | J12: 패치 | K12: 광스위치 | L12: 디지탈스카다㈜(홍천-동원주) | M12: KEPCO | N12: =IF(F12=TRUE,"X","O") -> X | AX12: DAS
A13: 강원본부 | B13: 원주전력소 | C13: 원주전력소 | D13: 홍천변전소 | E13: 10 | F13: =ISTEXT(L13) -> FALSE | G13: 1000000353, 1000005969 | H13: 원주문막#2 T/L, 원주북원주#2 T/L | I13: =IF(F13=TRUE,"사용","미사용") -> 미사용 | N13: =IF(F13=TRUE,"X","O") -> O | O13: 43.285 | P13: 14.573 | Q13: 9.171 | R13: 43243 | S13: 43.44 | T13: 14.474 | U13: 9.819 | V13: 43700 | W13: 43.54 | X13: 14.511 | Y13: 10.827 | Z13: 43878 | AA13: 43.64 | AB13: 14.355 | AC13: 10.496 | AD13: 43878 | AH13: 44355 | AI13: 44.024 | AJ13: 14.764 | AK13: 10.508 | AL13: 44641 | AM13: 43.547 | AN13: 14.554 | AO13: 10.666 | AP13: 44972 | AX13: 기타
A14: 강원본부 | B14: 원주전력소 | C14: 원주전력소 | D14: 홍천변전소 | E14: 11 | F14: =ISTEXT(L14) -> FALSE | G14: 1000000353, 1000005969 | H14: 원주문막#2 T/L, 원주북원주#2 T/L | I14: =IF(F14=TRUE,"사용","미사용") -> 미사용 | M14: KEPCO | N14: =IF(F14=TRUE,"X","O") -> O | AX14: 송PTPU
A15: 강원본부 | B15: 원주전력소 | C15: 원주전력소 | D15: 홍천변전소 | E15: 12 | F15: =ISTEXT(L15) -> FALSE | G15: 1000000353, 1000005969 | H15: 원주문막#2 T/L, 원주북원주#2 T/L | I15: =IF(F15=TRUE,"사용","미사용") -> 미사용 | M15: KEPCO | N15: =IF(F15=TRUE,"X","O") -> O
A16: 강원본부 | B16: 원주전력소 | C16: 원주전력소 | D16: 홍천변전소 | E16: 13 | F16: =ISTEXT(L16) -> TRUE | G16: 1000000353, 1000005969 | H16: 원주문막#2 T/L, 원주북원주#2 T/L | I16: =IF(F16=TRUE,"사용","미사용") -> 사용 | J16: 패치 | K16: 송변전광 | L16: 홍천-원주 송변전광 W-OUT | M16: KEPCO | N16: =IF(F16=TRUE,"X","O") -> X | O16: 43.589 | P16: 15.074 | Q16: 10.42 | R16: 43243
A17: 강원본부 | B17: 원주전력소 | C17: 원주전력소 | D17: 홍천변전소 | E17: 14 | F17: =ISTEXT(L17) -> TRUE | G17: 1000000353, 1000005969 | H17: 원주문막#2 T/L, 원주북원주#2 T/L | I17: =IF(F17=TRUE,"사용","미사용") -> 사용 | J17: 패치 | K17: 송변전광 | L17: 홍천-원주 송변전광 W-IN | M17: KEPCO | N17: =IF(F17=TRUE,"X","O") -> X | O17: 43.24 | P17: 14.85 | Q17: 9.72 | R17: 43243
A18: 강원본부 | B18: 원주전력소 | C18: 원주전력소 | D18: 홍천변전소 | E18: 15 | F18: =ISTEXT(L18) -> FALSE | G18: 1000000353, 1000005969 | H18: 원주문막#2 T/L, 원주북원주#2 T/L | I18: =IF(F18=TRUE,"사용","미사용") -> 미사용 | N18: =IF(F18=TRUE,"X","O") -> O | S18: 42.62 | T18: 14.462 | U18: 10.366 | V18: 43700 | W18: 42.62 | X18: 14.657 | Y18: 10.625 | Z18: 43878 | AA18: 42.964 | AB18: 14.245 | AC18: 10.972 | AD18: 43878 | AH18: 44355 | AI18: 43.63 | AJ18: 14.78 | AK18: 10.935 | AL18: 44641 | AM18: 42.825 | AN18: 14.635 | AO18: 11.13 | AP18: 44972
A19: 강원본부 | B19: 원주전력소 | C19: 원주전력소 | D19: 홍천변전소 | E19: 16 | F19: =ISTEXT(L19) -> FALSE | G19: 1000000353, 1000005969 | H19: 원주문막#2 T/L, 원주북원주#2 T/L | I19: =IF(F19=TRUE,"사용","미사용") -> 미사용 | N19: =IF(F19=TRUE,"X","O") -> O | S19: 43.36 | T19: 14.786 | U19: 10.25 | V19: 43700 | W19: 43.75 | X19: 14.77 | Y19: 10.326 | Z19: 43878 | AA19: 43.57 | AB19: 14.649 | AC19: 11.011 | AD19: 43878 | AH19: 44355 | AI19: 42.972 | AJ19: 14.512 | AK19: 11.16 | AL19: 44641 | AM19: 42.808 | AN19: 14.809 | AO19: 11.24 | AP19: 44972
A20: 강원본부 | B20: 원주전력소 | C20: 원주전력소 | D20: 홍천변전소 | E20: 17 | F20: =ISTEXT(L20) -> TRUE | G20: 1000000353, 1000005969 | H20: 원주문막#2 T/L, 원주북원주#2 T/L | I20: =IF(F20=TRUE,"사용","미사용") -> 사용 | J20: 패치 | K20: KepCIT | L20: 차세대전력통신망 중부2링(강원지사-원주P/O) | M20: KEPCO | N20: =IF(F20=TRUE,"X","O") -> X | S20: 43.96 | T20: 16.506 | U20: 10.899 | V20: 43700 | W20: 43.56 | X20: 15.394 | Y20: 11.274 | Z20: 43878 | AA20: 76.59 | AB20: 25.788 | AC20: 19.573 | AD20: 43878 | AH20: 44355
A21: 강원본부 | B21: 원주전력소 | C21: 원주전력소 | D21: 홍천변전소 | E21: 18 | F21: =ISTEXT(L21) -> TRUE | G21: 1000000353, 1000005969 | H21: 원주문막#2 T/L, 원주북원주#2 T/L | I21: =IF(F21=TRUE,"사용","미사용") -> 사용 | J21: 패치 | K21: KepCIT | L21: 차세대전력통신망 중부2링(강원지사-원주P/O) | M21: KEPCO | N21: =IF(F21=TRUE,"X","O") -> X | S21: 43.37 | T21: 14.294 | U21: 10.196 | V21: 43700 | W21: 43.58 | X21: 14.349 | Y21: 10.121 | Z21: 43878 | AA21: 77.94 | AB21: 25.344 | AC21: 18.182 | AD21: 43878 | AH21: 44355
A22: 강원본부 | B22: 원주전력소 | C22: 원주전력소 | D22: 홍천변전소 | E22: 19 | F22: =ISTEXT(L22) -> FALSE | G22: 1000000353, 1000005969 | H22: 원주문막#2 T/L, 원주북원주#2 T/L | I22: =IF(F22=TRUE,"사용","미사용") -> 미사용 | K22: 임대 | M22: LG U+ | N22: =IF(F22=TRUE,"X","O") -> O | O22: 43.07 | P22: 13.99 | Q22: 8.94 | R22: 43243 | T22: 14.65 | U22: 10.218 | V22: 43700 | W22: 43.58 | X22: 14.388 | Y22: 10.28 | Z22: 43878 | AA22: 43.57 | AB22: 14.143 | AC22: 10.629 | AD22: 43878 | AH22: 44355 | AI22: 43.589 | AJ22: 14.509 | AK22: 10.739 | AL22: 44641 | AM22: 42.701 | AN22: 14.388 | AO22: 11.205 | AP22: 44972
A23: 강원본부 | B23: 원주전력소 | C23: 원주전력소 | D23: 홍천변전소 | E23: 20 | F23: =ISTEXT(L23) -> FALSE | G23: 1000000353, 1000005969 | H23: 원주문막#2 T/L, 원주북원주#2 T/L | I23: =IF(F23=TRUE,"사용","미사용") -> 미사용 | K23: 임대 | M23: LG U+ | N23: =IF(F23=TRUE,"X","O") -> O | O23: 43.26 | P23: 15.02 | Q23: 9.46 | R23: 43243 | T23: 13.674 | U23: 10.886 | V23: 43700 | W23: 41.218 | X23: 14.066 | Y23: 11.113 | Z23: 43878 | AA23: 43.58 | AB23: 14.664 | AC23: 11.827 | AD23: 43878 | AH23: 44355 | AI23: 43.589 | AJ23: 14.806 | AK23: 11.687 | AL23: 44641 | AM23: 43.966 | AN23: 15.149 | AO23: 11.877 | AP23: 44972
A24: 강원본부 | B24: 원주전력소 | C24: 원주전력소 | D24: 홍천변전소 | E24: 21 | F24: =ISTEXT(L24) -> TRUE | G24: 1000000353, 1000005969 | H24: 원주문막#2 T/L, 원주북원주#2 T/L | I24: =IF(F24=TRUE,"사용","미사용") -> 사용 | J24: 패치 | K24: PTPU | L24: 원주-홍천 PTPU E-OUT | M24: KEPCO | N24: =IF(F24=TRUE,"X","O") -> X
A25: 강원본부 | B25: 원주전력소 | C25: 원주전력소 | D25: 홍천변전소 | E25: 22 | F25: =ISTEXT(L25) -> TRUE | G25: 1000000353, 1000005969 | H25: 원주문막#2 T/L, 원주북원주#2 T/L | I25: =IF(F25=TRUE,"사용","미사용") -> 사용 | J25: 패치 | K25: PTPU | L25: 원주-홍천 PTPU E-IN | M25: KEPCO | N25: =IF(F25=TRUE,"X","O") -> X
A26: 강원본부 | B26: 원주전력소 | C26: 원주전력소 | D26: 홍천변전소 | E26: 23 | F26: =ISTEXT(L26) -> TRUE | G26: 1000000353, 1000005969 | H26: 원주문막#2 T/L, 원주북원주#2 T/L | I26: =IF(F26=TRUE,"사용","미사용") -> 사용 | J26: 패치 | K26: PTPU | L26: 원주-홍천 PTPU W-OUT | M26: KEPCO | N26: =IF(F26=TRUE,"X","O") -> X
A27: 강원본부 | B27: 원주전력소 | C27: 원주전력소 | D27: 홍천변전소 | E27: 24 | F27: =ISTEXT(L27) -> TRUE | G27: 1000000353, 1000005969 | H27: 원주문막#2 T/L, 원주북원주#2 T/L | I27: =IF(F27=TRUE,"사용","미사용") -> 사용 | J27: 패치 | K27: PTPU | L27: 원주-홍천 PTPU W-IN | M27: KEPCO | N27: =IF(F27=TRUE,"X","O") -> X
A28: 강원본부 | B28: 원주전력소 | C28: 원주전력소 | D28: 북원주변전소 | E28: 25 | F28: =ISTEXT(L28) -> FALSE | G28: 1000000353, 1000005969 | H28: 원주문막#2 T/L, 원주북원주#2 T/L | I28: =IF(F28=TRUE,"사용","미사용") -> 미사용 | J28: 패치 | M28: KEPCO | N28: =IF(F28=TRUE,"X","O") -> O | AM28: 12.404 | AN28: 5.103 | AO28: 6.115 | AP28: 44972
A29: 강원본부 | B29: 원주전력소 | C29: 원주전력소 | D29: 북원주변전소 | E29: 26 | F29: =ISTEXT(L29) -> FALSE | G29: 1000000353, 1000005969 | H29: 원주문막#2 T/L, 원주북원주#2 T/L | I29: =IF(F29=TRUE,"사용","미사용") -> 미사용 | J29: 패치 | M29: KEPCO | N29: =IF(F29=TRUE,"X","O") -> O | AM29: 12.398 | AN29: 5.144 | AO29: 6.055 | AP29: 44972
A30: 강원본부 | B30: 원주전력소 | C30: 원주전력소 | D30: 북원주변전소 | E30: 27 | F30: =ISTEXT(L30) -> FALSE | G30: 1000000353, 1000005969 | H30: 원주문막#2 T/L, 원주북원주#2 T/L | I30: =IF(F30=TRUE,"사용","미사용") -> 미사용 | J30: 패치 | M30: KEPCO | N30: =IF(F30=TRUE,"X","O") -> O | AM30: 12.398 | AN30: 4.946 | AO30: 4.945 | AP30: 44972
A31: 강원본부 | B31: 원주전력소 | C31: 원주전력소 | D31: 북원주변전소 | E31: 28 | F31: =ISTEXT(L31) -> FALSE | G31: 1000000353, 1000005969 | H31: 원주문막#2 T/L, 원주북원주#2 T/L | I31: =IF(F31=TRUE,"사용","미사용") -> 미사용 | J31: 패치 | M31: KEPCO | N31: =IF(F31=TRUE,"X","O") -> O | AM31: 12.398 | AN31: 4.933 | AO31: 4.699 | AP31: 44972
A32: 강원본부 | B32: 원주전력소 | C32: 원주전력소 | D32: 북원주변전소 | E32: 29 | F32: =ISTEXT(L32) -> TRUE | G32: 1000000353, 1000005969 | H32: 원주문막#2 T/L, 원주북원주#2 T/L | I32: =IF(F32=TRUE,"사용","미사용") -> 사용 | J32: 패치 | K32: 통합단말 | L32: 원주전력소 GR2링(북원주-원주) OUT | M32: KEPCO | N32: =IF(F32=TRUE,"X","O") -> X
A33: 강원본부 | B33: 원주전력소 | C33: 원주전력소 | D33: 북원주변전소 | E33: 30 | F33: =ISTEXT(L33) -> TRUE | G33: 1000000353, 1000005969 | H33: 원주문막#2 T/L, 원주북원주#2 T/L | I33: =IF(F33=TRUE,"사용","미사용") -> 사용 | J33: 패치 | K33: 통합단말 | L33: 원주전력소 GR2링(북원주-원주) IN | M33: KEPCO | N33: =IF(F33=TRUE,"X","O") -> X
A34: 강원본부 | B34: 원주전력소 | C34: 원주전력소 | D34: 북원주변전소 | E34: 31 | F34: =ISTEXT(L34) -> TRUE | G34: 1000000353, 1000005969 | H34: 원주문막#2 T/L, 원주북원주#2 T/L | I34: =IF(F34=TRUE,"사용","미사용") -> 사용 | J34: 패치 | K34: 광스위치 | L34: 디지탈스카다㈜(원주-북원주) | M34: KEPCO | N34: =IF(F34=TRUE,"X","O") -> X
A35: 강원본부 | B35: 원주전력소 | C35: 원주전력소 | D35: 북원주변전소 | E35: 32 | F35: =ISTEXT(L35) -> FALSE | G35: 1000000353, 1000005969 | H35: 원주문막#2 T/L, 원주북원주#2 T/L | I35: =IF(F35=TRUE,"사용","미사용") -> 미사용 | N35: =IF(F35=TRUE,"X","O") -> O | O35: 12.15 | P35: 4.37 | Q35: 3.07 | R35: 43243 | S35: 12.197 | T35: 4.287 | U35: 3.974 | V35: 43700 | W35: 12.402 | X35: 4.47 | Y35: 4.684 | Z35: 43878 | AA35: 12.402 | AB35: 4.535 | AC35: 5.896 | AD35: 43878 | AE35: 12.4 | AF35: 4.535 | AG35: 5.896 | AH35: 44377 | AI35: 12.404 | AJ35: 4.484 | AK35: 4.772 | AL35: 44641 | AM35: 12.398 | AN35: 4.641 | AO35: 4.925 | AP35: 44972
A36: 강원본부 | B36: 원주전력소 | C36: 원주전력소 | D36: 북원주변전소 | E36: 33 | F36: =ISTEXT(L36) -> TRUE | G36: 1000000353, 1000005969 | H36: 원주문막#2 T/L, 원주북원주#2 T/L | I36: =IF(F36=TRUE,"사용","미사용") -> 사용 | J36: 패치 | K36: 송변전광 | L36: 원주-북원주 송변전광 W-OUT | M36: KEPCO | N36: =IF(F36=TRUE,"X","O") -> X | O36: 12.15 | P36: 4.69 | Q36: 3.36 | R36: 43243 | AS36: 2018.11
A37: 강원본부 | B37: 원주전력소 | C37: 원주전력소 | D37: 북원주변전소 | E37: 34 | F37: =ISTEXT(L37) -> TRUE | G37: 1000000353, 1000005969 | H37: 원주문막#2 T/L, 원주북원주#2 T/L | I37: =IF(F37=TRUE,"사용","미사용") -> 사용 | J37: 패치 | K37: 송변전광 | L37: 원주-북원주 송변전광 W-IN | M37: KEPCO | N37: =IF(F37=TRUE,"X","O") -> X | O37: 12.15 | P37: 4.35 | Q37: 3.23 | R37: 43243 | AS37: 2018.11
A38: 강원본부 | B38: 원주전력소 | C38: 원주전력소 | D38: 북원주변전소 | E38: 35 | F38: =ISTEXT(L38) -> TRUE | G38: 1000000353, 1000005969 | H38: 원주문막#2 T/L, 원주북원주#2 T/L | I38: =IF(F38=TRUE,"사용","미사용") -> 사용 | J38: 패치 | K38: 송PTPU | L38: 원주-북원주 송PTPU EAST | M38: KEPCO | N38: =IF(F38=TRUE,"X","O") -> X | O38: 12.15 | P38: 4.1 | Q38: 2.94 | R38: 43243 | S38: 60 | T38: 22.327 | U38: 15 | V38: 43700 | W38: 12.391 | X38: 4.527 | Y38: 4.15 | Z38: 43878 | AA38: 12.4 | AB38: 4.451 | AC38: 5.257 | AD38: 43878 | AE38: 12.4 | AF38: 4.451 | AG38: 5.257 | AH38: 44377 | AI38: 12.396 | AJ38: 4.437 | AK38: 4.514 | AL38: 44641
A39: 강원본부 | B39: 원주전력소 | C39: 원주전력소 | D39: 북원주변전소 | E39: 36 | F39: =ISTEXT(L39) -> TRUE | G39: 1000000353, 1000005969 | H39: 원주문막#2 T/L, 원주북원주#2 T/L | I39: =IF(F39=TRUE,"사용","미사용") -> 사용 | J39: 패치 | K39: 송PTPU | L39: 원주-북원주 송PTPU WEST | M39: KEPCO | N39: =IF(F39=TRUE,"X","O") -> X | O39: 12.15 | P39: 4.38 | Q39: 3.03 | R39: 43243 | S39: 57.94 | T39: 20.344 | U39: 13.65 | V39: 43700 | W39: 12.404 | X39: 4.491 | Y39: 3.517 | Z39: 43878 | AA39: 12.404 | AB39: 4.496 | AC39: 4.905 | AD39: 43878 | AE39: 12.406 | AF39: 4.496 | AG39: 4.905 | AH39: 44377 | AI39: 12.402 | AJ39: 4.474 | AK39: 3.997 | AL39: 44641
A40: 강원본부 | B40: 원주전력소 | C40: 원주전력소 | D40: 북원주변전소 | E40: 37 | F40: =ISTEXT(L40) -> FALSE | G40: 1000000353, 1000005969 | H40: 원주문막#2 T/L, 원주북원주#2 T/L | I40: =IF(F40=TRUE,"사용","미사용") -> 미사용 | N40: =IF(F40=TRUE,"X","O") -> O | O40: 12.15 | P40: 6.591 | Q40: 4.15 | R40: 43243 | S40: 14.49 | T40: 5.969 | U40: 3.88 | V40: 43700 | W40: 12.394 | X40: 4.748 | Y40: 3.296 | Z40: 43878 | AA40: 12.4 | AB40: 4.684 | AC40: 3.335 | AD40: 43878 | AE40: 12.4 | AF40: 4.684 | AG40: 3.335 | AH40: 44377 | AI40: 12.394 | AJ40: 4.689 | AK40: 3.535 | AL40: 44641 | AM40: 12.396 | AN40: 4.907 | AO40: 3.724 | AP40: 44972
...

Sheet 원주SA
A1: ■ 강원본부 OFD 선번장(원주SA) | L1: ※ 코아명칭 부여 PTP : COT측 장비 광출력 기준 링 : 링방향 West 광출력 기준
AS2: =원주!AS2 -> 45601 | AX2: 용도
A3: 본부 | B3: 관리사업소 | C3: 설치장소 | D3: 상대국명 | E3: 코어 선번 | F3: 사용여부판단 | G3: 송전선로 관리번호 | H3: 송전, 배전 선로명 | I3: 사용 여부 | J3: 융착/ 패치 | K3: 용도 | L3: 수용내역 | M3: 사용회사 | N3: 측정가능 여부 | O3: 측정거리 (km) | P3: 측정DATA 1310 (dB) | Q3: 측정DATA 1550 (dB) | R3: 측정일자 | S3: 측정거리 (km) | T3: 측정DATA 1310 (dB) | U3: 측정DATA 1550 (dB) | V3: 측정일자 | W3: 측정거리 (km) | X3: 측정DATA 1310 (dB) | Y3: 측정DATA 1550 (dB) | Z3: 측정일자 | AA3: 측정거리 (km) | AB3: 측정DATA 1310 (dB) | AC3: 측정DATA 1550 (dB) | AD3: 측정일자 | AE3: 측정거리 (km) | AF3: 측정DATA 1310 (dB) | AG3: 측정DATA 1550 (dB) | AH3: 측정일자 | AI3: 측정거리 (km) | AJ3: 측정DATA 1310 (dB) | AK3: 측정DATA 1550 (dB) | AL3: 측정일자 | AM3: 측정거리 (km) | AN3: 측정DATA 1310 (dB) | AO3: 측정DATA 1550 (dB) | AP3: 측정일자 | AQ3: 접속개소 | AR3: 상태 판단 | AS3: 비고 | AX3: 소형광단국
A4: 강원본부 | B4: 원주전력소 | C4: 원주SA | D4: 원주ICT | E4: 1 | F4: =ISTEXT(L4) -> TRUE | G4: ICT실-SA연계 | H4: 비금속자가망 | I4: =IF(F4=TRUE,"사용","미사용") -> 사용 | J4: 패치 | K4: 송변전광 | L4: 확장장치 L1 TX | M4: KEPCO | N4: =IF(F4=TRUE,"X","O") -> X | AX4: 통합단말
A5: 강원본부 | B5: 원주전력소 | C5: 원주SA | D5: 원주ICT | E5: 2 | F5: =ISTEXT(L5) -> TRUE | G5: ICT실-SA연계 | H5: 비금속자가망 | I5: =IF(F5=TRUE,"사용","미사용") -> 사용 | J5: 패치 | K5: 송변전광 | L5: 확장장치 L1 RX | M5: KEPCO | N5: =IF(F5=TRUE,"X","O") -> X | AX5: KepCIT
A6: 강원본부 | B6: 원주전력소 | C6: 원주SA | D6: 원주ICT | E6: 3 | F6: =ISTEXT(L6) -> TRUE | G6: ICT실-SA연계 | H6: 비금속자가망 | I6: =IF(F6=TRUE,"사용","미사용") -> 사용 | J6: 패치 | K6: 송변전광 | L6: 확장장치 L2 TX | M6: KEPCO | N6: =IF(F6=TRUE,"X","O") -> X | AX6: 광스위치
A7: 강원본부 | B7: 원주전력소 | C7: 원주SA | D7: 원주ICT | E7: 4 | F7: =ISTEXT(L7) -> TRUE | G7: ICT실-SA연계 | H7: 비금속자가망 | I7: =IF(F7=TRUE,"사용","미사용") -> 사용 | J7: 패치 | K7: 송변전광 | L7: 확장장치 L2 RX | M7: KEPCO | N7: =IF(F7=TRUE,"X","O") -> X | AX7: 송변전광
A8: 강원본부 | B8: 원주전력소 | C8: 원주SA | D8: 원주ICT | E8: 5 | F8: =ISTEXT(L8) -> TRUE | G8: ICT실-SA연계 | H8: 비금속자가망 | I8: =IF(F8=TRUE,"사용","미사용") -> 사용 | J8: 패치 | K8: PTPU | L8: 원주-원주SA1 EAST OUT | M8: KEPCO | N8: =IF(F8=TRUE,"X","O") -> X | AX8: 임대
A9: 강원본부 | B9: 원주전력소 | C9: 원주SA | D9: 원주ICT | E9: 6 | F9: =ISTEXT(L9) -> TRUE | G9: ICT실-SA연계 | H9: 비금속자가망 | I9: =IF(F9=TRUE,"사용","미사용") -> 사용 | J9: 패치 | K9: PTPU | L9: 원주-원주SA1 EAST IN | M9: KEPCO | N9: =IF(F9=TRUE,"X","O") -> X | AX9: PTPU
A10: 강원본부 | B10: 원주전력소 | C10: 원주SA | D10: 원주ICT | E10: 7 | F10: =ISTEXT(L10) -> TRUE | G10: ICT실-SA연계 | H10: 비금속자가망 | I10: =IF(F10=TRUE,"사용","미사용") -> 사용 | J10: 패치 | K10: PTPU | L10: 원주-원주SA1 WEST OUT | M10: KEPCO | N10: =IF(F10=TRUE,"X","O") -> X | AX10: SCADA
A11: 강원본부 | B11: 원주전력소 | C11: 원주SA | D11: 원주ICT | E11: 8 | F11: =ISTEXT(L11) -> TRUE | G11: ICT실-SA연계 | H11: 비금속자가망 | I11: =IF(F11=TRUE,"사용","미사용") -> 사용 | J11: 패치 | K11: PTPU | L11: 원주-원주SA1 WEST IN | M11: KEPCO | N11: =IF(F11=TRUE,"X","O") -> X | AX11: PITR
A12: 강원본부 | B12: 원주전력소 | C12: 원주SA | D12: 원주ICT | E12: 9 | F12: =ISTEXT(L12) -> TRUE | G12: ICT실-SA연계 | H12: 비금속자가망 | I12: =IF(F12=TRUE,"사용","미사용") -> 사용 | J12: 패치 | K12: PTPU | L12: 원주-원주SA2 EAST OUT | M12: KEPCO | N12: =IF(F12=TRUE,"X","O") -> X | AX12: DAS
A13: 강원본부 | B13: 원주전력소 | C13: 원주SA | D13: 원주ICT | E13: 10 | F13: =ISTEXT(L13) -> TRUE | G13: ICT실-SA연계 | H13: 비금속자가망 | I13: =IF(F13=TRUE,"사용","미사용") -> 사용 | J13: 패치 | K13: PTPU | L13: 원주-원주SA2 EAST IN | M13: KEPCO | N13: =IF(F13=TRUE,"X","O") -> X | AX13: 기타
A14: 강원본부 | B14: 원주전력소 | C14: 원주SA | D14: 원주ICT | E14: 11 | F14: =ISTEXT(L14) -> TRUE | G14: ICT실-SA연계 | H14: 비금속자가망 | I14: =IF(F14=TRUE,"사용","미사용") -> 사용 | J14: 패치 | K14: PTPU | L14: 원주-원주SA2 WEST OUT | M14: KEPCO | N14: =IF(F14=TRUE,"X","O") -> X | AX14: 송PTPU
A15: 강원본부 | B15: 원주전력소 | C15: 원주SA | D15: 원주ICT | E15: 12 | F15: =ISTEXT(L15) -> TRUE | G15: ICT실-SA연계 | H15: 비금속자가망 | I15: =IF(F15=TRUE,"사용","미사용") -> 사용 | J15: 패치 | K15: PTPU | L15: 원주-원주SA2 WEST IN | M15: KEPCO | N15: =IF(F15=TRUE,"X","O") -> X
A16: 강원본부 | B16: 원주전력소 | C16: 원주SA | D16: 원주ICT | E16: 13 | F16: =ISTEXT(L16) -> TRUE | G16: ICT실-SA연계 | H16: 비금속자가망 | I16: =IF(F16=TRUE,"사용","미사용") -> 사용 | J16: 패치 | K16: SCADA | L16: SA 주회선 | M16: KEPCO | N16: =IF(F16=TRUE,"X","O") -> X
A17: 강원본부 | B17: 원주전력소 | C17: 원주SA | D17: 원주ICT | E17: 14 | F17: =ISTEXT(L17) -> TRUE | G17: ICT실-SA연계 | H17: 비금속자가망 | I17: =IF(F17=TRUE,"사용","미사용") -> 사용 | J17: 패치 | K17: SCADA | L17: SA 예비회선 | M17: KEPCO | N17: =IF(F17=TRUE,"X","O") -> X
A18: 강원본부 | B18: 원주전력소 | C18: 원주SA | D18: 원주ICT | E18: 15 | F18: =ISTEXT(L18) -> TRUE | G18: ICT실-SA연계 | H18: 비금속자가망 | I18: =IF(F18=TRUE,"사용","미사용") -> 사용 | J18: 패치 | K18: 기타 | L18: SA OA PC | M18: KEPCO | N18: =IF(F18=TRUE,"X","O") -> X
A19: 강원본부 | B19: 원주전력소 | C19: 원주SA | D19: 원주ICT | E19: 16 | F19: =ISTEXT(L19) -> TRUE | G19: ICT실-SA연계 | H19: 비금속자가망 | I19: =IF(F19=TRUE,"사용","미사용") -> 사용 | J19: 패치 | K19: 기타 | L19: SA IPT | M19: KEPCO | N19: =IF(F19=TRUE,"X","O") -> X
A20: 강원본부 | B20: 원주전력소 | C20: 원주SA | D20: 원주ICT | E20: 17 | F20: =ISTEXT(L20) -> TRUE | G20: ICT실-SA연계 | H20: 비금속자가망 | I20: =IF(F20=TRUE,"사용","미사용") -> 사용 | J20: 패치 | K20: 기타 | L20: SA #5 | M20: KEPCO | N20: =IF(F20=TRUE,"X","O") -> X
A21: 강원본부 | B21: 원주전력소 | C21: 원주SA | D21: 원주ICT | E21: 18 | F21: =ISTEXT(L21) -> TRUE | G21: ICT실-SA연계 | H21: 비금속자가망 | I21: =IF(F21=TRUE,"사용","미사용") -> 사용 | J21: 패치 | K21: 기타 | L21: SA 송변전광 NMS | M21: KEPCO | N21: =IF(F21=TRUE,"X","O") -> X
A22: 강원본부 | B22: 원주전력소 | C22: 원주SA | D22: 원주ICT | E22: 19 | F22: =ISTEXT(L22) -> TRUE | G22: ICT실-SA연계 | H22: 비금속자가망 | I22: =IF(F22=TRUE,"사용","미사용") -> 사용 | J22: 패치 | K22: 기타 | L22: SA 감시정보 | M22: KEPCO | N22: =IF(F22=TRUE,"X","O") -> X
A23: 강원본부 | B23: 원주전력소 | C23: 원주SA | D23: 원주ICT | E23: 20 | F23: =ISTEXT(L23) -> TRUE | G23: ICT실-SA연계 | H23: 비금속자가망 | I23: =IF(F23=TRUE,"사용","미사용") -> 사용 | J23: 패치 | K23: 기타 | L23: SA #8 | M23: KEPCO | N23: =IF(F23=TRUE,"X","O") -> X
A24: 강원본부 | B24: 원주전력소 | C24: 원주SA | D24: 원주ICT | E24: 21 | F24: =ISTEXT(L24) -> FALSE | G24: ICT실-SA연계 | H24: 비금속자가망 | I24: =IF(F24=TRUE,"사용","미사용") -> 미사용 | J24: 패치 | M24: KEPCO | N24: =IF(F24=TRUE,"X","O") -> O | W24: 0.201 | Y24: 0.52 | Z24: 43901 | AM24: 0.21 | AN24: 0.255 | AO24: 0.018 | AP24: 44973 | AS24: 2020.07.06
A25: 강원본부 | B25: 원주전력소 | C25: 원주SA | D25: 원주ICT | E25: 22 | F25: =ISTEXT(L25) -> FALSE | G25: ICT실-SA연계 | H25: 비금속자가망 | I25: =IF(F25=TRUE,"사용","미사용") -> 미사용 | J25: 패치 | M25: KEPCO | N25: =IF(F25=TRUE,"X","O") -> O | W25: 0.201 | X25: 0.173 | Y25: 0.14 | Z25: 43901 | AM25: 0.21 | AN25: 0.209 | AO25: 0.221 | AP25: 44973 | AS25: 2020.07.06
A26: 강원본부 | B26: 원주전력소 | C26: 원주SA | D26: 원주ICT | E26: 23 | F26: =ISTEXT(L26) -> FALSE | G26: ICT실-SA연계 | H26: 비금속자가망 | I26: =IF(F26=TRUE,"사용","미사용") -> 미사용 | J26: 패치 | M26: KEPCO | N26: =IF(F26=TRUE,"X","O") -> O | W26: 0.203 | X26: 0.261 | Y26: 0.058 | Z26: 43901 | AM26: 0.21 | AN26: 0.216 | AO26: 0.068 | AP26: 44973 | AS26: 2020.07.06
A27: 강원본부 | B27: 원주전력소 | C27: 원주SA | D27: 원주ICT | E27: 24 | F27: =ISTEXT(L27) -> FALSE | G27: ICT실-SA연계 | H27: 비금속자가망 | I27: =IF(F27=TRUE,"사용","미사용") -> 미사용 | J27: 패치 | M27: KEPCO | N27: =IF(F27=TRUE,"X","O") -> O | W27: 0.199 | X27: 0.151 | Y27: 0.161 | Z27: 43901 | AM27: 0.21 | AN27: 0.181 | AO27: 0.204 | AP27: 44973 | AS27: 2020.07.06
A28: 강원본부 | B28: 원주전력소 | C28: 원주SA | D28: 원주ICT | E28: 25 | F28: =ISTEXT(L28) -> TRUE | G28: ICT실-SA연계 | H28: 비금속자가망 | I28: =IF(F28=TRUE,"사용","미사용") -> 사용 | J28: 패치 | K28: 기타 | L28: 배전전력구 비상통신망 | M28: KEPCO | N28: =IF(F28=TRUE,"X","O") -> X | W28: 0.203 | X28: 0.136 | Y28: 0.027 | Z28: 43901 | AA28: 0.199 | AB28: 0.194 | AC28: 0.368 | AE28: 0.199 | AF28: 0.194 | AG28: 0.368 | AH28: 44377
A29: 강원본부 | B29: 원주전력소 | C29: 원주SA | D29: 원주ICT | E29: 26 | F29: =ISTEXT(L29) -> TRUE | G29: ICT실-SA연계 | H29: 비금속자가망 | I29: =IF(F29=TRUE,"사용","미사용") -> 사용 | J29: 패치 | K29: 기타 | L29: 송전전력구 비상통신망 | M29: KEPCO | N29: =IF(F29=TRUE,"X","O") -> X | W29: 0.202 | X29: 0.089 | Y29: 0.121 | Z29: 43901 | AA29: 0.199 | AB29: 0.151 | AC29: 0.208 | AE29: 0.199 | AF29: 0.151 | AG29: 0.208 | AH29: 44377
A30: 강원본부 | B30: 원주전력소 | C30: 원주SA | D30: 원주ICT | E30: 27 | F30: =ISTEXT(L30) -> FALSE | G30: ICT실-SA연계 | H30: 비금속자가망 | I30: =IF(F30=TRUE,"사용","미사용") -> 미사용 | N30: =IF(F30=TRUE,"X","O") -> O | W30: 0.192 | X30: 0.149 | Y30: 0.019 | Z30: 43901 | AA30: 0.199 | AB30: 0.16 | AC30: 0.088 | AE30: 0.18 | AF30: 0.16 | AG30: 0.16 | AH30: 44377 | AI30: 0.195 | AJ30: 0.217 | AK30: 0.003 | AL30: 44641 | AM30: 0.2 | AN30: 0.206 | AO30: -0.034 | AP30: 44973
A31: 강원본부 | B31: 원주전력소 | C31: 원주SA | D31: 원주ICT | E31: 28 | F31: =ISTEXT(L31) -> FALSE | G31: ICT실-SA연계 | H31: 비금속자가망 | I31: =IF(F31=TRUE,"사용","미사용") -> 미사용 | N31: =IF(F31=TRUE,"X","O") -> O | W31: 0.204 | X31: 0.559 | Y31: 0.129 | Z31: 43901 | AA31: 0.199 | AB31: 0.532 | AC31: 0.083 | AE31: 0.183 | AF31: 0.532 | AG31: 0.083 | AH31: 44377 | AI31: 0.201 | AJ31: 0.493 | AK31: 0.308 | AL31: 44642 | AM31: 0.199 | AN31: 0.172 | AO31: 0.15 | AP31: 44973
A32: 강원본부 | B32: 원주전력소 | C32: 원주SA | D32: 원주ICT | E32: 29 | F32: =ISTEXT(L32) -> FALSE | G32: ICT실-SA연계 | H32: 비금속자가망 | I32: =IF(F32=TRUE,"사용","미사용") -> 미사용 | N32: =IF(F32=TRUE,"X","O") -> O | W32: 0.199 | X32: 0.2 | Y32: 0.095 | Z32: 43901 | AA32: 0.199 | AB32: 0.579 | AC32: 0.528 | AE32: 0.206 | AF32: 0.579 | AG32: 0.528 | AH32: 44377 | AI32: 0.2 | AJ32: 0.163 | AK32: 0.051 | AL32: 44643 | AM32: 0.2 | AN32: 0.082 | AO32: -0.047 | AP32: 44973
A33: 강원본부 | B33: 원주전력소 | C33: 원주SA | D33: 원주ICT | E33: 30 | F33: =ISTEXT(L33) -> FALSE | G33: ICT실-SA연계 | H33: 비금속자가망 | I33: =IF(F33=TRUE,"사용","미사용") -> 미사용 | N33: =IF(F33=TRUE,"X","O") -> O | W33: 0.204 | X33: 0.458 | Y33: 0.151 | Z33: 43901 | AA33: 0.199 | AB33: 0.297 | AC33: 0.24 | AE33: 0.179 | AF33: 0.297 | AG33: 0.24 | AH33: 44377 | AI33: 0.193 | AJ33: 0.055 | AK33: 0.356 | AL33: 44644 | AM33: 0.2 | AN33: 0.093 | AO33: 0.175 | AP33: 44973
A34: 강원본부 | B34: 원주전력소 | C34: 원주SA | D34: 원주ICT | E34: 31 | F34: =ISTEXT(L34) -> FALSE | G34: ICT실-SA연계 | H34: 비금속자가망 | I34: =IF(F34=TRUE,"사용","미사용") -> 미사용 | N34: =IF(F34=TRUE,"X","O") -> O | W34: 0.204 | X34: 0.501 | Y34: 0.154 | Z34: 43901 | AA34: 0.199 | AB34: 0.278 | AC34: 0.178 | AE34: 0.179 | AF34: 0.278 | AG34: 0.178 | AH34: 44377 | AI34: 0.198 | AJ34: 0.183 | AK34: 0.151 | AL34: 44645 | AM34: 0.2 | AN34: 0.134 | AO34: 0.003 | AP34: 44973
A35: 강원본부 | B35: 원주전력소 | C35: 원주SA | D35: 원주ICT | E35: 32 | F35: =ISTEXT(L35) -> FALSE | G35: ICT실-SA연계 | H35: 비금속자가망 | I35: =IF(F35=TRUE,"사용","미사용") -> 미사용 | N35: =IF(F35=TRUE,"X","O") -> O | W35: 0.201 | X35: 0.227 | Y35: 0.13 | Z35: 43901 | AA35: 0.199 | AB35: 0.277 | AC35: 0.261 | AE35: 0.2 | AF35: 0 | AG35: 0.261 | AH35: 44377 | AI35: 0.197 | AJ35: 0.288 | AK35: 0.319 | AL35: 44646 | AM35: 0.2 | AN35: 0.168 | AO35: 0.029 | AP35: 44973
A36: 강원본부 | B36: 원주전력소 | C36: 원주SA | D36: 원주ICT | E36: 33 | F36: =ISTEXT(L36) -> FALSE | G36: ICT실-SA연계 | H36: 비금속자가망 | I36: =IF(F36=TRUE,"사용","미사용") -> 미사용 | N36: =IF(F36=TRUE,"X","O") -> O | W36: 0.201 | X36: 0.022 | Y36: 0.3 | Z36: 43901 | AA36: 0.199 | AB36: 0.166 | AC36: 0.73 | AE36: 0.2 | AF36: 0.166 | AG36: 0.73 | AH36: 44377 | AI36: 0.196 | AJ36: 0.632 | AK36: 1.068 | AL36: 44647 | AM36: 0.2 | AN36: 0.092 | AO36: 0.131 | AP36: 44973
A37: 강원본부 | B37: 원주전력소 | C37: 원주SA | D37: 원주ICT | E37: 34 | F37: =ISTEXT(L37) -> FALSE | G37: ICT실-SA연계 | H37: 비금속자가망 | I37: =IF(F37=TRUE,"사용","미사용") -> 미사용 | N37: =IF(F37=TRUE,"X","O") -> O | W37: 0.201 | X37: 0.041 | Y37: 0.026 | Z37: 43901 | AA37: 0.199 | AB37: 0.227 | AC37: 0.153 | AE37: 0.199 | AF37: 0.227 | AG37: 0.153 | AH37: 44377 | AI37: 0.198 | AJ37: 0.3 | AK37: 0.143 | AL37: 44648 | AM37: 0.2 | AN37: 0.13 | AO37: -0.148 | AP37: 44973
A38: 강원본부 | B38: 원주전력소 | C38: 원주SA | D38: 원주ICT | E38: 35 | F38: =ISTEXT(L38) -> FALSE | G38: ICT실-SA연계 | H38: 비금속자가망 | I38: =IF(F38=TRUE,"사용","미사용") -> 미사용 | N38: =IF(F38=TRUE,"X","O") -> O | W38: 0.196 | X38: 0.021 | Y38: 0.122 | Z38: 43901 | AA38: 0.199 | AB38: 0.256 | AC38: 0.394 | AE38: 0.181 | AF38: 0.26 | AG38: 0.394 | AH38: 44377 | AI38: 0.203 | AJ38: 0.454 | AK38: 0.338 | AL38: 44649 | AM38: 0.2 | AN38: 0 | AO38: 0.138 | AP38: 44973
A39: 강원본부 | B39: 원주전력소 | C39: 원주SA | D39: 원주ICT | E39: 36 | F39: =ISTEXT(L39) -> FALSE | G39: ICT실-SA연계 | H39: 비금속자가망 | I39: =IF(F39=TRUE,"사용","미사용") -> 미사용 | N39: =IF(F39=TRUE,"X","O") -> O | W39: 0.2 | X39: 0.15 | Y39: 0.211 | Z39: 43901 | AA39: 0.199 | AB39: 0.055 | AC39: 0.183 | AE39: 0.2 | AF39: 0.055 | AG39: 0.183 | AH39: 44377 | AI39: 0.198 | AJ39: 0.228 | AK39: 0.03 | AL39: 44650 | AM39: 0.2 | AN39: 0.15 | AO39: 0.373 | AP39: 44973
A40: 강원본부 | B40: 원주전력소 | C40: 원주SA | D40: 원주ICT | E40: 37 | F40: =ISTEXT(L40) -> FALSE | G40: ICT실-SA연계 | H40: 비금속자가망 | I40: =IF(F40=TRUE,"사용","미사용") -> 미사용 | N40: =IF(F40=TRUE,"X","O") -> O | W40: 0.202 | X40: 0.195 | Y40: 0.172 | Z40: 43901 | AA40: 0.199 | AB40: 0.494 | AC40: 0.099 | AE40: 0.205 | AF40: 0.494 | AG40: 0.099 | AH40: 44377 | AI40: 0.196 | AJ40: 0.233 | AK40: 0.233 | AL40: 44651 | AM40: 0.201 | AN40: 0.096 | AO40: 0.107 | AP40: 44973
...

Sheet 서원주
A1: ■ 강원본부 OFD 선번장(서원주) | L1: ※ 코아명칭 부여 PTP : COT측 장비 광출력 기준 링 : 링방향 West 광출력 기준
AO2: =원주!AS2 -> 45601 | AT2: 용도
A3: 본부 | B3: 관리사업소 | C3: 설치장소 | D3: 상대국명 | E3: 코어 선번 | F3: 사용여부판단 | G3: 송전선로 관리번호 | H3: 송전, 배전 선로명 | I3: 사용 여부 | J3: 융착/ 패치 | K3: 용도 | L3: 수용내역 | M3: 사용회사 | N3: 측정가능 여부 | O3: 측정거리 (km) | P3: 측정DATA 1310 (dB) | Q3: 측정DATA 1550 (dB) | R3: 측정일자 | S3: 측정거리 (km) | T3: 측정DATA 1310 (dB) | U3: 측정DATA 1550 (dB) | V3: 측정일자 | W3: 측정거리 (km) | X3: 측정DATA 1310 (dB) | Y3: 측정DATA 1550 (dB) | Z3: 측정일자 | AA3: 측정거리 (km) | AB3: 측정DATA 1310 (dB) | AC3: 측정DATA 1550 (dB) | AD3: 측정일자 | AE3: 측정거리 (km) | AF3: 측정DATA 1310 (dB) | AG3: 측정DATA 1550 (dB) | AH3: 측정일자 | AI3: 측정거리 (km) | AJ3: 측정DATA 1310 (dB) | AK3: 측정DATA 1550 (dB) | AL3: 측정일자 | AM3: 접속개소 | AN3: 상태 판단 | AO3: 비고 | AT3: 소형광단국
A4: 강원본부 | B4: 원주전력소 | C4: 서원주변전소 | D4: 원주전력소 | E4: 1 | F4: =ISTEXT(L4) -> FALSE | G4: 1000000353, 1000005969 | H4: 원주문막#2 T/L, 원주북원주#2 T/L | I4: =IF(F4=TRUE,"사용","미사용") -> 미사용 | M4: KEPCO | N4: =IF(F4=TRUE,"X","O") -> O | AI4: 5.253 | AJ4: 1.737 | AK4: 1.055 | AL4: 44979 | AT4: 통합단말
A5: 강원본부 | B5: 원주전력소 | C5: 서원주변전소 | D5: 원주전력소 | E5: 2 | F5: =ISTEXT(L5) -> FALSE | G5: 1000000353, 1000005969 | H5: 원주문막#2 T/L, 원주북원주#2 T/L | I5: =IF(F5=TRUE,"사용","미사용") -> 미사용 | M5: KEPCO | N5: =IF(F5=TRUE,"X","O") -> O | AI5: 5.245 | AJ5: 2.022 | AK5: 1.121 | AL5: 44979 | AT5: KepCIT
A6: 강원본부 | B6: 원주전력소 | C6: 서원주변전소 | D6: 원주전력소 | E6: 3 | F6: =ISTEXT(L6) -> FALSE | G6: 1000000353, 1000005969 | H6: 원주문막#2 T/L, 원주북원주#2 T/L | I6: =IF(F6=TRUE,"사용","미사용") -> 미사용 | M6: KEPCO | N6: =IF(F6=TRUE,"X","O") -> O | AI6: 5.246 | AJ6: 1.735 | AK6: 1.707 | AL6: 44979 | AT6: 광스위치
A7: 강원본부 | B7: 원주전력소 | C7: 서원주변전소 | D7: 원주전력소 | E7: 4 | F7: =ISTEXT(L7) -> FALSE | G7: 1000000353, 1000005969 | H7: 원주문막#2 T/L, 원주북원주#2 T/L | I7: =IF(F7=TRUE,"사용","미사용") -> 미사용 | M7: KEPCO | N7: =IF(F7=TRUE,"X","O") -> O | AI7: 5.246 | AJ7: 1.754 | AK7: 1.087 | AL7: 44979 | AT7: 송변전광
A8: 강원본부 | B8: 원주전력소 | C8: 서원주변전소 | D8: 원주전력소 | E8: 5 | F8: =ISTEXT(L8) -> TRUE | G8: 1000000353, 1000005969 | H8: 원주문막#2 T/L, 원주북원주#2 T/L | I8: =IF(F8=TRUE,"사용","미사용") -> 사용 | J8: 패치 | K8: 통합단말 | L8: 원주전력소 GR3링(남원주-문막) OUT | M8: KEPCO | N8: =IF(F8=TRUE,"X","O") -> X | AT8: 임대
A9: 강원본부 | B9: 원주전력소 | C9: 서원주변전소 | D9: 원주전력소 | E9: 6 | F9: =ISTEXT(L9) -> TRUE | G9: 1000000353, 1000005969 | H9: 원주문막#2 T/L, 원주북원주#2 T/L | I9: =IF(F9=TRUE,"사용","미사용") -> 사용 | J9: 패치 | K9: 통합단말 | L9: 원주전력소 GR3링(남원주-문막) IN | M9: KEPCO | N9: =IF(F9=TRUE,"X","O") -> X | AT9: PTPU
A10: 강원본부 | B10: 원주전력소 | C10: 서원주변전소 | D10: 원주전력소 | E10: 7 | F10: =ISTEXT(L10) -> TRUE | G10: 1000000353, 1000005969 | H10: 원주문막#2 T/L, 원주북원주#2 T/L | I10: =IF(F10=TRUE,"사용","미사용") -> 사용 | J10: 패치 | K10: 광스위치 | L10: 디지탈스카다㈜(남원주-문막) | M10: KEPCO | N10: =IF(F10=TRUE,"X","O") -> X | AT10: SCADA
A11: 강원본부 | B11: 원주전력소 | C11: 서원주변전소 | D11: 원주전력소 | E11: 8 | F11: =ISTEXT(L11) -> TRUE | G11: 1000000353, 1000005969 | H11: 원주문막#2 T/L, 원주북원주#2 T/L | I11: =IF(F11=TRUE,"사용","미사용") -> 사용 | J11: 패치 | K11: 광스위치 | L11: 디지탈스카다㈜(서원주-원주) | M11: KEPCO | N11: =IF(F11=TRUE,"X","O") -> X | AT11: PITR
A12: 강원본부 | B12: 원주전력소 | C12: 서원주변전소 | D12: 원주전력소 | E12: 9 | F12: =ISTEXT(L12) -> FALSE | G12: 1000000353, 1000005969 | H12: 원주문막#2 T/L, 원주북원주#2 T/L | I12: =IF(F12=TRUE,"사용","미사용") -> 미사용 | M12: KEPCO | N12: =IF(F12=TRUE,"X","O") -> O | AI12: 5.246 | AJ12: 1.789 | AK12: 1.289 | AL12: 44979 | AT12: DAS
A13: 강원본부 | B13: 원주전력소 | C13: 서원주변전소 | D13: 원주전력소 | E13: 10 | F13: =ISTEXT(L13) -> FALSE | G13: 1000000353, 1000005969 | H13: 원주문막#2 T/L, 원주북원주#2 T/L | I13: =IF(F13=TRUE,"사용","미사용") -> 미사용 | M13: KEPCO | N13: =IF(F13=TRUE,"X","O") -> O | AI13: 5.246 | AJ13: 1.663 | AK13: 1.48 | AL13: 44979 | AT13: 기타
A14: 강원본부 | B14: 원주전력소 | C14: 서원주변전소 | D14: 원주전력소 | E14: 11 | F14: =ISTEXT(L14) -> FALSE | G14: 1000000353, 1000005969 | H14: 원주문막#2 T/L, 원주북원주#2 T/L | I14: =IF(F14=TRUE,"사용","미사용") -> 미사용 | M14: KEPCO | N14: =IF(F14=TRUE,"X","O") -> O | AI14: 5.245 | AJ14: 1.895 | AK14: 1.25 | AL14: 44979 | AT14: 송PTPU
A15: 강원본부 | B15: 원주전력소 | C15: 서원주변전소 | D15: 원주전력소 | E15: 12 | F15: =ISTEXT(L15) -> FALSE | G15: 1000000353, 1000005969 | H15: 원주문막#2 T/L, 원주북원주#2 T/L | I15: =IF(F15=TRUE,"사용","미사용") -> 미사용 | M15: KEPCO | N15: =IF(F15=TRUE,"X","O") -> O | AI15: 5.248 | AJ15: 1.912 | AK15: 1.25 | AL15: 44979
A16: 강원본부 | B16: 원주전력소 | C16: 서원주변전소 | D16: 원주전력소 | E16: 13 | F16: =ISTEXT(L16) -> TRUE | G16: 1000000353, 1000005969 | H16: 원주문막#2 T/L, 원주북원주#2 T/L | I16: =IF(F16=TRUE,"사용","미사용") -> 사용 | J16: 패치 | K16: 통합단말 | L16: 원주전력소 GR3링(서원주-원주) OUT | M16: KEPCO | N16: =IF(F16=TRUE,"X","O") -> X
A17: 강원본부 | B17: 원주전력소 | C17: 서원주변전소 | D17: 원주전력소 | E17: 14 | F17: =ISTEXT(L17) -> FALSE | G17: 1000000353, 1000005969 | H17: 원주문막#2 T/L, 원주북원주#2 T/L | I17: =IF(F17=TRUE,"사용","미사용") -> 미사용 | N17: =IF(F17=TRUE,"X","O") -> O | O17: 5.037 | P17: 1.809 | Q17: 1.298 | R17: 43248 | S17: 5.038 | T17: 1.746 | U17: 1.039 | V17: 43703 | W17: 5.246 | X17: 1.671 | Y17: 1.033 | Z17: 43882 | AA17: 5.25 | AB17: 1.652 | AC17: 1.272 | AD17: 44438 | AE17: 5.246 | AF17: 1.717 | AG17: 1.218 | AH17: 44652 | AI17: 5.246 | AJ17: 1.746 | AK17: 1.217 | AL17: 44979
A18: 강원본부 | B18: 원주전력소 | C18: 서원주변전소 | D18: 원주전력소 | E18: 15 | F18: =ISTEXT(L18) -> TRUE | G18: 1000000353, 1000005969 | H18: 원주문막#2 T/L, 원주북원주#2 T/L | I18: =IF(F18=TRUE,"사용","미사용") -> 사용 | J18: 패치 | K18: PTPU | L18: 원주-서원주 PTPU EAST | M18: KEPCO | N18: =IF(F18=TRUE,"X","O") -> X | AO18: 23.01.10작업
A19: 강원본부 | B19: 원주전력소 | C19: 서원주변전소 | D19: 원주전력소 | E19: 16 | F19: =ISTEXT(L19) -> TRUE | G19: 1000000353, 1000005969 | H19: 원주문막#2 T/L, 원주북원주#2 T/L | I19: =IF(F19=TRUE,"사용","미사용") -> 사용 | J19: 패치 | K19: PTPU | L19: 원주-서원주 PTPU WEST | M19: KEPCO | N19: =IF(F19=TRUE,"X","O") -> X | AO19: 23.01.10작업
A20: 강원본부 | B20: 원주전력소 | C20: 서원주변전소 | D20: 원주전력소 | E20: 17 | F20: =ISTEXT(L20) -> FALSE | G20: 1000000353, 1000005969 | H20: 원주문막#2 T/L, 원주북원주#2 T/L | I20: =IF(F20=TRUE,"사용","미사용") -> 미사용 | J20: 패치 | M20: KEPCO | N20: =IF(F20=TRUE,"X","O") -> O | AI20: 5.249 | AJ20: 1.808 | AK20: 1.045 | AL20: 44979
A21: 강원본부 | B21: 원주전력소 | C21: 서원주변전소 | D21: 원주전력소 | E21: 18 | F21: =ISTEXT(L21) -> FALSE | G21: 1000000353, 1000005969 | H21: 원주문막#2 T/L, 원주북원주#2 T/L | I21: =IF(F21=TRUE,"사용","미사용") -> 미사용 | J21: 패치 | M21: KEPCO | N21: =IF(F21=TRUE,"X","O") -> O | AI21: 5.247 | AJ21: 1.775 | AK21: 1.38 | AL21: 44979
A22: 강원본부 | B22: 원주전력소 | C22: 서원주변전소 | D22: 원주전력소 | E22: 19 | F22: =ISTEXT(L22) -> TRUE | G22: 1000000353, 1000005969 | H22: 원주문막#2 T/L, 원주북원주#2 T/L | I22: =IF(F22=TRUE,"사용","미사용") -> 사용 | J22: 패치 | K22: 통합단말 | L22: 원주전력소 GR3링(서원주-원주) IN | M22: KEPCO | N22: =IF(F22=TRUE,"X","O") -> X
A23: 강원본부 | B23: 원주전력소 | C23: 서원주변전소 | D23: 원주전력소 | E23: 20 | F23: =ISTEXT(L23) -> FALSE | G23: 1000000353, 1000005969 | H23: 원주문막#2 T/L, 원주북원주#2 T/L | I23: =IF(F23=TRUE,"사용","미사용") -> 미사용 | N23: =IF(F23=TRUE,"X","O") -> O | O23: 5.038 | P23: 1.838 | Q23: 1.113 | R23: 43248 | S23: 5.083 | T23: 1.786 | U23: 1.124 | V23: 43703 | W23: 5.245 | X23: 1.706 | Y23: 1.056 | Z23: 43882 | AA23: 5.247 | AB23: 1.723 | AC23: 1.163 | AD23: 44438 | AE23: 5.246 | AF23: 1.76 | AG23: 1.088 | AH23: 44652 | AI23: 5.248 | AJ23: 1.862 | AK23: 1.55 | AL23: 44979
A24: 강원본부 | B24: 원주전력소 | C24: 서원주변전소 | D24: 원주전력소 | E24: 21 | F24: =ISTEXT(L24) -> TRUE | G24: 1000000353, 1000005969 | H24: 원주문막#2 T/L, 원주북원주#2 T/L | I24: =IF(F24=TRUE,"사용","미사용") -> 사용 | J24: 패치 | K24: 송변전광 | L24: 문막-원주 송변전광 W-OUT | M24: KEPCO | N24: =IF(F24=TRUE,"X","O") -> X | O24: 5.038 | P24: 1.714 | Q24: 1.093 | R24: 43248 | S24: 5.084 | T24: 1.677 | U24: 1.161 | V24: 43703
A25: 강원본부 | B25: 원주전력소 | C25: 서원주변전소 | D25: 원주전력소 | E25: 22 | F25: =ISTEXT(L25) -> TRUE | G25: 1000000353, 1000005969 | H25: 원주문막#2 T/L, 원주북원주#2 T/L | I25: =IF(F25=TRUE,"사용","미사용") -> 사용 | J25: 패치 | K25: 송변전광 | L25: 문막-원주 송변전광 W-IN | M25: KEPCO | N25: =IF(F25=TRUE,"X","O") -> X | O25: 5.045 | P25: 1.664 | Q25: 1.033 | R25: 43248 | S25: 5.083 | T25: 1.817 | U25: 1.035 | V25: 43703
A26: 강원본부 | B26: 원주전력소 | C26: 서원주변전소 | D26: 원주전력소 | E26: 23 | F26: =ISTEXT(L26) -> TRUE | G26: 1000000353, 1000005969 | H26: 원주문막#2 T/L, 원주북원주#2 T/L | I26: =IF(F26=TRUE,"사용","미사용") -> 사용 | J26: 패치 | K26: 송변전광 | L26: 남원주-서원주 송변전광 W-OUT | M26: KEPCO | N26: =IF(F26=TRUE,"X","O") -> X | S26: 5.084 | T26: 2.029 | U26: 1.277 | V26: 43703
A27: 강원본부 | B27: 원주전력소 | C27: 서원주변전소 | D27: 원주전력소 | E27: 24 | F27: =ISTEXT(L27) -> TRUE | G27: 1000000353, 1000005969 | H27: 원주문막#2 T/L, 원주북원주#2 T/L | I27: =IF(F27=TRUE,"사용","미사용") -> 사용 | J27: 패치 | K27: 송변전광 | L27: 남원주-서원주 송변전광 W-IN | M27: KEPCO | N27: =IF(F27=TRUE,"X","O") -> X | O27: 5.037 | P27: 1.87 | Q27: 1.283 | R27: 43248 | S27: 5.083 | T27: 1.871 | U27: 1.234 | V27: 43703
A28: 강원본부 | B28: 원주전력소 | C28: 서원주변전소 | D28: 문막변전소 | E28: 25 | F28: =ISTEXT(L28) -> FALSE | G28: 1000000353, 1000005969 | H28: 원주문막#2 T/L, 원주북원주#2 T/L | I28: =IF(F28=TRUE,"사용","미사용") -> 미사용 | M28: KEPCO | N28: =IF(F28=TRUE,"X","O") -> O | AI28: 18.759 | AJ28: 6.045 | AK28: 3.811 | AL28: 44979
A29: 강원본부 | B29: 원주전력소 | C29: 서원주변전소 | D29: 문막변전소 | E29: 26 | F29: =ISTEXT(L29) -> FALSE | G29: 1000000353, 1000005969 | H29: 원주문막#2 T/L, 원주북원주#2 T/L | I29: =IF(F29=TRUE,"사용","미사용") -> 미사용 | M29: KEPCO | N29: =IF(F29=TRUE,"X","O") -> O | AI29: 18.759 | AJ29: 6.462 | AK29: 4.132 | AL29: 44979
A30: 강원본부 | B30: 원주전력소 | C30: 서원주변전소 | D30: 문막변전소 | E30: 27 | F30: =ISTEXT(L30) -> FALSE | G30: 1000000353, 1000005969 | H30: 원주문막#2 T/L, 원주북원주#2 T/L | I30: =IF(F30=TRUE,"사용","미사용") -> 미사용 | M30: KEPCO | N30: =IF(F30=TRUE,"X","O") -> O | AI30: 18.759 | AJ30: 6.535 | AK30: 4.269 | AL30: 44979
A31: 강원본부 | B31: 원주전력소 | C31: 서원주변전소 | D31: 문막변전소 | E31: 28 | F31: =ISTEXT(L31) -> FALSE | G31: 1000000353, 1000005969 | H31: 원주문막#2 T/L, 원주북원주#2 T/L | I31: =IF(F31=TRUE,"사용","미사용") -> 미사용 | M31: KEPCO | N31: =IF(F31=TRUE,"X","O") -> O | AI31: 18.755 | AJ31: 6.141 | AK31: 4.151 | AL31: 44979
A32: 강원본부 | B32: 원주전력소 | C32: 서원주변전소 | D32: 문막변전소 | E32: 29 | F32: =ISTEXT(L32) -> TRUE | G32: 1000000353, 1000005969 | H32: 원주문막#2 T/L, 원주북원주#2 T/L | I32: =IF(F32=TRUE,"사용","미사용") -> 사용 | J32: 패치 | K32: 통합단말 | L32: 원주전력소 GR3링(남원주-문막) OUT | M32: KEPCO | N32: =IF(F32=TRUE,"X","O") -> X
A33: 강원본부 | B33: 원주전력소 | C33: 서원주변전소 | D33: 문막변전소 | E33: 30 | F33: =ISTEXT(L33) -> TRUE | G33: 1000000353, 1000005969 | H33: 원주문막#2 T/L, 원주북원주#2 T/L | I33: =IF(F33=TRUE,"사용","미사용") -> 사용 | J33: 패치 | K33: 통합단말 | L33: 원주전력소 GR3링(남원주-문막) IN | M33: KEPCO | N33: =IF(F33=TRUE,"X","O") -> X
A34: 강원본부 | B34: 원주전력소 | C34: 서원주변전소 | D34: 문막변전소 | E34: 31 | F34: =ISTEXT(L34) -> TRUE | G34: 1000000353, 1000005969 | H34: 원주문막#2 T/L, 원주북원주#2 T/L | I34: =IF(F34=TRUE,"사용","미사용") -> 사용 | J34: 패치 | K34: 광스위치 | L34: 디지탈스카다㈜(남원주-문막) | M34: KEPCO | N34: =IF(F34=TRUE,"X","O") -> X
A35: 강원본부 | B35: 원주전력소 | C35: 서원주변전소 | D35: 문막변전소 | E35: 32 | F35: =ISTEXT(L35) -> TRUE | G35: 1000000353, 1000005969 | H35: 원주문막#2 T/L, 원주북원주#2 T/L | I35: =IF(F35=TRUE,"사용","미사용") -> 사용 | J35: 패치 | K35: 광스위치 | L35: 디지탈스카다㈜(문막-서원주) | M35: KEPCO | N35: =IF(F35=TRUE,"X","O") -> X
A36: 강원본부 | B36: 원주전력소 | C36: 서원주변전소 | D36: 문막변전소 | E36: 33 | F36: =ISTEXT(L36) -> TRUE | G36: 1000000353, 1000005969 | H36: 원주문막#2 T/L, 원주북원주#2 T/L | I36: =IF(F36=TRUE,"사용","미사용") -> 사용 | J36: 패치 | K36: 송변전광 | L36: 문막-원주 송변전광 W-OUT | M36: KEPCO | N36: =IF(F36=TRUE,"X","O") -> X | O36: 18.75 | P36: 6.278 | Q36: 3.676 | R36: 43248 | S36: 18.771 | T36: 6.247 | U36: 4.074 | V36: 43703
A37: 강원본부 | B37: 원주전력소 | C37: 서원주변전소 | D37: 문막변전소 | E37: 34 | F37: =ISTEXT(L37) -> TRUE | G37: 1000000353, 1000005969 | H37: 원주문막#2 T/L, 원주북원주#2 T/L | I37: =IF(F37=TRUE,"사용","미사용") -> 사용 | J37: 패치 | K37: 송변전광 | L37: 문막-원주 송변전광 W-IN | M37: KEPCO | N37: =IF(F37=TRUE,"X","O") -> X | S37: 18.763 | T37: 6.537 | U37: 4.614 | V37: 43703
A38: 강원본부 | B38: 원주전력소 | C38: 서원주변전소 | D38: 문막변전소 | E38: 35 | F38: =ISTEXT(L38) -> TRUE | G38: 1000000353, 1000005969 | H38: 원주문막#2 T/L, 원주북원주#2 T/L | I38: =IF(F38=TRUE,"사용","미사용") -> 사용 | J38: 패치 | K38: 송변전광 | L38: 서원주-문막 송변전광 W-IN | M38: KEPCO | N38: =IF(F38=TRUE,"X","O") -> X | O38: 18.759 | P38: 6.587 | Q38: 4.014 | R38: 43248 | S38: 18.771 | T38: 6.624 | U38: 4.462 | V38: 43703
A39: 강원본부 | B39: 원주전력소 | C39: 서원주변전소 | D39: 문막변전소 | E39: 36 | F39: =ISTEXT(L39) -> TRUE | G39: 1000000353, 1000005969 | H39: 원주문막#2 T/L, 원주북원주#2 T/L | I39: =IF(F39=TRUE,"사용","미사용") -> 사용 | J39: 패치 | K39: 송변전광 | L39: 서원주-문막 송변전광 W-OUT | M39: KEPCO | N39: =IF(F39=TRUE,"X","O") -> X | O39: 18.75 | P39: 6.377 | Q39: 4.212 | R39: 43248 | S39: 18.767 | T39: 6.449 | U39: 4.82 | V39: 43703
A40: 강원본부 | B40: 원주전력소 | C40: 서원주변전소 | D40: 문막변전소 | E40: 37 | F40: =ISTEXT(L40) -> TRUE | G40: 1000000353, 1000005969 | H40: 원주문막#2 T/L, 원주북원주#2 T/L | I40: =IF(F40=TRUE,"사용","미사용") -> 사용 | J40: 패치 | K40: 통합단말 | L40: 원주전력소 GR3링(문막-서원주) OUT | M40: KEPCO | N40: =IF(F40=TRUE,"X","O") -> X
...

Sheet 북원주
A1: ■ 강원본부 OFD 선번장(북원주) | L1: ※ 코아명칭 부여 PTP : COT측 장비 광출력 기준 링 : 링방향 West 광출력 기준
AO2: =원주!AS2 -> 45601 | AU2: 용도
A3: 본부 | B3: 관리사업소 | C3: 설치장소 | D3: 상대국명 | E3: 코어 선번 | F3: 사용여부판단 | G3: 송전선로 관리번호 | H3: 송전, 배전 선로명 | I3: 사용 여부 | J3: 융착/ 패치 | K3: 용도 | L3: 수용내역 | M3: 사용회사 | N3: 측정가능 여부 | O3: 측정거리 (km) | P3: 측정DATA 1310 (dB) | Q3: 측정DATA 1550 (dB) | R3: 측정일자 | S3: 측정거리 (km) | T3: 측정DATA 1310 (dB) | U3: 측정DATA 1550 (dB) | V3: 측정일자 | W3: 측정거리 (km) | X3: 측정DATA 1310 (dB) | Y3: 측정DATA 1550 (dB) | Z3: 측정일자 | AA3: 측정거리 (km) | AB3: 측정DATA 1310 (dB) | AC3: 측정DATA 1550 (dB) | AD3: 측정일자 | AE3: 측정거리 (km) | AF3: 측정DATA 1310 (dB) | AG3: 측정DATA 1550 (dB) | AH3: 측정일자 | AI3: 측정거리 (km) | AJ3: 측정DATA 1310 (dB) | AK3: 측정DATA 1550 (dB) | AL3: 측정일자 | AM3: 접속개소 | AN3: 상태 판단 | AO3: 비고 | AU3: 소형광단국
A4: 강원본부 | B4: 원주전력소 | C4: 북원주변전소 | D4: 원주전력소 | E4: 1 | F4: =ISTEXT(L4) -> FALSE | G4: 1000005969 | H4: 원주북원주#2 T/L | I4: =IF(F4=TRUE,"사용","미사용") -> 미사용 | J4: 패치 | M4: KEPCO | N4: =IF(F4=TRUE,"X","O") -> O | Z4: 43887 | AI4: 12.396 | AJ4: 4.802 | AK4: 5.381 | AL4: 44980 | AU4: 통합단말
A5: 강원본부 | B5: 원주전력소 | C5: 북원주변전소 | D5: 원주전력소 | E5: 2 | F5: =ISTEXT(L5) -> FALSE | G5: 1000005969 | H5: 원주북원주#2 T/L | I5: =IF(F5=TRUE,"사용","미사용") -> 미사용 | J5: 패치 | M5: KEPCO | N5: =IF(F5=TRUE,"X","O") -> O | AI5: 12.4 | AJ5: 4.939 | AK5: 5.512 | AL5: 44980 | AU5: KepCIT
A6: 강원본부 | B6: 원주전력소 | C6: 북원주변전소 | D6: 원주전력소 | E6: 3 | F6: =ISTEXT(L6) -> FALSE | G6: 1000005969 | H6: 원주북원주#2 T/L | I6: =IF(F6=TRUE,"사용","미사용") -> 미사용 | J6: 패치 | M6: KEPCO | N6: =IF(F6=TRUE,"X","O") -> O | AI6: 12.398 | AJ6: 4.546 | AK6: 4.546 | AL6: 44980 | AU6: 광스위치
A7: 강원본부 | B7: 원주전력소 | C7: 북원주변전소 | D7: 원주전력소 | E7: 4 | F7: =ISTEXT(L7) -> FALSE | G7: 1000005969 | H7: 원주북원주#2 T/L | I7: =IF(F7=TRUE,"사용","미사용") -> 미사용 | J7: 패치 | M7: KEPCO | N7: =IF(F7=TRUE,"X","O") -> O | AI7: 12.398 | AJ7: 4.864 | AK7: 4.701 | AL7: 44980 | AU7: 송변전광
A8: 강원본부 | B8: 원주전력소 | C8: 북원주변전소 | D8: 원주전력소 | E8: 5 | F8: =ISTEXT(L8) -> TRUE | G8: 1000005969 | H8: 원주북원주#2 T/L | I8: =IF(F8=TRUE,"사용","미사용") -> 사용 | J8: 패치 | K8: 통합단말 | L8: 원주전력소 GR2링(북원주-원주) OUT | M8: KEPCO | N8: =IF(F8=TRUE,"X","O") -> X | AU8: 임대
A9: 강원본부 | B9: 원주전력소 | C9: 북원주변전소 | D9: 원주전력소 | E9: 6 | F9: =ISTEXT(L9) -> TRUE | G9: 1000005969 | H9: 원주북원주#2 T/L | I9: =IF(F9=TRUE,"사용","미사용") -> 사용 | J9: 패치 | K9: 통합단말 | L9: 원주전력소 GR2링(북원주-원주) IN | M9: KEPCO | N9: =IF(F9=TRUE,"X","O") -> X | AU9: PTPU
A10: 강원본부 | B10: 원주전력소 | C10: 북원주변전소 | D10: 원주전력소 | E10: 7 | F10: =ISTEXT(L10) -> TRUE | G10: 1000005969 | H10: 원주북원주#2 T/L | I10: =IF(F10=TRUE,"사용","미사용") -> 사용 | J10: 패치 | K10: 광스위치 | L10: 디지탈스카다㈜(원주-북원주) | M10: KEPCO | N10: =IF(F10=TRUE,"X","O") -> X | AU10: SCADA
A11: 강원본부 | B11: 원주전력소 | C11: 북원주변전소 | D11: 원주전력소 | E11: 8 | F11: =ISTEXT(L11) -> FALSE | G11: 1000005969 | H11: 원주북원주#2 T/L | I11: =IF(F11=TRUE,"사용","미사용") -> 미사용 | N11: =IF(F11=TRUE,"X","O") -> O | O11: 12.151 | P11: 4.37 | Q11: 3.18 | R11: 43248 | S11: 12.197 | T11: 4.414 | U11: 4.225 | V11: 43703 | W11: 12.398 | X11: 4.513 | Y11: 4.635 | Z11: 43887 | AA11: 12.404 | AB11: 4.498 | AC11: 5.85 | AD11: 44361 | AE11: 12.396 | AF11: 4.414 | AG11: 4.803 | AH11: 44650 | AI11: 12.398 | AJ11: 4.76 | AK11: 3.651 | AL11: 44980 | AU11: PITR
A12: 강원본부 | B12: 원주전력소 | C12: 북원주변전소 | D12: 원주전력소 | E12: 9 | F12: =ISTEXT(L12) -> TRUE | G12: 1000005969 | H12: 원주북원주#2 T/L | I12: =IF(F12=TRUE,"사용","미사용") -> 사용 | J12: 패치 | K12: 송변전광 | L12: 원주-북원주 송변전광 W-OUT | M12: KEPCO | N12: =IF(F12=TRUE,"X","O") -> X | O12: 12.15 | P12: 4.469 | Q12: 3.19 | R12: 43248 | AU12: DAS
A13: 강원본부 | B13: 원주전력소 | C13: 북원주변전소 | D13: 원주전력소 | E13: 10 | F13: =ISTEXT(L13) -> TRUE | G13: 1000005969 | H13: 원주북원주#2 T/L | I13: =IF(F13=TRUE,"사용","미사용") -> 사용 | J13: 패치 | K13: 송변전광 | L13: 원주-북원주 송변전광 W-IN | M13: KEPCO | N13: =IF(F13=TRUE,"X","O") -> X | O13: 12.15 | P13: 4.174 | Q13: 3.078 | R13: 43248 | AU13: 기타
A14: 강원본부 | B14: 원주전력소 | C14: 북원주변전소 | D14: 원주전력소 | E14: 11 | F14: =ISTEXT(L14) -> TRUE | G14: 1000005969 | H14: 원주북원주#2 T/L | I14: =IF(F14=TRUE,"사용","미사용") -> 사용 | J14: 패치 | K14: 송PTPU | L14: 원주-북원주 송PTPU EAST | M14: KEPCO | N14: =IF(F14=TRUE,"X","O") -> X | O14: 12.15 | P14: 4.317 | Q14: 3.085 | R14: 43248 | S14: 12.197 | T14: 4.353 | U14: 3.727 | V14: 43703 | W14: 12.398 | X14: 4.267 | Y14: 3.787 | Z14: 43887 | AC14: 5.168 | AD14: 44361 | AE14: 12.396 | AF14: 4.29 | AG14: 4.131 | AH14: 44650 | AU14: 송PTPU
A15: 강원본부 | B15: 원주전력소 | C15: 북원주변전소 | D15: 원주전력소 | E15: 12 | F15: =ISTEXT(L15) -> TRUE | G15: 1000005969 | H15: 원주북원주#2 T/L | I15: =IF(F15=TRUE,"사용","미사용") -> 사용 | J15: 패치 | K15: 송PTPU | L15: 원주-북원주 송PTPU WEST | M15: KEPCO | N15: =IF(F15=TRUE,"X","O") -> X | O15: 12.15 | P15: 4.32 | Q15: 2.893 | R15: 43248 | S15: 12.207 | T15: 4.235 | U15: 2.96 | V15: 43703 | W15: 12.406 | X15: 4.326 | Y15: 3.134 | Z15: 43887 | AA15: 12.39 | AC15: 4.503 | AD15: 44361 | AE15: 12.398 | AF15: 4.293 | AG15: 3.542 | AH15: 44650
A16: 강원본부 | B16: 원주전력소 | C16: 북원주변전소 | D16: 원주전력소 | E16: 13 | F16: =ISTEXT(L16) -> FALSE | G16: 1000005969 | H16: 원주북원주#2 T/L | I16: =IF(F16=TRUE,"사용","미사용") -> 미사용 | N16: =IF(F16=TRUE,"X","O") -> O | S16: 12.19 | T16: 4.676 | U16: 2.989 | V16: 43703 | W16: 12.394 | X16: 4.591 | Y16: 2.945 | Z16: 43887 | AA16: 12.4 | AB16: 4.735 | AC16: 3.38 | AD16: 44361 | AE16: 12.396 | AF16: 4.647 | AG16: 3.391 | AH16: 44650 | AI16: 12.402 | AJ16: 4.704 | AK16: 3.816 | AL16: 44980
A17: 강원본부 | B17: 원주전력소 | C17: 북원주변전소 | D17: 원주전력소 | E17: 14 | F17: =ISTEXT(L17) -> FALSE | G17: 1000005969 | H17: 원주북원주#2 T/L | I17: =IF(F17=TRUE,"사용","미사용") -> 미사용 | N17: =IF(F17=TRUE,"X","O") -> O | S17: 12.19 | T17: 4.546 | U17: 3.037 | V17: 43703 | W17: 12.396 | X17: 4.504 | Y17: 2.94 | Z17: 43887 | AB17: 4.515 | AC17: 3.1 | AD17: 44361 | AE17: 12.396 | AF17: 4.529 | AG17: 3.145 | AH17: 44650 | AI17: 12.396 | AJ17: 4.586 | AK17: 3.356 | AL17: 44980
A18: 강원본부 | B18: 원주전력소 | C18: 북원주변전소 | D18: 원주전력소 | E18: 15 | F18: =ISTEXT(L18) -> FALSE | G18: 1000005969 | H18: 원주북원주#2 T/L | I18: =IF(F18=TRUE,"사용","미사용") -> 미사용 | N18: =IF(F18=TRUE,"X","O") -> O | S18: 12.19 | T18: 4.462 | U18: 2.872 | V18: 43703 | W18: 12.402 | X18: 4.65 | Y18: 3.159 | Z18: 43887 | AB18: 4.687 | AC18: 3.331 | AD18: 44361 | AE18: 12.4 | AF18: 4.62 | AG18: 3.494 | AH18: 44650 | AI18: 12.402 | AJ18: 4.675 | AK18: 4.05 | AL18: 44980
A19: 강원본부 | B19: 원주전력소 | C19: 북원주변전소 | D19: 원주전력소 | E19: 16 | F19: =ISTEXT(L19) -> FALSE | G19: 1000005969 | H19: 원주북원주#2 T/L | I19: =IF(F19=TRUE,"사용","미사용") -> 미사용 | N19: =IF(F19=TRUE,"X","O") -> O | S19: 12.19 | T19: 4.287 | U19: 2.868 | V19: 43703 | W19: 12.4 | X19: 4.517 | Y19: 2.993 | Z19: 43887 | AA19: 12.4 | AB19: 4.529 | AC19: 3.284 | AD19: 44361 | AE19: 12.404 | AF19: 4.498 | AG19: 3.457 | AH19: 44650 | AI19: 12.4 | AJ19: 4.553 | AK19: 3.259 | AL19: 44980
A20: 강원본부 | B20: 원주전력소 | C20: 북원주변전소 | D20: 원주전력소 | E20: 17 | F20: =ISTEXT(L20) -> FALSE | G20: 1000005969 | H20: 원주북원주#2 T/L | I20: =IF(F20=TRUE,"사용","미사용") -> 미사용 | N20: =IF(F20=TRUE,"X","O") -> O | S20: 12.19 | T20: 4.51 | U20: 3.62 | V20: 43703 | W20: 12.398 | X20: 4.396 | Y20: 3.49 | Z20: 43887 | AA20: 12.4 | AB20: 4.569 | AC20: 3.941 | AD20: 44361 | AE20: 12.4 | AF20: 4.519 | AG20: 3.79 | AH20: 44650 | AI20: 12.4 | AJ20: 5.038 | AK20: 3.88 | AL20: 44980
A21: 강원본부 | B21: 원주전력소 | C21: 북원주변전소 | D21: 원주전력소 | E21: 18 | F21: =ISTEXT(L21) -> FALSE | G21: 1000005969 | H21: 원주북원주#2 T/L | I21: =IF(F21=TRUE,"사용","미사용") -> 미사용 | N21: =IF(F21=TRUE,"X","O") -> O | S21: 12.19 | T21: 4.166 | U21: 2.671 | V21: 43703 | W21: 12.4 | X21: 4.133 | Y21: 2.693 | Z21: 43887 | AA21: 12.4 | AB21: 3.912 | AC21: 3.355 | AD21: 44361 | AE21: 12.396 | AF21: 4.136 | AG21: 3.276 | AH21: 44650 | AI21: 12.396 | AJ21: 4.534 | AK21: 3.909 | AL21: 44980
A22: 강원본부 | B22: 원주전력소 | C22: 북원주변전소 | D22: 원주전력소 | E22: 19 | F22: =ISTEXT(L22) -> FALSE | G22: 1000005969 | H22: 원주북원주#2 T/L | I22: =IF(F22=TRUE,"사용","미사용") -> 미사용 | N22: =IF(F22=TRUE,"X","O") -> O | O22: 12.15 | P22: 4.305 | Q22: 2.855 | R22: 43248 | S22: 12.194 | T22: 4.36 | U22: 3.05 | V22: 43703 | W22: 12.404 | X22: 4.765 | Y22: 3.131 | Z22: 43887 | AA22: 12.4 | AB22: 4.787 | AC22: 3.366 | AD22: 44361 | AE22: 12.398 | AF22: 4.747 | AG22: 3.48 | AH22: 44650 | AI22: 12.398 | AJ22: 5.109 | AK22: 3.951 | AL22: 44980
A23: 강원본부 | B23: 원주전력소 | C23: 북원주변전소 | D23: 원주전력소 | E23: 20 | F23: =ISTEXT(L23) -> FALSE | G23: 1000005969 | H23: 원주북원주#2 T/L | I23: =IF(F23=TRUE,"사용","미사용") -> 미사용 | N23: =IF(F23=TRUE,"X","O") -> O | O23: 12.14 | P23: 4.326 | Q23: 2.924 | R23: 43248 | S23: 15.851 | T23: 4.332 | U23: 2.867 | V23: 43703 | W23: 12.398 | X23: 4.422 | Y23: 3.823 | Z23: 43887 | AA23: 12.4 | AB23: 4.392 | AC23: 2.743 | AD23: 44361 | AE23: 12.402 | AF23: 4.384 | AG23: 3.228 | AH23: 44650 | AI23: 12.402 | AJ23: 4.805 | AK23: 3.212 | AL23: 44980
A24: 강원본부 | B24: 원주전력소 | C24: 북원주변전소 | D24: 원주전력소 | E24: 21 | F24: =ISTEXT(L24) -> TRUE | G24: 1000005969 | H24: 원주북원주#2 T/L | I24: =IF(F24=TRUE,"사용","미사용") -> 사용 | K24: DAS | L24: DAS | M24: KEPCO | N24: =IF(F24=TRUE,"X","O") -> X | O24: 6.88 | P24: 2.77 | Q24: 1.756 | R24: 43248 | W24: 6.884 | X24: 2.315 | Y24: 1.404 | Z24: 43887 | AA24: 6.8 | AB24: 2.7 | AC24: 1.883 | AD24: 44361 | AE24: 6.883 | AF24: 2.772 | AG24: 2.206 | AH24: 44650 | AO24: 접속함체에서 연결
A25: 강원본부 | B25: 원주전력소 | C25: 북원주변전소 | D25: 원주전력소 | E25: 22 | F25: =ISTEXT(L25) -> TRUE | G25: 1000005969 | H25: 원주북원주#2 T/L | I25: =IF(F25=TRUE,"사용","미사용") -> 사용 | K25: DAS | L25: DAS | M25: KEPCO | N25: =IF(F25=TRUE,"X","O") -> X | O25: 6.88 | P25: 2.308 | Q25: 1.397 | R25: 43248 | W25: 6.804 | X25: 2.426 | Y25: 1.418 | Z25: 43887 | AA25: 6.8 | AB25: 2.319 | AC25: 1.531 | AD25: 44361 | AE25: 6.883 | AF25: 2.318 | AG25: 1.927 | AH25: 44650 | AO25: 접속함체에서 연결
A26: 강원본부 | B26: 원주전력소 | C26: 북원주변전소 | D26: 원주전력소 | E26: 23 | F26: =ISTEXT(L26) -> TRUE | G26: 1000005969 | H26: 원주북원주#2 T/L | I26: =IF(F26=TRUE,"사용","미사용") -> 사용 | K26: DAS | L26: DAS | M26: KEPCO | N26: =IF(F26=TRUE,"X","O") -> X | O26: 6.88 | P26: 2.411 | Q26: 1.415 | R26: 43248 | AA26: 6.8 | AB26: 2.419 | AC26: 1.514 | AD26: 44361 | AE26: 6.883 | AF26: 2.419 | AG26: 1.96 | AH26: 44650 | AO26: 접속함체에서 연결
A27: 강원본부 | B27: 원주전력소 | C27: 북원주변전소 | D27: 원주전력소 | E27: 24 | F27: =ISTEXT(L27) -> TRUE | G27: 1000005969 | H27: 원주북원주#2 T/L | I27: =IF(F27=TRUE,"사용","미사용") -> 사용 | K27: DAS | L27: DAS | M27: KEPCO | N27: =IF(F27=TRUE,"X","O") -> X | O27: 6.88 | P27: 2.75 | Q27: 1.737 | R27: 43248 | AA27: 6.8 | AB27: 2.771 | AC27: 1.898 | AD27: 44361 | AE27: 6.883 | AF27: 2.771 | AG27: 2.207 | AH27: 44650 | AO27: 접속함체에서 연결
A28: 강원본부 | B28: 원주전력소 | C28: 북원주변전소 | D28: 횡성변전소 | E28: 25 | F28: =ISTEXT(L28) -> FALSE | G28: 1000005969 | H28: 원주북원주#2 T/L | I28: =IF(F28=TRUE,"사용","미사용") -> 미사용 | M28: KEPCO | N28: =IF(F28=TRUE,"X","O") -> O | AI28: 39.74 | AJ28: 13.327 | AK28: 8.831 | AL28: 44980
A29: 강원본부 | B29: 원주전력소 | C29: 북원주변전소 | D29: 횡성변전소 | E29: 26 | F29: =ISTEXT(L29) -> FALSE | G29: 1000005969 | H29: 원주북원주#2 T/L | I29: =IF(F29=TRUE,"사용","미사용") -> 미사용 | M29: KEPCO | N29: =IF(F29=TRUE,"X","O") -> O | AI29: 39.753 | AJ29: 14.805 | AK29: 9.574 | AL29: 44980
A30: 강원본부 | B30: 원주전력소 | C30: 북원주변전소 | D30: 횡성변전소 | E30: 27 | F30: =ISTEXT(L30) -> FALSE | G30: 1000005969 | H30: 원주북원주#2 T/L | I30: =IF(F30=TRUE,"사용","미사용") -> 미사용 | M30: KEPCO | N30: =IF(F30=TRUE,"X","O") -> O | AI30: 39.695 | AJ30: 13.558 | AK30: 8.59 | AL30: 44980
A31: 강원본부 | B31: 원주전력소 | C31: 북원주변전소 | D31: 횡성변전소 | E31: 28 | F31: =ISTEXT(L31) -> FALSE | G31: 1000005969 | H31: 원주북원주#2 T/L | I31: =IF(F31=TRUE,"사용","미사용") -> 미사용 | M31: KEPCO | N31: =IF(F31=TRUE,"X","O") -> O | AI31: 39.819 | AJ31: 13.831 | AK31: 8.962 | AL31: 44980
A32: 강원본부 | B32: 원주전력소 | C32: 북원주변전소 | D32: 횡성변전소 | E32: 29 | F32: =ISTEXT(L32) -> TRUE | G32: 1000005969 | H32: 원주북원주#2 T/L | I32: =IF(F32=TRUE,"사용","미사용") -> 사용 | J32: 패치 | K32: 통합단말 | L32: 원주전력소 GR2링(횡성-북원주) OUT | M32: KEPCO | N32: =IF(F32=TRUE,"X","O") -> X
A33: 강원본부 | B33: 원주전력소 | C33: 북원주변전소 | D33: 횡성변전소 | E33: 30 | F33: =ISTEXT(L33) -> TRUE | G33: 1000005969 | H33: 원주북원주#2 T/L | I33: =IF(F33=TRUE,"사용","미사용") -> 사용 | J33: 패치 | K33: 통합단말 | L33: 원주전력소 GR2링(횡성-북원주) IN | M33: KEPCO | N33: =IF(F33=TRUE,"X","O") -> X
A34: 강원본부 | B34: 원주전력소 | C34: 북원주변전소 | D34: 횡성변전소 | E34: 31 | F34: =ISTEXT(L34) -> TRUE | G34: 1000005969 | H34: 원주북원주#2 T/L | I34: =IF(F34=TRUE,"사용","미사용") -> 사용 | J34: 패치 | K34: 광스위치 | L34: 디지탈스카다㈜(북원주-횡성) | M34: KEPCO | N34: =IF(F34=TRUE,"X","O") -> X
A35: 강원본부 | B35: 원주전력소 | C35: 북원주변전소 | D35: 횡성변전소 | E35: 32 | F35: =ISTEXT(L35) -> TRUE | G35: 1000005969 | H35: 원주북원주#2 T/L | I35: =IF(F35=TRUE,"사용","미사용") -> 사용 | K35: 광스위치 | L35: 디지탈스카다㈜(북원주-홍천)_예정 | N35: =IF(F35=TRUE,"X","O") -> X | O35: 39.76 | P35: 13.457 | Q35: 8.354 | R35: 43248 | S35: 39.704 | T35: 13.798 | U35: 8.41 | V35: 43703 | W35: 39.769 | X35: 13.802 | Y35: 8.422 | Z35: 43887 | AA35: 39.773 | AB35: 13.638 | AC35: 8.456 | AD35: 44361 | AE35: 39.469 | AF35: 13.529 | AG35: 8.581 | AH35: 44650 | AI35: 39.736 | AJ35: 13.803 | AK35: 8.809 | AL35: 44980
A36: 강원본부 | B36: 원주전력소 | C36: 북원주변전소 | D36: 횡성변전소 | E36: 33 | F36: =ISTEXT(L36) -> TRUE | G36: 1000005969 | H36: 원주북원주#2 T/L | I36: =IF(F36=TRUE,"사용","미사용") -> 사용 | J36: 패치 | K36: 송변전광 | L36: 북원주-둔내 송변전광 W-OUT | M36: KEPCO | N36: =IF(F36=TRUE,"X","O") -> X | O36: 39.74 | P36: 13.274 | Q36: 8.106 | R36: 43248
A37: 강원본부 | B37: 원주전력소 | C37: 북원주변전소 | D37: 횡성변전소 | E37: 34 | F37: =ISTEXT(L37) -> TRUE | G37: 1000005969 | H37: 원주북원주#2 T/L | I37: =IF(F37=TRUE,"사용","미사용") -> 사용 | J37: 패치 | K37: 송변전광 | L37: 북원주-둔내 송변전광 W-IN | M37: KEPCO | N37: =IF(F37=TRUE,"X","O") -> X | O37: 39.84 | P37: 15.301 | Q37: 8.09 | R37: 43248
A38: 강원본부 | B38: 원주전력소 | C38: 북원주변전소 | D38: 횡성변전소 | E38: 35 | F38: =ISTEXT(L38) -> FALSE | G38: 1000005969 | H38: 원주북원주#2 T/L | I38: =IF(F38=TRUE,"사용","미사용") -> 미사용 | N38: =IF(F38=TRUE,"X","O") -> O | O38: 39.86 | P38: 21.932 | Q38: 8.44 | R38: 43248 | S38: 39.749 | T38: 13.706 | U38: 9.415 | V38: 43703 | W38: 39.724 | X38: 13.7 | Y38: 9.252 | Z38: 43887 | AA38: 39.7 | AB38: 13.603 | AC38: 8.585 | AD38: 44361 | AE38: 39.753 | AF38: 13.713 | AG38: 8.708 | AH38: 44650 | AI38: 39.761 | AJ38: 13.736 | AK38: 8.771 | AL38: 44980
A39: 강원본부 | B39: 원주전력소 | C39: 북원주변전소 | D39: 횡성변전소 | E39: 36 | F39: =ISTEXT(L39) -> FALSE | G39: 1000005969 | H39: 원주북원주#2 T/L | I39: =IF(F39=TRUE,"사용","미사용") -> 미사용 | N39: =IF(F39=TRUE,"X","O") -> O | O39: 39.73 | P39: 13.458 | Q39: 8.157 | R39: 43248 | S39: 39.749 | T39: 13.497 | U39: 8.945 | V39: 43703 | W39: 39.736 | X39: 13.49 | Y39: 8.999 | Z39: 43887 | AA39: 39.7 | AB39: 13.396 | AC39: 8.31 | AD39: 44361 | AE39: 39.745 | AF39: 13.599 | AG39: 8.461 | AH39: 44650 | AI39: 39.74 | AJ39: 13.465 | AK39: 8.578 | AL39: 44980
A40: 강원본부 | B40: 원주전력소 | C40: 북원주변전소 | D40: 횡성변전소 | E40: 37 | F40: =ISTEXT(L40) -> FALSE | G40: 1000005969 | H40: 원주북원주#2 T/L | I40: =IF(F40=TRUE,"사용","미사용") -> 미사용 | N40: =IF(F40=TRUE,"X","O") -> O | O40: 39.75 | P40: 13.445 | Q40: 8.327 | R40: 43248 | S40: 39.732 | T40: 13.487 | U40: 8.353 | V40: 43703 | W40: 39.74 | X40: 13.808 | Y40: 8.256 | Z40: 43887 | AA40: 39.7 | AB40: 13.487 | AC40: 8.313 | AD40: 44361 | AE40: 39.736 | AF40: 13.338 | AG40: 8.285 | AH40: 44650 | AI40: 39.753 | AJ40: 13.705 | AK40: 8.901 | AL40: 44980
...

Sheet 남원주
A1: ■ 강원본부 OFD 선번장(남원주) | L1: ※ 코아명칭 부여 PTP : COT측 장비 광출력 기준 링 : 링방향 West 광출력 기준
AO2: =원주!AS2 -> 45601 | AU2: 용도
A3: 본부 | B3: 관리사업소 | C3: 설치장소 | D3: 상대국명 | E3: 코어 선번 | F3: 사용여부판단 | G3: 송전선로 관리번호 | H3: 송전, 배전 선로명 | I3: 사용 여부 | J3: 융착/ 패치 | K3: 용도 | L3: 수용내역 | M3: 사용회사 | N3: 측정가능 여부 | O3: 측정거리 (km) | P3: 측정DATA 1310 (dB) | Q3: 측정DATA 1550 (dB) | R3: 측정일자 | S3: 측정거리 (km) | T3: 측정DATA 1310 (dB) | U3: 측정DATA 1550 (dB) | V3: 측정일자 | W3: 측정거리 (km) | X3: 측정DATA 1310 (dB) | Y3: 측정DATA 1550 (dB) | Z3: 측정일자 | AA3: 측정거리 (km) | AB3: 측정DATA 1310 (dB) | AC3: 측정DATA 1550 (dB) | AD3: 측정일자 | AE3: 측정거리 (km) | AF3: 측정DATA 1310 (dB) | AG3: 측정DATA 1550 (dB) | AH3: 측정일자 | AI3: 측정거리 (km) | AJ3: 측정DATA 1310 (dB) | AK3: 측정DATA 1550 (dB) | AL3: 측정일자 | AM3: 접속개소 | AN3: 상태 판단 | AO3: 비고 | AU3: 소형광단국
A4: 강원본부 | B4: 원주전력소 | C4: 남원주변전소 | D4: 원주전력소 | E4: 1 | F4: =ISTEXT(L4) -> FALSE | G4: 1000000355 | H4: 남원주원주#2 T/L | I4: =IF(F4=TRUE,"사용","미사용") -> 미사용 | J4: 패치 | M4: KEPCO | N4: =IF(F4=TRUE,"X","O") -> O | AI4: 8.845 | AJ4: 2.947 | AK4: 1.714 | AL4: 44978 | AU4: 통합단말
A5: 강원본부 | B5: 원주전력소 | C5: 남원주변전소 | D5: 원주전력소 | E5: 2 | F5: =ISTEXT(L5) -> FALSE | G5: 1000000355 | H5: 남원주원주#2 T/L | I5: =IF(F5=TRUE,"사용","미사용") -> 미사용 | J5: 패치 | M5: KEPCO | N5: =IF(F5=TRUE,"X","O") -> O | AI5: 8.856 | AJ5: 2.833 | AK5: 1.612 | AL5: 44978 | AU5: KepCIT
A6: 강원본부 | B6: 원주전력소 | C6: 남원주변전소 | D6: 원주전력소 | E6: 3 | F6: =ISTEXT(L6) -> FALSE | G6: 1000000355 | H6: 남원주원주#2 T/L | I6: =IF(F6=TRUE,"사용","미사용") -> 미사용 | J6: 패치 | M6: KEPCO | N6: =IF(F6=TRUE,"X","O") -> O | AI6: 8.856 | AJ6: 2.877 | AK6: 1.6 | AL6: 44978 | AU6: 광스위치
A7: 강원본부 | B7: 원주전력소 | C7: 남원주변전소 | D7: 원주전력소 | E7: 4 | F7: =ISTEXT(L7) -> FALSE | G7: 1000000355 | H7: 남원주원주#2 T/L | I7: =IF(F7=TRUE,"사용","미사용") -> 미사용 | J7: 패치 | M7: KEPCO | N7: =IF(F7=TRUE,"X","O") -> O | AI7: 8.843 | AJ7: 3.096 | AK7: 1.807 | AL7: 44978 | AU7: 송변전광
A8: 강원본부 | B8: 원주전력소 | C8: 남원주변전소 | D8: 원주전력소 | E8: 5 | F8: =ISTEXT(L8) -> TRUE | G8: 1000000355 | H8: 남원주원주#2 T/L | I8: =IF(F8=TRUE,"사용","미사용") -> 사용 | J8: 패치 | K8: 송PTPU | L8: 원주-남원주 송PTPU WEST | M8: KEPCO | N8: =IF(F8=TRUE,"X","O") -> X | O8: 8.642 | P8: 2.844 | Q8: 1.72 | R8: 43248 | S8: 8.636 | T8: 2.885 | U8: 1.739 | V8: 43704 | W8: 8.636 | X8: 2.93 | Y8: 1.746 | Z8: 43887 | AA8: 8.85 | AB8: 5.371 | AC8: 2.941 | AD8: 44347 | AE8: 8.847 | AF8: 2.969 | AG8: 1.787 | AH8: 44644 | AU8: 임대
A9: 강원본부 | B9: 원주전력소 | C9: 남원주변전소 | D9: 원주전력소 | E9: 6 | F9: =ISTEXT(L9) -> TRUE | G9: 1000000355 | H9: 남원주원주#2 T/L | I9: =IF(F9=TRUE,"사용","미사용") -> 사용 | J9: 패치 | K9: 송PTPU | L9: 원주-남원주 송PTPU EAST | M9: KEPCO | N9: =IF(F9=TRUE,"X","O") -> X | O9: 8.638 | P9: 2.799 | Q9: 1.657 | R9: 43248 | S9: 8.64 | T9: 2.833 | U9: 1.681 | V9: 43704 | W9: 8.642 | X9: 2.879 | Y9: 1.773 | Z9: 43887 | AA9: 8.85 | AB9: 5.276 | AC9: 3.135 | AD9: 44347 | AE9: 8.85 | AF9: 2.954 | AG9: 1.745 | AH9: 44644 | AU9: PTPU
A10: 강원본부 | B10: 원주전력소 | C10: 남원주변전소 | D10: 원주전력소 | E10: 7 | F10: =ISTEXT(L10) -> TRUE | G10: 1000000355 | H10: 남원주원주#2 T/L | I10: =IF(F10=TRUE,"사용","미사용") -> 사용 | J10: 패치 | K10: 통합단말 | L10: 원주전력소 GR3링(원주-동원주) OUT | M10: KEPCO | N10: =IF(F10=TRUE,"X","O") -> X | AU10: SCADA
A11: 강원본부 | B11: 원주전력소 | C11: 남원주변전소 | D11: 원주전력소 | E11: 8 | F11: =ISTEXT(L11) -> TRUE | G11: 1000000355 | H11: 남원주원주#2 T/L | I11: =IF(F11=TRUE,"사용","미사용") -> 사용 | J11: 패치 | K11: 통합단말 | L11: 원주전력소 GR3링(원주-동원주) IN | M11: KEPCO | N11: =IF(F11=TRUE,"X","O") -> X | AU11: PITR
A12: 강원본부 | B12: 원주전력소 | C12: 남원주변전소 | D12: 원주전력소 | E12: 9 | F12: =ISTEXT(L12) -> TRUE | G12: 1000000355 | H12: 남원주원주#2 T/L | I12: =IF(F12=TRUE,"사용","미사용") -> 사용 | J12: 패치 | K12: 통합단말 | L12: 원주전력소 GR3링(남원주-문막) OUT | M12: KEPCO | N12: =IF(F12=TRUE,"X","O") -> X | AU12: DAS
A13: 강원본부 | B13: 원주전력소 | C13: 남원주변전소 | D13: 원주전력소 | E13: 10 | F13: =ISTEXT(L13) -> TRUE | G13: 1000000355 | H13: 남원주원주#2 T/L | I13: =IF(F13=TRUE,"사용","미사용") -> 사용 | J13: 패치 | K13: 통합단말 | L13: 원주전력소 GR3링(남원주-문막) IN | M13: KEPCO | N13: =IF(F13=TRUE,"X","O") -> X | AU13: 기타
A14: 강원본부 | B14: 원주전력소 | C14: 남원주변전소 | D14: 원주전력소 | E14: 11 | F14: =ISTEXT(L14) -> TRUE | G14: 1000000355 | H14: 남원주원주#2 T/L | I14: =IF(F14=TRUE,"사용","미사용") -> 사용 | J14: 패치 | K14: KepCIT | L14: 차세대전력통신망 중부2링(원주P/O-신제천S/S) | M14: KEPCO | N14: =IF(F14=TRUE,"X","O") -> X | O14: 8.646 | P14: 2.902 | Q14: 1.755 | R14: 43248 | S14: 8.638 | T14: 2.934 | U14: 1.768 | V14: 43704 | W14: 8.638 | X14: 2.97 | Y14: 1.623 | Z14: 43887 | AA14: 8.85 | AB14: 4.986 | AC14: 3.131 | AD14: 44347 | AU14: 송PTPU
